<?xml version="1.0" ?>
<sdf version="1.4">
  <model name="schunk_mpg_80">
    <link name="base">
      <self_collide>false</self_collide>
      <inertial>
        <pose>0 0.035 0 0 0 0</pose>
        <inertia>
          <ixx>0.00053312</ixx>
          <ixy>0</ixy>
          <ixz>0</ixz>
          <iyy>0.00065312</iyy>
          <iyz>0</iyz>
          <izz>0.000904</izz>
        </inertia>
        <mass>0.96</mass>
      </inertial>
      <visual name="base_geom_visual">
        <pose>0 0 0 0 0 0</pose>
        <geometry>
          <mesh>
            <uri>model://schunk_mpg_80/meshes/visual/SCHUNK_MPG-80_BASE.dae</uri>
          </mesh>
        </geometry>
      </visual>
      <collision name="base_geom_collision">
        <pose>0 0.035 0 0 0 0</pose>
        <geometry>
          <box>
            <size>0.08 0.07 0.042</size>
          </box>
        </geometry>
      </collision>
      <collision name="base_tab1_geom_collision">
        <pose>-0.043 0.036 0.009 0 0 0</pose>
        <geometry>
          <box>
            <size>0.006 0.012 0.012</size>
          </box>
        </geometry>
      </collision>
      <collision name="base_tab2_geom_collision">
        <pose>-0.043 0.036 -0.009 0 0 0</pose>
        <geometry>
          <box>
            <size>0.006 0.012 0.012</size>
          </box>
        </geometry>
      </collision>
    </link>
    <link name="l_finger">
      <self_collide>true</self_collide>
      <inertial>
        <pose>-0.0205 0.0798 0 0 0 0</pose>
        <inertia>
          <ixx>0.0000095236</ixx>
          <ixy>0</ixy>
          <ixz>0</ixz>
          <iyy>0.0000072</iyy>
          <iyz>0</iyz>
          <izz>0.0000052036</izz>
        </inertia>
        <mass>0.12</mass>
      </inertial>
      <visual name="l_finger_geom_visual">
        <pose>0 0 0 0 0 0</pose>
        <geometry>
          <mesh>
            <uri>model://schunk_mpg_80/meshes/visual/SCHUNK_MPG-80_LEFT_FINGER.dae</uri>
          </mesh>
        </geometry>
      </visual>
      <collision name="l_finger_tip_geom_collision">
        <pose>-0.0205 0.0798 0 0 0 0</pose>
        <geometry>
          <box>
            <size>0.012 0.0194 0.024</size>
          </box>
        </geometry>
      </collision>
    </link>
    <link name="r_finger">
      <self_collide>true</self_collide>
      <inertial>
        <pose>0.0205 0.0798 0 0 0 0</pose>
        <inertia>
          <ixx>0.0000095236</ixx>
          <ixy>0</ixy>
          <ixz>0</ixz>
          <iyy>0.0000072</iyy>
          <iyz>0</iyz>
          <izz>0.0000052036</izz>
        </inertia>
        <mass>0.12</mass>
      </inertial>
      <visual name="r_finger_geom_visual">
        <pose>0 0 0 0 0 0</pose>
        <geometry>
          <mesh>
            <uri>model://schunk_mpg_80/meshes/visual/SCHUNK_MPG-80_RIGHT_FINGER.dae</uri>
          </mesh>
        </geometry>
      </visual>
      <collision name="r_finger_tip_geom_collision">
        <pose>0.0205 0.0798 0 0 0 0</pose>
        <geometry>
          <box>
            <size>0.012 0.0194 0.024</size>
          </box>
        </geometry>
      </collision>
    </link>

    <joint name="l_finger_actuator" type="prismatic"> 
      <parent>base</parent>
      <child>l_finger</child>
      <axis>
        <dynamics>
          <damping>0.0</damping>
          <friction>0.0</friction>
        </dynamics>
        <xyz>1 0 0</xyz>
        <limit>
          <lower>0</lower>
          <upper>0.014</upper>
        </limit>
      </axis>
    </joint>

    <joint name="r_finger_actuator" type="prismatic"> 
      <parent>base</parent>
      <child>r_finger</child>
      <axis>
        <dynamics>
          <damping>0.0</damping>
          <friction>0.0</friction>
        </dynamics>
        <xyz>1 0 0</xyz>
        <limit>
          <lower>-0.014</lower>
          <upper>0</upper>
        </limit>
      </axis>
    </joint>

    <!-- Fixed base -->
    <joint name="fixed_joint" type="revolute"> 
      <parent>world</parent>
      <child>base</child>
      <axis>
        <xyz>0 0 1</xyz>
        <limit>
          <lower>0</lower>
          <upper>0</upper>
        </limit>
      </axis>
    </joint>

  </model>
</sdf>

