<robot xmlns:xacro="http://ros.org/wiki/xacro"
        xmlns:sensor="http://playerstage.sourceforge.net/gazebo/xmlschema/#sensor"
       xmlns:controller="http://playerstage.sourceforge.net/gazebo/xmlschema/#controller"
       xmlns:joint="http://playerstage.sourceforge.net/gazebo/xmlschema/#slider"
       xmlns:interface="http://playerstage.sourceforge.net/gazebo/xmlschema/#interface"
       xmlns:body="http://playerstage.sourceforge.net/gazebo/xmlschema/#body"
       xmlns:geom="http://playerstage.sourceforge.net/gazebo/xmlschema/#geom">

  <xacro:include filename="$(find sr_description)/hand/xacro/finger/middle/middle.transmission.xacro" />

  <xacro:macro name="middle" params="link_prefix joint_prefix parent">

    <link name="${link_prefix}middle">
      <inertial>
	<origin xyz="0 0 0.0125" rpy="0 0 0" />
	<mass value="0.012" />
	<inertia  ixx="0.0000008" ixy="0.0"  ixz="0.0"
            iyy="0.0000008" iyz="0.0"
            izz="0.0000003" />
      </inertial>
      <visual>
	<origin xyz="0 0 0" rpy="0 0 0" />
	<geometry name="${link_prefix}middle_visual">
      <mesh filename="package://sr_description/hand/model/F2.dae" scale="0.001 0.001 0.001" />
      </geometry>
      <material name="Grey" />
      </visual>
      <collision>
	<origin xyz="0 0 0.0125" rpy="0 0 0" />
	<geometry name="${link_prefix}middle_collision_geom">
	  <box size="0.008 0.008 0.015" />
	</geometry>
      </collision>
    </link>

    <gazebo reference="${link_prefix}middle">
      <sensor type="contact" name="${link_prefix}middle_contact" >
        <always_on>1</always_on>
        <update_rate>1000.0</update_rate>
        <contact>
          <collision>${link_prefix}middle_collision</collision>
          <topic>${link_prefix}middle_collision</topic>
        </contact>
        <plugin name="${link_prefix}middle_gazebo_ros_bumper_controller" filename="libgazebo_ros_bumper.so">
          <updateRate>100.0</updateRate>
	  <frameName>${link_prefix}middle</frameName>
	  <bumperTopicName>contacts/${link_prefix}/middle</bumperTopicName>
        </plugin>
      </sensor>
      <material>LightGrey</material>
    </gazebo>

    <joint name="${joint_prefix}J2" type="revolute">
      <parent link="${parent}"/>
      <child link="${link_prefix}middle"/>
      <origin xyz="0 0 0.045" rpy="0 0 0" />
      <axis xyz="1 0 0" />
      <limit lower="0" upper="${M_PI/2}" effort="1000.0"
      velocity="10.0" />
      <dynamics damping="10.0"/>
    </joint>
    <gazebo reference="${joint_prefix}J2">
    <provideFeedback>1</provideFeedback>
    <implicitSpringDamper>1</implicitSpringDamper>
    </gazebo>

    <xacro:middle_transmission />

  </xacro:macro>

</robot>
