<?xml version="1.0" ?>
<sdf version="1.5">
  <model name="four_bar_with_base">
    <link name="base">
      <inertial>
        <pose>0 0 0.1 0 0 0</pose>
        <mass>120</mass>
        <inertia>
          <ixx>46</ixx>
          <ixy>0</ixy>
          <ixz>0</ixz>
          <iyy>46</iyy>
          <iyz>0</iyz>
          <izz>90</izz>
        </inertia>
      </inertial>
      <visual name="vis_plate_on_ground">
        <pose>0 0 0.01 0 0 0</pose>
        <geometry>
          <cylinder>
            <radius>1.2</radius>
            <length>0.02</length>
          </cylinder>
        </geometry>
        <material>
          <script>
            <uri>file://media/materials/scripts/gazebo.material</uri>
            <name>Gazebo/Grey</name>
          </script>
        </material>
      </visual>
      <visual name="vis_pole">
        <pose>-0.275 0 1.15 0 0 0</pose>
        <geometry>
          <box>
            <size>0.2 0.2 2.3</size>
          </box>
        </geometry>
        <material>
          <script>
            <uri>file://media/materials/scripts/gazebo.material</uri>
            <name>Gazebo/Grey</name>
          </script>
        </material>
      </visual>
      <collision name="col_plate_on_ground">
        <pose>0 0 0.01 0 0 0</pose>
        <geometry>
          <cylinder>
            <radius>1.2</radius>
            <length>0.02</length>
          </cylinder>
        </geometry>
      </collision>
      <collision name="col_pole">
        <pose>-0.275 0 1.15 0 0 0</pose>
        <geometry>
          <box>
            <size>0.2 0.2 2.3</size>
          </box>
        </geometry>
      </collision>
    </link>
    <!-- upper link, length 1 -->
    <link name="upper_link">
      <pose>0 0 2.2 2.58719 0 0</pose>
      <self_collide>0</self_collide>
      <inertial>
        <pose>0 0 0.5 0 0 0</pose>
        <mass>12</mass>
        <inertia>
          <ixx>0.85</ixx>
          <ixy>0</ixy>
          <ixz>0</ixz>
          <iyy>0.85</iyy>
          <iyz>0</iyz>
          <izz>0.04</izz>
        </inertia>
      </inertial>
      <visual name="vis_upper_joint">
        <pose>-0.05 0 0 0 1.5708 0</pose>
        <geometry>
          <cylinder>
            <radius>0.1</radius>
            <length>0.3</length>
          </cylinder>
        </geometry>
        <material>
          <script>
            <uri>file://media/materials/scripts/gazebo.material</uri>
            <name>Gazebo/Grey</name>
          </script>
        </material>
      </visual>
      <visual name="vis_upper_middle_joint">
        <pose>0 0 1.0 0 1.5708 0</pose>
        <geometry>
          <cylinder>
            <radius>0.1</radius>
            <length>0.2</length>
          </cylinder>
        </geometry>
        <material>
          <script>
            <uri>file://media/materials/scripts/gazebo.material</uri>
            <name>Gazebo/Grey</name>
          </script>
        </material>
      </visual>
      <visual name="vis_cylinder">
        <pose>0 0 0.5 0 0 0</pose>
        <geometry>
          <cylinder>
            <radius>0.1</radius>
            <length>0.9</length>
          </cylinder>
        </geometry>
        <material>
          <script>
            <uri>file://media/materials/scripts/gazebo.material</uri>
            <name>Gazebo/Grey</name>
          </script>
        </material>
      </visual>
      <collision name="col_upper_joint">
        <pose>-0.05 0 0 0 1.5708 0</pose>
        <geometry>
          <cylinder>
            <radius>0.1</radius>
            <length>0.3</length>
          </cylinder>
        </geometry>
      </collision>
      <collision name="col_upper_middle_joint">
        <pose>0 0 1.0 0 1.5708 0</pose>
        <geometry>
          <cylinder>
            <radius>0.1</radius>
            <length>0.2</length>
          </cylinder>
        </geometry>
      </collision>
      <collision name="col_cylinder">
        <pose>0 0 0.5 0 0 0</pose>
        <geometry>
          <cylinder>
            <radius>0.1</radius>
            <length>0.9</length>
          </cylinder>
        </geometry>
      </collision>
    </link>
    <!-- middle link, length 1 -->
    <link name="middle_link">
      <pose>0.25 -0.5265 1.35 -2.639 0 0</pose>
      <self_collide>0</self_collide>
      <inertial>
        <pose>0 0 0.5 0 0 0</pose>
        <mass>12</mass>
        <inertia>
          <ixx>0.85</ixx>
          <ixy>0</ixy>
          <ixz>0</ixz>
          <iyy>0.85</iyy>
          <iyz>0</iyz>
          <izz>0.04</izz>
        </inertia>
      </inertial>
      <visual name="vis_upper_middle_joint">
        <pose>0 0 0 0 1.5708 0</pose>
        <geometry>
          <cylinder>
            <radius>0.08</radius>
            <length>0.3</length>
          </cylinder>
        </geometry>
        <material>
          <script>
            <uri>file://media/materials/scripts/gazebo.material</uri>
            <name>Gazebo/Grey</name>
          </script>
        </material>
      </visual>
      <visual name="vis_cylinder">
        <pose>0 0 0.5 0 0 0</pose>
        <geometry>
          <cylinder>
            <radius>0.1</radius>
            <length>0.9</length>
          </cylinder>
        </geometry>
        <material>
          <script>
            <uri>file://media/materials/scripts/gazebo.material</uri>
            <name>Gazebo/Grey</name>
          </script>
        </material>
      </visual>
      <visual name="vis_middle_lower_joint">
        <pose>0 0 1.0 0 1.5708 0</pose>
        <geometry>
          <cylinder>
            <radius>0.1</radius>
            <length>0.2</length>
          </cylinder>
        </geometry>
        <material>
          <script>
            <uri>file://media/materials/scripts/gazebo.material</uri>
            <name>Gazebo/Grey</name>
          </script>
        </material>
      </visual>
      <collision name="col_upper_middle_joint">
        <pose>0 0 0 0 1.5708 0</pose>
        <geometry>
          <cylinder>
            <radius>0.08</radius>
            <length>0.3</length>
          </cylinder>
        </geometry>
      </collision>
      <collision name="col_cylinder">
        <pose>0 0 0.5 0 0 0</pose>
        <geometry>
          <cylinder>
            <radius>0.1</radius>
            <length>0.9</length>
          </cylinder>
        </geometry>
      </collision>
      <collision name="col_middle_lower_joint">
        <pose>0 0 1.0 0 1.5708 0</pose>
        <geometry>
          <cylinder>
            <radius>0.1</radius>
            <length>0.2</length>
          </cylinder>
        </geometry>
      </collision>
    </link>
    <!-- lower link, length 1, IC ~-120 degrees more -->
    <link name="lower_link">
      <pose>0 -0.042713 0.480714 -1.82 0 0</pose>
      <self_collide>0</self_collide>
      <inertial>
        <pose>0 0 0.5 0 0 0</pose>
        <mass>12</mass>
        <inertia>
          <ixx>0.85</ixx>
          <ixy>0</ixy>
          <ixz>0</ixz>
          <iyy>0.85</iyy>
          <iyz>0</iyz>
          <izz>0.04</izz>
        </inertia>
      </inertial>
      <visual name="vis_middle_lower_joint">
        <pose>0 0 0 0 1.5708 0</pose>
        <geometry>
          <cylinder>
            <radius>0.08</radius>
            <length>0.3</length>
          </cylinder>
        </geometry>
        <material>
          <script>
            <uri>file://media/materials/scripts/gazebo.material</uri>
            <name>Gazebo/Grey</name>
          </script>
        </material>
      </visual>
      <visual name="vis_cylinder">
        <pose>0 0 0.5 0 0 0</pose>
        <geometry>
          <cylinder>
            <radius>0.1</radius>
            <length>0.9</length>
          </cylinder>
        </geometry>
        <material>
          <script>
            <uri>file://media/materials/scripts/gazebo.material</uri>
            <name>Gazebo/Grey</name>
          </script>
        </material>
      </visual>
      <visual name="vis_closed_loop_joint">
        <pose>0 0 1.0 0 1.5708 0</pose>
        <geometry>
          <cylinder>
            <radius>0.22</radius>
            <length>0.2</length>
          </cylinder>
        </geometry>
        <material>
          <script>
            <uri>file://media/materials/scripts/gazebo.material</uri>
            <name>Gazebo/Grey</name>
          </script>
        </material>
      </visual>
      <collision name="col_middle_lower_joint">
        <pose>0 0 0 0 1.5708 0</pose>
        <geometry>
          <cylinder>
            <radius>0.08</radius>
            <length>0.3</length>
          </cylinder>
        </geometry>
      </collision>
      <collision name="col_cylinder">
        <pose>0 0 0.5 0 0 0</pose>
        <geometry>
          <cylinder>
            <radius>0.1</radius>
            <length>0.9</length>
          </cylinder>
        </geometry>
      </collision>
      <collision name="col_closed_loop_joint">
        <pose>0 0 1.0 0 1.5708 0</pose>
        <geometry>
          <cylinder>
            <radius>0.22</radius>
            <length>0.2</length>
          </cylinder>
        </geometry>
      </collision>
    </link>
    <!-- pin joint for upper link, at origin of upper link -->
    <joint name="upper_joint" type="revolute">
      <parent>base</parent>
      <child>upper_link</child>
      <axis>
        <xyz>1.0 0 0</xyz>
      </axis>
    </joint>
    <!-- pin joint for lower link, at origin of child link -->
    <joint name="upper_middle_joint" type="revolute">
      <parent>upper_link</parent>
      <child>middle_link</child>
      <axis>
        <xyz>1.0 0 0</xyz>
      </axis>
    </joint>
    <!-- pin joint for lower link_clone, at origin of child link -->
    <joint name="middle_lower_joint" type="revolute">
      <parent>middle_link</parent>
      <child>lower_link</child>
      <axis>
        <xyz>1.0 0 0</xyz>
      </axis>
    </joint>
    <!-- pin joint for lower link_clone, at origin of child link -->
    <joint name="closed_loop_joint" type="revolute">
      <pose>0 0 1.0 0 0 0</pose>
      <parent>base</parent>
      <child>lower_link</child>
      <axis>
        <xyz>1.0 0 0</xyz>
      </axis>
    </joint>
  </model>
</sdf>
