<?xml version='1.0'?>
<sdf version='1.4'>
  <model name='Landroids_Robot2'>
    <link name='Chassis'>
      <pose>0 0 .05 1.570796 0 0</pose>
      <collision name='collision'>
        <geometry>
          <mesh>
            <uri>model://FTC_Robot2/meshes/chassis.stl</uri>
            <scale>0.025400 0.025400 0.025400</scale>
          </mesh>
        </geometry>
      </collision>
      <visual name='visual'>
        <geometry>
          <mesh>
            <uri>model://FTC_Robot2/meshes/chassis.stl</uri>
            <scale>0.025400 0.025400 0.025400</scale>
          </mesh>
        </geometry>
        <material>
          <ambient>0 0 .6 1</ambient>
          <diffuse>0 0 .6 1</diffuse>
          <specular>0 0 .6 1</specular>
        </material>
      </visual>
      <self_collide>0</self_collide>
      <inertial>
        <pose>0 0 0 0 0 0</pose>
        <inertia>
          <ixx>0.1000000</ixx>
          <ixy>0.000000</ixy>
          <ixz>0.000000</ixz>
          <iyy>0.1000000</iyy>
          <iyz>0.000000</iyz>
          <izz>0.1000000</izz>
        </inertia>
        <mass>10.000000</mass>
      </inertial>
      <kinematic>0</kinematic>
      <gravity>1</gravity>
      <velocity_decay>
        <linear>0.1</linear>
        <angular>0.1</angular>
      </velocity_decay>
    </link>

    <link name='Lift'>
      <pose>.06 0 .2 0.000000 1.570796 3.926990</pose>
      <collision name='collision'>
        <geometry>
          <mesh>
            <uri>model://FTC_Robot2/meshes/lift.stl</uri>
            <scale>0.025400 0.025400 0.025400</scale>
          </mesh>
        </geometry>
      </collision>
      <visual name='visual'>
        <geometry>
          <mesh>
            <uri>model://FTC_Robot2/meshes/lift.stl</uri>
            <scale>0.025400 0.025400 0.025400</scale>
          </mesh>
        </geometry>
        <material>
          <ambient>.8 0 1 1</ambient>
          <diffuse>.8 0 1 1</diffuse>
          <specular>.8 0 1 1</specular>
        </material>
      </visual>
      <self_collide>0</self_collide>
      <inertial>5
        <inertia>
          <ixx>0.001000000</ixx>
          <ixy>0.000000</ixy>
          <ixz>0.000000</ixz>
          <iyy>0.001000000</iyy>
          <iyz>0.000000</iyz>
          <izz>0.001000000</izz>
        </inertia>
        <mass>.5000000</mass>
      </inertial>
      <kinematic>0</kinematic>
      <gravity>1</gravity>
      <sensor name="Webcam" type="camera">
        <pose>-.1 -.1 -.08 -1.57 -1.57 0</pose>
        <camera>
          <horizontal_fov>1.047</horizontal_fov>
          <image>
            <width>640</width>
            <height>480</height>
            <format>R8G8B8</format>
          </image>
          <clip>
            <near>0.05</near>
            <far>500</far>
          </clip>
        </camera>
        <update_rate>30</update_rate>
        <topic>Webcam</topic>
        <always_on>true</always_on>
        <visualize>false</visualize>
        <plugin name="CameraPlugin" filename="libCameraPlugin.so"/>
      </sensor>
    </link>

    <link name='Claw'>
      <pose>.05 .05 .25 1.570796 0.000000 0.785398</pose>
      <collision name='collision'>
        <geometry>
          <mesh>
            <uri>model://FTC_Robot2/meshes/claw.stl</uri>
            <scale>0.025400 0.025400 0.025400</scale>
          </mesh>
        </geometry>
      </collision>
      <visual name='visual'>
        <geometry>
          <mesh>
            <uri>model://FTC_Robot2/meshes/claw.stl</uri>
            <scale>0.025400 0.025400 0.025400</scale>
          </mesh>
        </geometry>
        <material>
          <ambient>0 1 0 1</ambient>
          <diffuse>0 1 0 1</diffuse>
          <specular>0 1 0 1</specular>
        </material>
      </visual>
      <self_collide>0</self_collide>
      <inertial>
        <pose>.055 .13 .04 0 0 0</pose>
        <inertia>
          <ixx>0.010000</ixx>
          <ixy>0.000000</ixy>
          <ixz>0.000000</ixz>
          <iyy>0.01000000</iyy>
          <iyz>0.000000</iyz>
          <izz>0.01000000</izz>
        </inertia>
        <mass>0.200</mass>
      </inertial>
      <kinematic>0</kinematic>
      <gravity>1</gravity>
    </link>

    <link name='Wheel_1'>
      <pose>.225 .185 .05 0.000000 0.000000 1.570796</pose>
      <self_collide>false</self_collide>
      <collision name='collision'>
        <geometry>
          <mesh>
            <uri>model://FTC_Robot2/meshes/wheel.stl</uri>
            <scale>0.001000 0.001000 0.001000</scale>
          </mesh>
        </geometry>
        <surface>
          <friction>
            <ode>
              <mu>0</mu>
              <mu2>0</mu2>
            </ode>
          </friction>
        </surface>
      </collision>
      <visual name='visual'>
        <geometry>
          <mesh>
            <uri>model://FTC_Robot2/meshes/wheel.stl</uri>
            <scale>0.001000 0.001000 0.001000</scale>
          </mesh>
        </geometry>
      </visual>
      <self_collide>0</self_collide>
      <inertial>
        <inertia>
          <ixx>0.0010000</ixx>
          <ixy>0.000000</ixy>
          <ixz>0.000000</ixz>
          <iyy>0.001000000</iyy>
          <iyz>0.000000</iyz>
          <izz>0.001000000</izz>
        </inertia>
        <mass>0.05</mass>
      </inertial>
      <kinematic>0</kinematic>
      <gravity>1</gravity>
    </link>

    <link name='Wheel_2'>
      <pose>-.225 .185 .05 0.000000 0.000000 1.570796</pose>
      <self_collide>false</self_collide>
      <collision name='collision'>
        <geometry>
          <mesh>
            <uri>model://FTC_Robot2/meshes/wheel.stl</uri>
            <scale>0.001000 0.001000 0.001000</scale>
          </mesh>
        </geometry>
        <surface>
          <friction>
            <ode>
              <mu>0</mu>
              <mu2>0</mu2>
            </ode>
          </friction>
        </surface>
      </collision>
      <visual name='visual'>
        <geometry>
          <mesh>
            <uri>model://FTC_Robot2/meshes/wheel.stl</uri>
            <scale>0.001000 0.001000 0.001000</scale>
          </mesh>
        </geometry>
      </visual>
      <self_collide>0</self_collide>
      <inertial>
        <inertia>
          <ixx>0.0010000</ixx>
          <ixy>0.000000</ixy>
          <ixz>0.000000</ixz>
          <iyy>0.001000000</iyy>
          <iyz>0.000000</iyz>
          <izz>0.001000000</izz>
        </inertia>
        <mass>0.05</mass>
      </inertial>
      <kinematic>0</kinematic>
      <gravity>1</gravity>
    </link>

    <link name='Wheel_3'>
      <pose>0 -.05 .05 0.000000 0.000000 0.000000</pose>
      <self_collide>false</self_collide>
      <collision name='collision'>
        <geometry>
          <mesh>
            <uri>model://FTC_Robot2/meshes/wheel.stl</uri>
            <scale>0.001000 0.001000 0.001000</scale>
          </mesh>
        </geometry>
        <surface>
          <friction>
            <ode>
              <mu>0</mu>
              <mu2>0</mu2>
            </ode>
          </friction>
        </surface>
      </collision>
      <visual name='visual'>
        <geometry>
          <mesh>
            <uri>model://FTC_Robot2/meshes/wheel.stl</uri>
            <scale>0.001000 0.001000 0.001000</scale>
          </mesh>
        </geometry>
      </visual>
      <self_collide>0</self_collide>
      <inertial>
        <inertia>
          <ixx>0.0010000</ixx>
          <ixy>0.000000</ixy>
          <ixz>0.000000</ixz>
          <iyy>0.001000000</iyy>
          <iyz>0.000000</iyz>
          <izz>0.001000000</izz>
        </inertia>
        <mass>0.05</mass>
      </inertial>
      <kinematic>0</kinematic>
      <gravity>1</gravity>
    </link>

    <link name='Wheel_4'>
      <pose>0 .41 0.05 0.000000 0.000000 0.000000</pose>
      <self_collide>false</self_collide>
      <collision name='collision'>
        <geometry>
          <mesh>
            <uri>model://FTC_Robot2/meshes/wheel.stl</uri>
            <scale>0.001000 0.001000 0.001000</scale>
          </mesh>
        </geometry>
        <surface>
          <friction>
            <ode>
              <mu>0</mu>
              <mu2>0</mu2>
            </ode>
          </friction>
        </surface>
      </collision>
      <visual name='visual'>
        <geometry>
          <mesh>
            <uri>model://FTC_Robot2/meshes/wheel.stl</uri>
            <scale>0.001000 0.001000 0.001000</scale>
          </mesh>
        </geometry>
      </visual>
      <self_collide>0</self_collide>
      <inertial>
        <inertia>
          <ixx>0.0010000</ixx>
          <ixy>0.000000</ixy>
          <ixz>0.000000</ixz>
          <iyy>0.001000000</iyy>
          <iyz>0.000000</iyz>
          <izz>0.001000000</izz>
        </inertia>
        <mass>0.05</mass>
      </inertial>
      <kinematic>0</kinematic>
      <gravity>1</gravity>
    </link>

    <joint name="Lift_joint" type="prismatic">
      <parent>Chassis</parent>
      <child>Lift</child>
      <pose>0 0 0 0 0 0</pose>
      <axis>
        <xyz>0 0 1</xyz>
        <limit>
          <lower>0</lower>
          <upper>0.5</upper>
        </limit>
      </axis>
    </joint>

    <joint name="Claw_joint" type="revolute">
      <parent>Lift</parent>
      <child>Claw</child>
      <pose>.055 .13 .04 0 0 0</pose>
      <axis>
        <xyz>.1 .1 0</xyz>
        <dynamics>
          <damping>0.02</damping>
          <friction>0.01</friction>
        </dynamics>
        <limit>
          <lower>-.1</lower>
          <upper>.1</upper>
        </limit>
      </axis>
    </joint>

    <joint name="Wheel_1_joint" type="revolute">
      <parent>Chassis</parent>
      <child>Wheel_1</child>
      <pose>0 0 0 0 0 0</pose>
      <axis>
        <xyz>1 0 0</xyz>
      </axis>
    </joint>

    <joint name="Wheel_2_joint" type="revolute">
      <parent>Chassis</parent>
      <child>Wheel_2</child>
      <pose>0 0 0 0 0 0</pose>
      <axis>
        <xyz>1 0 0</xyz>
      </axis>
    </joint>

    <joint name="Wheel_3_joint" type="revolute">
      <parent>Chassis</parent>
      <child>Wheel_3</child>
      <pose>0 0 0 0 0 0</pose>
      <axis>
        <xyz>0 1 0</xyz>
      </axis>
    </joint>

    <joint name="Wheel_4_joint" type="revolute">
      <parent>Chassis</parent>
      <child>Wheel_4</child>
      <pose>0 0 0 0 0 0</pose>
      <axis>
        <xyz>0 1 0</xyz>
      </axis>
    </joint>

    <plugin name="FTC_drive" filename="libFTC2.so"/>
  </model>
</sdf>
