<?xml version="1.0"?>
<sdf version="1.3">
  <model name="Polaris Ranger EV">
    <link name="chassis">
      <inertial>
        <!-- subtracted wheel weights from dry weight of 771 kg -->
        <!-- http://www.polaris.com/en-us/ranger-utv/side-by-sides/ranger-ev/specifications -->
        <mass>720.0</mass>
        <inertia>
          <ixx>140</ixx>
          <ixy>0.0</ixy><iyy>550</iyy>
          <ixz>0.0</ixz><iyz>0.0</iyz><izz>550</izz>
        </inertia>
      </inertial>
      <visual name="visual">
        <!-- rotate mesh to get to X-forward -->
        <pose>0 0 0 0 0 -1.570796</pose>
        <geometry>
          <mesh>
            <uri>model://polaris_ranger_ev/meshes/polaris.dae</uri>
          </mesh>
        </geometry>
      </visual>
      <collision name="chassis_bottom">
        <pose>0.0 0.0 0.35 0.0 0.0 0.0</pose> 
        <geometry>
          <box>
            <size>2.0 1.0 0.1</size>
          </box>
        </geometry>
      </collision>
      <collision name="cargo_bottom">
        <pose>-0.9 0.0 0.9 0.0 0.0 0.0</pose> 
        <geometry>
          <box>
            <size>0.9 1.2 0.01</size>
          </box>
        </geometry>
      </collision>
      <collision name="cargo_front">
        <pose>-0.45 0.0 1.025 0.0 0.0 0.0</pose> 
        <geometry>
          <box>
            <size>0.05 1.2 0.25</size>
          </box>
        </geometry>
      </collision>
      <collision name="cargo_back">
        <pose>-1.35 0.0 1.025 0.0 0.0 0.0</pose> 
        <geometry>
          <box>
            <size>0.05 1.2 0.25</size>
          </box>
        </geometry>
      </collision>
      <collision name="cargo_left">
        <pose>-0.9 0.6 1.025 0.0 0.0 0.0</pose> 
        <geometry>
          <box>
            <size>0.9 0.05 0.25</size>
          </box>
        </geometry>
      </collision>
      <collision name="cargo_right">
        <pose>-0.9 -0.6 1.025 0.0 0.0 0.0</pose> 
        <geometry>
          <box>
            <size>0.9 0.05 0.25</size>
          </box>
        </geometry>
      </collision>
      <collision name="seat">
        <pose>-0.1 0.0 0.625 0.0 0.0 0.0</pose> 
        <geometry>
          <box>
            <size>0.6 1.0 0.65</size>
          </box>
        </geometry>
      </collision>
      <collision name="seat_back">
        <pose>-0.3 0.0 1.125 0.0 -0.2 0.0</pose> 
        <geometry>
          <box>
            <size>0.1 1.0 0.4</size>
          </box>
        </geometry>
      </collision>
      <collision name="engine">
        <pose>0.95 0.0 0.7 0.0 0.0 0.0</pose> 
        <geometry>
          <box>
            <size>0.75 1.0 0.8</size>
          </box>
        </geometry>
      </collision>
      <collision name="steering_column">
        <pose>0.525 0.3 1.025 0.0 -0.8 0.0</pose> 
        <geometry>
          <cylinder>
            <radius>0.05</radius>
            <length>0.45</length>
          </cylinder>
        </geometry>
      </collision>
      <collision name="steering_wheel_post_left">
        <pose>0.37 0.38 1.2 1.570796 -0.8 0.0</pose> 
        <geometry>
          <cylinder>
            <radius>0.02</radius>
            <length>0.15</length>
          </cylinder>
        </geometry>
      </collision>
      <collision name="steering_wheel_post_right">
        <pose>0.37 0.23 1.2 1.570796 -0.8 0.0</pose> 
        <geometry>
          <cylinder>
            <radius>0.02</radius>
            <length>0.15</length>
          </cylinder>
        </geometry>
      </collision>
      <collision name="steering_wheel_post_middle">
        <pose>0.325 0.305 1.15 0.0 -2.3708 0.0</pose> 
        <geometry>
          <cylinder>
            <radius>0.02</radius>
            <length>0.15</length>
          </cylinder>
        </geometry>
      </collision>
    </link>
    <link name="rear_right_wheel">
      <pose>-0.85 -0.6 0.32 1.570796 0.0 0.0</pose>
      <inertial>
        <mass>12</mass><!-- estimated from http://www.rzrforums.net/wheels-tires/1729-tire-wheel-weights-most-sizes.html -->
        <inertia>
          <ixx>0.5</ixx>
          <ixy>0.0</ixy><iyy>0.5</iyy>
          <ixz>0.0</ixz><iyz>0.0</iyz><izz>1.0</izz>
        </inertia>
      </inertial>
      <collision name="collision">
        <geometry>
          <cylinder>
            <radius>0.32</radius>
            <length>0.23</length>
          </cylinder>
        </geometry>
        <surface>
          <friction>
            <ode>
              <mu>100000.0</mu>
              <mu2>100000.0</mu2>
              <slip1>0.0</slip1>
              <slip2>0.0</slip2>
            </ode>
          </friction>
        </surface>
      </collision>
    </link>
    <joint type="revolute" name="rear_right_wheel_joint">
      <pose>0.0 0.0 -0.1 0 0 0</pose>
      <child>rear_right_wheel</child>
      <parent>chassis</parent>
      <axis>
        <xyz>0 1 0</xyz>
      </axis>
      <physics><ode><limit>
        <cfm>0.000000</cfm>
        <erp>0.900000</erp>
      </limit></ode></physics>
    </joint>
    <link name="rear_left_wheel">
      <pose>-0.85 0.6 0.32 1.570796 0.0 0.0</pose>
      <inertial>
        <mass>12</mass><!-- estimated from http://www.rzrforums.net/wheels-tires/1729-tire-wheel-weights-most-sizes.html -->
        <inertia>
          <ixx>0.5</ixx>
          <ixy>0.0</ixy><iyy>0.5</iyy>
          <ixz>0.0</ixz><iyz>0.0</iyz><izz>1.0</izz>
        </inertia>
      </inertial>
      <collision name="collision">
        <geometry>
          <cylinder>
            <radius>0.32</radius>
            <length>0.23</length>
          </cylinder>
        </geometry>
        <surface>
          <friction>
            <ode>
              <mu>100000.0</mu>
              <mu2>100000.0</mu2>
              <slip1>0.0</slip1>
              <slip2>0.0</slip2>
            </ode>
          </friction>
        </surface>
      </collision>
    </link>
    <joint type="revolute" name="rear_left_wheel_joint">
      <child>rear_left_wheel</child>
      <parent>chassis</parent>
      <axis>
        <xyz>0 1 0</xyz>
      </axis>
      <physics><ode><limit>
        <cfm>0.000000</cfm>
        <erp>0.900000</erp>
      </limit></ode></physics>
    </joint>
    <link name="front_right_wheel">
      <pose>1.03 -0.6 0.32 1.570796 0.0 0.0</pose>
      <inertial>
        <mass>12</mass><!-- estimated from http://www.rzrforums.net/wheels-tires/1729-tire-wheel-weights-most-sizes.html -->
        <inertia>
          <ixx>0.5</ixx>
          <ixy>0.0</ixy><iyy>0.5</iyy>
          <ixz>0.0</ixz><iyz>0.0</iyz><izz>1.0</izz>
        </inertia>
      </inertial>
      <collision name="collision">
        <geometry>
          <cylinder>
            <radius>0.32</radius>
            <length>0.23</length>
          </cylinder>
        </geometry>
        <surface>
          <friction>
            <ode>
              <mu>100000.0</mu>
              <mu2>100000.0</mu2>
              <slip1>0.0</slip1>
              <slip2>0.0</slip2>
            </ode>
          </friction>
        </surface>
      </collision>
    </link>
    <link name="front_right_wheel_steering_block">
      <pose>1.03 -0.5 0.32 1.570796 0.0 0.0</pose>
      <inertial>
        <mass>1</mass>
        <inertia>
          <ixx>1.0</ixx>
          <ixy>0.0</ixy><iyy>1.0</iyy>
          <ixz>0.0</ixz><iyz>0.0</iyz><izz>1.0</izz>
        </inertia>
      </inertial>
      <collision name="collision">
        <geometry>
          <cylinder>
            <radius>0.05</radius>
            <length>0.01</length>
          </cylinder>
        </geometry>
      </collision>
    </link>
    <joint type="revolute" name="front_right_steering_joint">
      <child>front_right_wheel_steering_block</child>
      <parent>chassis</parent>
      <axis>
        <xyz>0 0 1</xyz>
        <limit>
          <lower>-1.0</lower>
          <upper>1.0</upper>
        </limit>
      </axis>
      <physics><ode><limit>
        <cfm>0.000000</cfm>
        <erp>0.900000</erp>
      </limit></ode></physics>
    </joint>
    <joint type="revolute" name="front_right_wheel_joint">
      <child>front_right_wheel</child>
      <parent>front_right_wheel_steering_block</parent>
      <axis>
        <xyz>0 1 0</xyz>
      </axis>
      <physics><ode><limit>
        <cfm>0.000000</cfm>
        <erp>0.900000</erp>
      </limit></ode></physics>
    </joint>
    <link name="front_left_wheel">
      <pose>1.03 0.6 0.32 1.570796 0.0 0.0</pose>
      <inertial>
        <mass>12</mass><!-- estimated from http://www.rzrforums.net/wheels-tires/1729-tire-wheel-weights-most-sizes.html -->
        <inertia>
          <ixx>0.5</ixx>
          <ixy>0.0</ixy><iyy>0.5</iyy>
          <ixz>0.0</ixz><iyz>0.0</iyz><izz>1.0</izz>
        </inertia>
      </inertial>
      <collision name="collision">
        <geometry>
          <cylinder>
            <radius>0.32</radius>
            <length>0.23</length>
          </cylinder>
        </geometry>
        <surface>
          <friction>
            <ode>
              <mu>100000.0</mu>
              <mu2>100000.0</mu2>
              <slip1>0.0</slip1>
              <slip2>0.0</slip2>
            </ode>
          </friction>
        </surface>
      </collision>
    </link>
    <link name="front_left_wheel_steering_block">
      <pose>1.03 0.5 0.32 1.570796 0.0 0.0</pose>
      <inertial>
        <mass>1</mass>
        <inertia>
          <ixx>1.0</ixx>
          <ixy>0.0</ixy><iyy>1.0</iyy>
          <ixz>0.0</ixz><iyz>0.0</iyz><izz>1.0</izz>
        </inertia>
      </inertial>
      <collision name="collision">
        <geometry>
          <cylinder>
            <radius>0.05</radius>
            <length>0.01</length>
          </cylinder>
        </geometry>
      </collision>
    </link>
    <joint type="revolute" name="front_left_steering_joint">
      <child>front_left_wheel_steering_block</child>
      <parent>chassis</parent>
      <axis>
        <xyz>0 0 1</xyz>
        <limit>
          <lower>-1.0</lower>
          <upper>1.0</upper>
        </limit>
      </axis>
      <physics><ode><limit>
        <cfm>0.000000</cfm>
        <erp>0.900000</erp>
      </limit></ode></physics>
    </joint>
    <joint type="revolute" name="front_left_wheel_joint">
      <child>front_left_wheel</child>
      <parent>front_left_wheel_steering_block</parent>
      <axis>
        <xyz>0 1 0</xyz>
      </axis>
      <physics><ode><limit>
        <cfm>0.000000</cfm>
        <erp>0.900000</erp>
      </limit></ode></physics>
    </joint>
  </model>
</sdf>
