<?xml version='1.0'?>
<sdf version='1.5'>

  <model name='buoyant_submarine'>
    <pose>0 0 1.5 1.5707963267948966 0 0</pose>
    <link name='body'>
      <pose>0 0 -1.07935 0 0 0</pose>
      <inertial>
        <mass>369.3072732306469</mass>
        <inertia>
          <ixx>216.352510900954</ixx>
          <ixy>0</ixy>
          <ixz>0</ixz>
          <iyy>216.352510900954</iyy>
          <iyz>0</iyz>
          <izz>16.61882729537911</izz>
        </inertia>
      </inertial>
      <visual name='body_visual'>
        <geometry>
          <cylinder>
            <radius>0.3</radius>
            <length>2.6</length>
          </cylinder>
        </geometry>
      </visual>
      <collision name='body_collision'>
        <geometry>
          <cylinder>
            <radius>0.3</radius>
            <length>2.6</length>
          </cylinder>
        </geometry>
      </collision>
      <visual name='spacer_visual'>
        <pose>0 0 1.378546 0 0 0</pose>
        <geometry>
          <cylinder>
            <radius>0.0933402</radius>
            <length>0.127211</length>
          </cylinder>
        </geometry>
      </visual>
      <collision name='spacer_collision'>
        <pose>0 0 1.378546 0 0 0</pose>
        <geometry>
          <cylinder>
            <radius>0.0933402</radius>
            <length>0.127211</length>
          </cylinder>
        </geometry>
      </collision>
    </link>

    <link name='propeller'>
      <pose>0 0 0.3455 3.14159 0 0</pose>
      <inertial>
        <mass>8.410409900000001</mass>
        <inertia>
          <ixx>0.17730244606378792</ixx>
          <ixy>0</ixy>
          <ixz>0</ixz>
          <iyy>0.17730244606378792</iyy>
          <iyz>0</iyz>
          <izz>0.35043374583333337</izz>
        </inertia>
      </inertial>

      <visual name='blade1_visual'>
        <pose>0.3433402 0 0 0.3490658503988659 0 0</pose>
        <geometry>
          <box>
            <size>0.5 0.154178 0.05455</size>
          </box>
        </geometry>
      </visual>
      <collision name='blade1_collision'>
        <pose>0.3433402 0 0 0.3490658503988659 0 0</pose>
        <geometry>
          <box>
            <size>0.5 0.154178 0.05455</size>
          </box>
        </geometry>
      </collision>
      <visual name='blade2_visual'>
        <pose>0 0.3433402 0 0.3490658503988659 0 1.5707963267948966</pose>
        <geometry>
          <box>
            <size>0.5 0.154178 0.05455</size>
          </box>
        </geometry>
      </visual>
      <collision name='blade2_collision'>
        <pose>0 0.3433402 0 0.3490658503988659 0 1.5707963267948966</pose>
        <geometry>
          <box>
            <size>0.5 0.154178 0.05455</size>
          </box>
        </geometry>
      </collision>

      <visual name='blade3_visual'>
        <pose>-0.3433402 0 0 -0.3490658503988659 0 0</pose>
        <geometry>
          <box>
            <size>0.5 0.154178 0.05455</size>
          </box>
        </geometry>
      </visual>
      <collision name='blade3_collision'>
        <pose>-0.3433402 0 0 -0.3490658503988659 0 0</pose>
        <geometry>
          <box>
            <size>0.5 0.154178 0.05455</size>
          </box>
        </geometry>
      </collision>
      <visual name='blade4_visual'>
        <pose>0 -0.3433402 0 -0.3490658503988659 0 1.5707963267948966</pose>
        <geometry>
          <box>
            <size>0.5 0.154178 0.05455</size>
          </box>
        </geometry>
      </visual>
      <collision name='blade4_collision'>
        <pose>0 -0.3433402 0 -0.3490658503988659 0 1.5707963267948966</pose>
        <geometry>
          <box>
            <size>0.5 0.154178 0.05455</size>
          </box>
        </geometry>
      </collision>

    </link>
    <joint name='spinning_joint' type='revolute'>
      <parent>body</parent>
      <child>propeller</child>
      <axis>
        <xyz>0 0 1</xyz>
        <use_parent_model_frame>1</use_parent_model_frame>
        <limit>
          <lower>-1e+12</lower>
          <upper>1e+12</upper>
          <effort>-1</effort>
          <velocity>-1</velocity>
        </limit>
        <dynamics>
          <spring_reference>0</spring_reference>
          <spring_stiffness>0</spring_stiffness>
          <damping>0</damping>
          <friction>0</friction>
        </dynamics>
      </axis>
      <pose>0 0 0 0 -0 0</pose>
      <physics>
        <ode>
          <cfm>0</cfm>
          <bounce>0</bounce>
          <velocity>0</velocity>
          <fudge_factor>0</fudge_factor>
          <limit>
            <cfm>0</cfm>
            <erp>0.2</erp>
          </limit>
          <suspension>
            <cfm>0</cfm>
            <erp>0.2</erp>
          </suspension>
        </ode>
      </physics>
    </joint>

    <allow_auto_disable>1</allow_auto_disable>


    <plugin name="submarine_body" filename="libLiftDragPlugin.so">
      <cla>0.8</cla>
      <cda>0.8</cda>
      <alpha_stall>1</alpha_stall>
      <alpha>1.1</alpha>
      <cla_stall>0</cla_stall>
      <upward>1 0 0</upward>
      <forward>0 0 -1</forward>
      <area>4.900884539600077</area>
      <air_density>1000</air_density>
      <link_name>body</link_name>
    </plugin>

    <plugin name="submarine_propeller" filename="libLiftDragPlugin.so">
      <cla>1.05</cla>
      <cda>1.05</cda>
      <alpha_stall>1</alpha_stall>
      <alpha>1.1</alpha>
      <cla_stall>0</cla_stall>
      <upward>1 0 0</upward>
      <forward>0 0 -1</forward>
      <area>0.9021952792000001</area>
      <air_density>1000</air_density>
      <link_name>propeller</link_name>
    </plugin>

    <plugin name="buoyancy" filename="libBuoyancyPlugin.so">
      <fluid_density>1000</fluid_density>
    </plugin>

  </model>
</sdf>
