<?xml version='1.0'?>

<sdf version='1.5'>
  <model name='Foosball'>
    <link name='table'>
      <pose>0 0 0 0 -0 0</pose>

      <visual name='base'>
        <pose>0 0 0 0 -0 0</pose>
        <geometry>
          <box>
            <size>1.4218 0.762 0.1</size>
          </box>
        </geometry>
        <material>
          <script>
            <uri>file://media/materials/scripts/gazebo.material</uri>
            <name>Gazebo/Wood</name>
          </script>
        </material>
      </visual>

      
        <visual name="sideA">
          <pose>0 -0.36195 0.2532 0 -0 0</pose>
          <geometry>
            <box>
              <size>1.1938 0.0381 0.4064</size>
            </box>
          </geometry>
          <material>
            <script>
              <uri>file://media/materials/scripts/gazebo.material</uri>
              <name>Gazebo/Wood</name>
            </script>
          </material>
        </visual>
        <collision name="sideA">
          <pose>0 -0.36195 0.2532 0 -0 0</pose>
          <geometry>
            <box>
              <size>1.1938 0.0381 0.4064</size>
            </box>
          </geometry>
        </collision>
      
        <visual name="sideB">
          <pose>0 0.36195 0.2532 0 -0 0</pose>
          <geometry>
            <box>
              <size>1.1938 0.0381 0.4064</size>
            </box>
          </geometry>
          <material>
            <script>
              <uri>file://media/materials/scripts/gazebo.material</uri>
              <name>Gazebo/Wood</name>
            </script>
          </material>
        </visual>
        <collision name="sideB">
          <pose>0 0.36195 0.2532 0 -0 0</pose>
          <geometry>
            <box>
              <size>1.1938 0.0381 0.4064</size>
            </box>
          </geometry>
        </collision>
      

      
        <visual name="goalA">
          <pose>0.5969 0 0.2532 0 1.5707963267948966 0</pose>
          <geometry>
            <polyline>
              <height>0.114</height>
              <point>0.2032 -0.381</point>
              <point>-0.2032 -0.381</point>
              <point>-0.2032 0.381</point>
              <point>0.2032 0.381</point>
              <point>0.10319999999999999 0.1</point>
              <point>-0.1 0.1</point>
              <point>-0.1 -0.1</point>
              <point>0.10319999999999999 -0.1</point>
            </polyline>
          </geometry>
          <material>
            <script>
              <uri>file://media/materials/scripts/gazebo.material</uri>
              <name>Gazebo/Wood</name>
            </script>
          </material>
        </visual> 
        <collision name="goalA">
          <pose>0.5969 0 0.2532 0 1.5707963267948966 0</pose>
          <geometry>
            <polyline>
              <height>0.114</height>
              <point>0.2032 -0.381</point>
              <point>-0.2032 -0.381</point>
              <point>-0.2032 0.381</point>
              <point>0.2032 0.381</point>
              <point>0.2032 0.1</point>
              <point>-0.1 0.1</point>
              <point>-0.1 -0.1</point>
              <point>0.2032 -0.1</point>
            </polyline>
          </geometry>
        </collision>
      
        <visual name="goalB">
          <pose>-0.5969 0 0.2532 3.141592653589793 1.5707963267948966 0</pose>
          <geometry>
            <polyline>
              <height>0.114</height>
              <point>0.2032 -0.381</point>
              <point>-0.2032 -0.381</point>
              <point>-0.2032 0.381</point>
              <point>0.2032 0.381</point>
              <point>0.10319999999999999 0.1</point>
              <point>-0.1 0.1</point>
              <point>-0.1 -0.1</point>
              <point>0.10319999999999999 -0.1</point>
            </polyline>
          </geometry>
          <material>
            <script>
              <uri>file://media/materials/scripts/gazebo.material</uri>
              <name>Gazebo/Wood</name>
            </script>
          </material>
        </visual> 
        <collision name="goalB">
          <pose>-0.5969 0 0.2532 3.141592653589793 1.5707963267948966 0</pose>
          <geometry>
            <polyline>
              <height>0.114</height>
              <point>0.2032 -0.381</point>
              <point>-0.2032 -0.381</point>
              <point>-0.2032 0.381</point>
              <point>0.2032 0.381</point>
              <point>0.2032 0.1</point>
              <point>-0.1 0.1</point>
              <point>-0.1 -0.1</point>
              <point>0.2032 -0.1</point>
            </polyline>
          </geometry>
        </collision>
      

      <visual name='ground'>
        <pose>0 0 0.15000000000000002 0 -0 0</pose>
        <geometry>
          <box>
            <size>1.1938 0.6858 0.2</size>
          </box>
        </geometry>
        <material>
          <ambient>0.3 0.3 0.3 1</ambient>
          <diffuse>0.7 0.7 0.7 1</diffuse>
          <specular>0.01 0.01 0.01 1</specular>
          <emissive>0 0.1 0 1</emissive>
        </material>
      </visual>
      <collision name='ground'>
        <pose>0 0 0.15000000000000002 0 -0 0</pose>
        <geometry>
          <box>
            <size>1.1938 0.6858 0.2</size>
          </box>
        </geometry>
      </collision>
    </link>

    <joint name='table_world' type='prismatic'>
      <parent>world</parent>
      <child>table</child>
      <axis>
        <xyz>0 0 1</xyz>
        <limit>
          <lower>0</lower>
          <upper>0.1</upper>
        </limit>
      </axis>
      <pose>0 0 0 0 -0 0</pose>
    </joint>

    
      <link name="shaftA0_bridge">
        <pose>0.522287 0 0.355381 1.5707963267948966 -0 0</pose>
      </link>    
      <link name="shaftA0">
        <pose>0.522287 0 0.355381 1.5707963267948966 -0 0</pose>
        <visual name='rod'>
          <pose>0 0 0 0 -0 0</pose>
          <geometry>
            <cylinder>
              <radius>0.00779907</radius>
              <length>1.2</length>
            </cylinder>
          </geometry>
          <material>
            <script>
              <uri>file://media/materials/scripts/gazebo.material</uri>
              <name>Gazebo/Grey</name>
            </script>
          </material>
        </visual>
        <collision name='rod'>
          <pose>0 0 0 0 -0 0</pose>
          <geometry>
            <cylinder>
              <radius>0.00779907</radius>
              <length>1.2</length>
            </cylinder>
          </geometry>
        </collision>
        
        <visual name='player_center'>
          <pose>0 0 0 1.5707963267948966 -0 0</pose>
          <geometry>
            <polyline>
              <height>0.1</height>
              <point>-0.00935486 -0.00548224</point>
              <point>-0.00935486 0.00548224</point>
              <point>-0.00887948 0.00844526</point>
              <point>-0.00755453 0.011014</point>
              <point>-0.00553179 0.0130368</point>
              <point>-0.00296304 0.0143617</point>
              <point>-3.95112e-08 0.0148371</point>
              <point>0.002963 0.0143617</point>
              <point>0.00553178 0.0130368</point>
              <point>0.00755453 0.011014</point>
              <point>0.00887948 0.00844526</point>
              <point>0.00935486 0.00548224</point>
              <point>0.00935486 -0.00548224</point>
              <point>0.00887948 -0.00844525</point>
              <point>0.00755453 -0.011014</point>
              <point>0.00553178 -0.0130368</point>
              <point>0.002963 -0.0143617</point>
              <point>-3.95112e-08 -0.0148371</point>
              <point>-0.00296304 -0.0143617</point>
              <point>-0.00553179 -0.0130368</point>
              <point>-0.00755453 -0.011014</point>
              <point>-0.00887948 -0.00844525</point>
              <point>-0.00935486 -0.00548224</point>
            </polyline>
          </geometry>
          <material>
            <emissive>0 1 0 1</emissive>
          </material>
        </visual>
        <collision name='player_center'>
          <pose>0 0 0 1.5707963267948966 -0 0</pose>
          <geometry>
            <polyline>
              <height>0.1</height>
              <point>-0.00935486 -0.00548224</point>
              <point>-0.00935486 0.00548224</point>
              <point>-0.00887948 0.00844526</point>
              <point>-0.00755453 0.011014</point>
              <point>-0.00553179 0.0130368</point>
              <point>-0.00296304 0.0143617</point>
              <point>-3.95112e-08 0.0148371</point>
              <point>0.002963 0.0143617</point>
              <point>0.00553178 0.0130368</point>
              <point>0.00755453 0.011014</point>
              <point>0.00887948 0.00844526</point>
              <point>0.00935486 0.00548224</point>
              <point>0.00935486 -0.00548224</point>
              <point>0.00887948 -0.00844525</point>
              <point>0.00755453 -0.011014</point>
              <point>0.00553178 -0.0130368</point>
              <point>0.002963 -0.0143617</point>
              <point>-3.95112e-08 -0.0148371</point>
              <point>-0.00296304 -0.0143617</point>
              <point>-0.00553179 -0.0130368</point>
              <point>-0.00755453 -0.011014</point>
              <point>-0.00887948 -0.00844525</point>
              <point>-0.00935486 -0.00548224</point>
            </polyline>
          </geometry>
        </collision>
     
     
     
      </link>
    
    <joint name="transA0" type="prismatic">
      <parent>world</parent>
      <child>shaftA0_bridge</child>
      <axis>
        <xyz>0 0 1</xyz>
        <use_parent_model_frame>0</use_parent_model_frame>
        <limit>
          <lower>-0.09</lower>
          <upper>0.09</upper>
        </limit>
      </axis>
      <pose>0 0 0 0 -0 0</pose>
    </joint>
    <joint name="rotA0" type="revolute">
      <parent>shaftA0_bridge</parent>
      <child>shaftA0</child>
      <axis>
        <xyz>0 0 1</xyz>
        <limit>
          <lower>-1000</lower>
          <upper>1000</upper>
        </limit>
      </axis>
      <pose>0 0 0 0 -0 0</pose>
    </joint>
    
      <link name="shaftA1_bridge">
        <pose>0.373062 0 0.355381 1.5707963267948966 -0 0</pose>
      </link>    
      <link name="shaftA1">
        <pose>0.373062 0 0.355381 1.5707963267948966 -0 0</pose>
        <visual name='rod'>
          <pose>0 0 0 0 -0 0</pose>
          <geometry>
            <cylinder>
              <radius>0.00779907</radius>
              <length>1.2</length>
            </cylinder>
          </geometry>
          <material>
            <script>
              <uri>file://media/materials/scripts/gazebo.material</uri>
              <name>Gazebo/Grey</name>
            </script>
          </material>
        </visual>
        <collision name='rod'>
          <pose>0 0 0 0 -0 0</pose>
          <geometry>
            <cylinder>
              <radius>0.00779907</radius>
              <length>1.2</length>
            </cylinder>
          </geometry>
        </collision>
        
     
      
       <visual name='player_side_1'>
        <pose>0 0 0.1 1.5707963267948966 -0 0</pose>
        <geometry>
          <polyline>
            <height>0.1</height>
            <point>-0.00935486 -0.00548224</point>
            <point>-0.00935486 0.00548224</point>
            <point>-0.00887948 0.00844526</point>
            <point>-0.00755453 0.011014</point>
            <point>-0.00553179 0.0130368</point>
            <point>-0.00296304 0.0143617</point>
            <point>-3.95112e-08 0.0148371</point>
            <point>0.002963 0.0143617</point>
            <point>0.00553178 0.0130368</point>
            <point>0.00755453 0.011014</point>
            <point>0.00887948 0.00844526</point>
            <point>0.00935486 0.00548224</point>
            <point>0.00935486 -0.00548224</point>
            <point>0.00887948 -0.00844525</point>
            <point>0.00755453 -0.011014</point>
            <point>0.00553178 -0.0130368</point>
            <point>0.002963 -0.0143617</point>
            <point>-3.95112e-08 -0.0148371</point>
            <point>-0.00296304 -0.0143617</point>
            <point>-0.00553179 -0.0130368</point>
            <point>-0.00755453 -0.011014</point>
            <point>-0.00887948 -0.00844525</point>
            <point>-0.00935486 -0.00548224</point>
          </polyline>
        </geometry>
        <material>
          <emissive>0 1 0 1</emissive>
        </material>
      </visual>
      <collision name='player_side_1'>
        <pose>0 0 0.1 1.5707963267948966 -0 0</pose>
        <geometry>
          <polyline>
            <height>0.1</height>
            <point>-0.00935486 -0.00548224</point>
            <point>-0.00935486 0.00548224</point>
            <point>-0.00887948 0.00844526</point>
            <point>-0.00755453 0.011014</point>
            <point>-0.00553179 0.0130368</point>
            <point>-0.00296304 0.0143617</point>
            <point>-3.95112e-08 0.0148371</point>
            <point>0.002963 0.0143617</point>
            <point>0.00553178 0.0130368</point>
            <point>0.00755453 0.011014</point>
            <point>0.00887948 0.00844526</point>
            <point>0.00935486 0.00548224</point>
            <point>0.00935486 -0.00548224</point>
            <point>0.00887948 -0.00844525</point>
            <point>0.00755453 -0.011014</point>
            <point>0.00553178 -0.0130368</point>
            <point>0.002963 -0.0143617</point>
            <point>-3.95112e-08 -0.0148371</point>
            <point>-0.00296304 -0.0143617</point>
            <point>-0.00553179 -0.0130368</point>
            <point>-0.00755453 -0.011014</point>
            <point>-0.00887948 -0.00844525</point>
            <point>-0.00935486 -0.00548224</point>
          </polyline>
        </geometry>
      </collision>
      <visual name='player_side_2'>
        <pose>0 0 -0.1 1.5707963267948966 -0 0</pose>
        <geometry>
          <polyline>
            <height>0.1</height>
            <point>-0.00935486 -0.00548224</point>
            <point>-0.00935486 0.00548224</point>
            <point>-0.00887948 0.00844526</point>
            <point>-0.00755453 0.011014</point>
            <point>-0.00553179 0.0130368</point>
            <point>-0.00296304 0.0143617</point>
            <point>-3.95112e-08 0.0148371</point>
            <point>0.002963 0.0143617</point>
            <point>0.00553178 0.0130368</point>
            <point>0.00755453 0.011014</point>
            <point>0.00887948 0.00844526</point>
            <point>0.00935486 0.00548224</point>
            <point>0.00935486 -0.00548224</point>
            <point>0.00887948 -0.00844525</point>
            <point>0.00755453 -0.011014</point>
            <point>0.00553178 -0.0130368</point>
            <point>0.002963 -0.0143617</point>
            <point>-3.95112e-08 -0.0148371</point>
            <point>-0.00296304 -0.0143617</point>
            <point>-0.00553179 -0.0130368</point>
            <point>-0.00755453 -0.011014</point>
            <point>-0.00887948 -0.00844525</point>
            <point>-0.00935486 -0.00548224</point>
          </polyline>
        </geometry>
        <material>
          <emissive>0 1 0 1</emissive>
        </material>
      </visual>
      <collision name='player_side_2'>
        <pose>0 0 -0.1 1.5707963267948966 -0 0</pose>
        <geometry>
          <polyline>
            <height>0.1</height>
            <point>-0.00935486 -0.00548224</point>
            <point>-0.00935486 0.00548224</point>
            <point>-0.00887948 0.00844526</point>
            <point>-0.00755453 0.011014</point>
            <point>-0.00553179 0.0130368</point>
            <point>-0.00296304 0.0143617</point>
            <point>-3.95112e-08 0.0148371</point>
            <point>0.002963 0.0143617</point>
            <point>0.00553178 0.0130368</point>
            <point>0.00755453 0.011014</point>
            <point>0.00887948 0.00844526</point>
            <point>0.00935486 0.00548224</point>
            <point>0.00935486 -0.00548224</point>
            <point>0.00887948 -0.00844525</point>
            <point>0.00755453 -0.011014</point>
            <point>0.00553178 -0.0130368</point>
            <point>0.002963 -0.0143617</point>
            <point>-3.95112e-08 -0.0148371</point>
            <point>-0.00296304 -0.0143617</point>
            <point>-0.00553179 -0.0130368</point>
            <point>-0.00755453 -0.011014</point>
            <point>-0.00887948 -0.00844525</point>
            <point>-0.00935486 -0.00548224</point>
          </polyline>
        </geometry>
      </collision>
      
      </link>
    
    <joint name="transA1" type="prismatic">
      <parent>world</parent>
      <child>shaftA1_bridge</child>
      <axis>
        <xyz>0 0 1</xyz>
        <use_parent_model_frame>0</use_parent_model_frame>
        <limit>
          <lower>-0.23</lower>
          <upper>0.23</upper>
        </limit>
      </axis>
      <pose>0 0 0 0 -0 0</pose>
    </joint>
    <joint name="rotA1" type="revolute">
      <parent>shaftA1_bridge</parent>
      <child>shaftA1</child>
      <axis>
        <xyz>0 0 1</xyz>
        <limit>
          <lower>-1000</lower>
          <upper>1000</upper>
        </limit>
      </axis>
      <pose>0 0 0 0 -0 0</pose>
    </joint>
    
      <link name="shaftA2_bridge">
        <pose>0.074612 0 0.355381 1.5707963267948966 -0 0</pose>
      </link>    
      <link name="shaftA2">
        <pose>0.074612 0 0.355381 1.5707963267948966 -0 0</pose>
        <visual name='rod'>
          <pose>0 0 0 0 -0 0</pose>
          <geometry>
            <cylinder>
              <radius>0.00779907</radius>
              <length>1.2</length>
            </cylinder>
          </geometry>
          <material>
            <script>
              <uri>file://media/materials/scripts/gazebo.material</uri>
              <name>Gazebo/Grey</name>
            </script>
          </material>
        </visual>
        <collision name='rod'>
          <pose>0 0 0 0 -0 0</pose>
          <geometry>
            <cylinder>
              <radius>0.00779907</radius>
              <length>1.2</length>
            </cylinder>
          </geometry>
        </collision>
        
        <visual name='player_center'>
          <pose>0 0 0 1.5707963267948966 -0 0</pose>
          <geometry>
            <polyline>
              <height>0.1</height>
              <point>-0.00935486 -0.00548224</point>
              <point>-0.00935486 0.00548224</point>
              <point>-0.00887948 0.00844526</point>
              <point>-0.00755453 0.011014</point>
              <point>-0.00553179 0.0130368</point>
              <point>-0.00296304 0.0143617</point>
              <point>-3.95112e-08 0.0148371</point>
              <point>0.002963 0.0143617</point>
              <point>0.00553178 0.0130368</point>
              <point>0.00755453 0.011014</point>
              <point>0.00887948 0.00844526</point>
              <point>0.00935486 0.00548224</point>
              <point>0.00935486 -0.00548224</point>
              <point>0.00887948 -0.00844525</point>
              <point>0.00755453 -0.011014</point>
              <point>0.00553178 -0.0130368</point>
              <point>0.002963 -0.0143617</point>
              <point>-3.95112e-08 -0.0148371</point>
              <point>-0.00296304 -0.0143617</point>
              <point>-0.00553179 -0.0130368</point>
              <point>-0.00755453 -0.011014</point>
              <point>-0.00887948 -0.00844525</point>
              <point>-0.00935486 -0.00548224</point>
            </polyline>
          </geometry>
          <material>
            <emissive>0 1 0 1</emissive>
          </material>
        </visual>
        <collision name='player_center'>
          <pose>0 0 0 1.5707963267948966 -0 0</pose>
          <geometry>
            <polyline>
              <height>0.1</height>
              <point>-0.00935486 -0.00548224</point>
              <point>-0.00935486 0.00548224</point>
              <point>-0.00887948 0.00844526</point>
              <point>-0.00755453 0.011014</point>
              <point>-0.00553179 0.0130368</point>
              <point>-0.00296304 0.0143617</point>
              <point>-3.95112e-08 0.0148371</point>
              <point>0.002963 0.0143617</point>
              <point>0.00553178 0.0130368</point>
              <point>0.00755453 0.011014</point>
              <point>0.00887948 0.00844526</point>
              <point>0.00935486 0.00548224</point>
              <point>0.00935486 -0.00548224</point>
              <point>0.00887948 -0.00844525</point>
              <point>0.00755453 -0.011014</point>
              <point>0.00553178 -0.0130368</point>
              <point>0.002963 -0.0143617</point>
              <point>-3.95112e-08 -0.0148371</point>
              <point>-0.00296304 -0.0143617</point>
              <point>-0.00553179 -0.0130368</point>
              <point>-0.00755453 -0.011014</point>
              <point>-0.00887948 -0.00844525</point>
              <point>-0.00935486 -0.00548224</point>
            </polyline>
          </geometry>
        </collision>
     
      
       <visual name='player_mid_1'>
        <pose>0 0 0.26 1.5707963267948966 -0 0</pose>
        <geometry>
          <polyline>
            <height>0.1</height>
            <point>-0.00935486 -0.00548224</point>
            <point>-0.00935486 0.00548224</point>
            <point>-0.00887948 0.00844526</point>
            <point>-0.00755453 0.011014</point>
            <point>-0.00553179 0.0130368</point>
            <point>-0.00296304 0.0143617</point>
            <point>-3.95112e-08 0.0148371</point>
            <point>0.002963 0.0143617</point>
            <point>0.00553178 0.0130368</point>
            <point>0.00755453 0.011014</point>
            <point>0.00887948 0.00844526</point>
            <point>0.00935486 0.00548224</point>
            <point>0.00935486 -0.00548224</point>
            <point>0.00887948 -0.00844525</point>
            <point>0.00755453 -0.011014</point>
            <point>0.00553178 -0.0130368</point>
            <point>0.002963 -0.0143617</point>
            <point>-3.95112e-08 -0.0148371</point>
            <point>-0.00296304 -0.0143617</point>
            <point>-0.00553179 -0.0130368</point>
            <point>-0.00755453 -0.011014</point>
            <point>-0.00887948 -0.00844525</point>
            <point>-0.00935486 -0.00548224</point>
          </polyline>
        </geometry>
        <material>
          <emissive>0 1 0 1</emissive>
        </material>
      </visual>
      <collision name='player_mid_1'>
        <pose>0 0 0.26 1.5707963267948966 -0 0</pose>
        <geometry>
          <polyline>
            <height>0.1</height>
            <point>-0.00935486 -0.00548224</point>
            <point>-0.00935486 0.00548224</point>
            <point>-0.00887948 0.00844526</point>
            <point>-0.00755453 0.011014</point>
            <point>-0.00553179 0.0130368</point>
            <point>-0.00296304 0.0143617</point>
            <point>-3.95112e-08 0.0148371</point>
            <point>0.002963 0.0143617</point>
            <point>0.00553178 0.0130368</point>
            <point>0.00755453 0.011014</point>
            <point>0.00887948 0.00844526</point>
            <point>0.00935486 0.00548224</point>
            <point>0.00935486 -0.00548224</point>
            <point>0.00887948 -0.00844525</point>
            <point>0.00755453 -0.011014</point>
            <point>0.00553178 -0.0130368</point>
            <point>0.002963 -0.0143617</point>
            <point>-3.95112e-08 -0.0148371</point>
            <point>-0.00296304 -0.0143617</point>
            <point>-0.00553179 -0.0130368</point>
            <point>-0.00755453 -0.011014</point>
            <point>-0.00887948 -0.00844525</point>
            <point>-0.00935486 -0.00548224</point>
          </polyline>
        </geometry>
      </collision>
      <visual name='player_mid_2'>
        <pose>0 0 -0.26 1.5707963267948966 -0 0</pose>
        <geometry>
          <polyline>
            <height>0.1</height>
            <point>-0.00935486 -0.00548224</point>
            <point>-0.00935486 0.00548224</point>
            <point>-0.00887948 0.00844526</point>
            <point>-0.00755453 0.011014</point>
            <point>-0.00553179 0.0130368</point>
            <point>-0.00296304 0.0143617</point>
            <point>-3.95112e-08 0.0148371</point>
            <point>0.002963 0.0143617</point>
            <point>0.00553178 0.0130368</point>
            <point>0.00755453 0.011014</point>
            <point>0.00887948 0.00844526</point>
            <point>0.00935486 0.00548224</point>
            <point>0.00935486 -0.00548224</point>
            <point>0.00887948 -0.00844525</point>
            <point>0.00755453 -0.011014</point>
            <point>0.00553178 -0.0130368</point>
            <point>0.002963 -0.0143617</point>
            <point>-3.95112e-08 -0.0148371</point>
            <point>-0.00296304 -0.0143617</point>
            <point>-0.00553179 -0.0130368</point>
            <point>-0.00755453 -0.011014</point>
            <point>-0.00887948 -0.00844525</point>
            <point>-0.00935486 -0.00548224</point>
          </polyline>
        </geometry>
        <material>
          <emissive>0 1 0 1</emissive>
        </material>
      </visual>
      <collision name='player_mid_2'>
        <pose>0 0 -0.26 1.5707963267948966 -0 0</pose>
        <geometry>
          <polyline>
            <height>0.1</height>
            <point>-0.00935486 -0.00548224</point>
            <point>-0.00935486 0.00548224</point>
            <point>-0.00887948 0.00844526</point>
            <point>-0.00755453 0.011014</point>
            <point>-0.00553179 0.0130368</point>
            <point>-0.00296304 0.0143617</point>
            <point>-3.95112e-08 0.0148371</point>
            <point>0.002963 0.0143617</point>
            <point>0.00553178 0.0130368</point>
            <point>0.00755453 0.011014</point>
            <point>0.00887948 0.00844526</point>
            <point>0.00935486 0.00548224</point>
            <point>0.00935486 -0.00548224</point>
            <point>0.00887948 -0.00844525</point>
            <point>0.00755453 -0.011014</point>
            <point>0.00553178 -0.0130368</point>
            <point>0.002963 -0.0143617</point>
            <point>-3.95112e-08 -0.0148371</point>
            <point>-0.00296304 -0.0143617</point>
            <point>-0.00553179 -0.0130368</point>
            <point>-0.00755453 -0.011014</point>
            <point>-0.00887948 -0.00844525</point>
            <point>-0.00935486 -0.00548224</point>
          </polyline>
        </geometry>
      </collision>
     
      
       <visual name='player_side_1'>
        <pose>0 0 0.13 1.5707963267948966 -0 0</pose>
        <geometry>
          <polyline>
            <height>0.1</height>
            <point>-0.00935486 -0.00548224</point>
            <point>-0.00935486 0.00548224</point>
            <point>-0.00887948 0.00844526</point>
            <point>-0.00755453 0.011014</point>
            <point>-0.00553179 0.0130368</point>
            <point>-0.00296304 0.0143617</point>
            <point>-3.95112e-08 0.0148371</point>
            <point>0.002963 0.0143617</point>
            <point>0.00553178 0.0130368</point>
            <point>0.00755453 0.011014</point>
            <point>0.00887948 0.00844526</point>
            <point>0.00935486 0.00548224</point>
            <point>0.00935486 -0.00548224</point>
            <point>0.00887948 -0.00844525</point>
            <point>0.00755453 -0.011014</point>
            <point>0.00553178 -0.0130368</point>
            <point>0.002963 -0.0143617</point>
            <point>-3.95112e-08 -0.0148371</point>
            <point>-0.00296304 -0.0143617</point>
            <point>-0.00553179 -0.0130368</point>
            <point>-0.00755453 -0.011014</point>
            <point>-0.00887948 -0.00844525</point>
            <point>-0.00935486 -0.00548224</point>
          </polyline>
        </geometry>
        <material>
          <emissive>0 1 0 1</emissive>
        </material>
      </visual>
      <collision name='player_side_1'>
        <pose>0 0 0.13 1.5707963267948966 -0 0</pose>
        <geometry>
          <polyline>
            <height>0.1</height>
            <point>-0.00935486 -0.00548224</point>
            <point>-0.00935486 0.00548224</point>
            <point>-0.00887948 0.00844526</point>
            <point>-0.00755453 0.011014</point>
            <point>-0.00553179 0.0130368</point>
            <point>-0.00296304 0.0143617</point>
            <point>-3.95112e-08 0.0148371</point>
            <point>0.002963 0.0143617</point>
            <point>0.00553178 0.0130368</point>
            <point>0.00755453 0.011014</point>
            <point>0.00887948 0.00844526</point>
            <point>0.00935486 0.00548224</point>
            <point>0.00935486 -0.00548224</point>
            <point>0.00887948 -0.00844525</point>
            <point>0.00755453 -0.011014</point>
            <point>0.00553178 -0.0130368</point>
            <point>0.002963 -0.0143617</point>
            <point>-3.95112e-08 -0.0148371</point>
            <point>-0.00296304 -0.0143617</point>
            <point>-0.00553179 -0.0130368</point>
            <point>-0.00755453 -0.011014</point>
            <point>-0.00887948 -0.00844525</point>
            <point>-0.00935486 -0.00548224</point>
          </polyline>
        </geometry>
      </collision>
      <visual name='player_side_2'>
        <pose>0 0 -0.13 1.5707963267948966 -0 0</pose>
        <geometry>
          <polyline>
            <height>0.1</height>
            <point>-0.00935486 -0.00548224</point>
            <point>-0.00935486 0.00548224</point>
            <point>-0.00887948 0.00844526</point>
            <point>-0.00755453 0.011014</point>
            <point>-0.00553179 0.0130368</point>
            <point>-0.00296304 0.0143617</point>
            <point>-3.95112e-08 0.0148371</point>
            <point>0.002963 0.0143617</point>
            <point>0.00553178 0.0130368</point>
            <point>0.00755453 0.011014</point>
            <point>0.00887948 0.00844526</point>
            <point>0.00935486 0.00548224</point>
            <point>0.00935486 -0.00548224</point>
            <point>0.00887948 -0.00844525</point>
            <point>0.00755453 -0.011014</point>
            <point>0.00553178 -0.0130368</point>
            <point>0.002963 -0.0143617</point>
            <point>-3.95112e-08 -0.0148371</point>
            <point>-0.00296304 -0.0143617</point>
            <point>-0.00553179 -0.0130368</point>
            <point>-0.00755453 -0.011014</point>
            <point>-0.00887948 -0.00844525</point>
            <point>-0.00935486 -0.00548224</point>
          </polyline>
        </geometry>
        <material>
          <emissive>0 1 0 1</emissive>
        </material>
      </visual>
      <collision name='player_side_2'>
        <pose>0 0 -0.13 1.5707963267948966 -0 0</pose>
        <geometry>
          <polyline>
            <height>0.1</height>
            <point>-0.00935486 -0.00548224</point>
            <point>-0.00935486 0.00548224</point>
            <point>-0.00887948 0.00844526</point>
            <point>-0.00755453 0.011014</point>
            <point>-0.00553179 0.0130368</point>
            <point>-0.00296304 0.0143617</point>
            <point>-3.95112e-08 0.0148371</point>
            <point>0.002963 0.0143617</point>
            <point>0.00553178 0.0130368</point>
            <point>0.00755453 0.011014</point>
            <point>0.00887948 0.00844526</point>
            <point>0.00935486 0.00548224</point>
            <point>0.00935486 -0.00548224</point>
            <point>0.00887948 -0.00844525</point>
            <point>0.00755453 -0.011014</point>
            <point>0.00553178 -0.0130368</point>
            <point>0.002963 -0.0143617</point>
            <point>-3.95112e-08 -0.0148371</point>
            <point>-0.00296304 -0.0143617</point>
            <point>-0.00553179 -0.0130368</point>
            <point>-0.00755453 -0.011014</point>
            <point>-0.00887948 -0.00844525</point>
            <point>-0.00935486 -0.00548224</point>
          </polyline>
        </geometry>
      </collision>
      
      </link>
    
    <joint name="transA2" type="prismatic">
      <parent>world</parent>
      <child>shaftA2_bridge</child>
      <axis>
        <xyz>0 0 1</xyz>
        <use_parent_model_frame>0</use_parent_model_frame>
        <limit>
          <lower>-0.07</lower>
          <upper>0.07</upper>
        </limit>
      </axis>
      <pose>0 0 0 0 -0 0</pose>
    </joint>
    <joint name="rotA2" type="revolute">
      <parent>shaftA2_bridge</parent>
      <child>shaftA2</child>
      <axis>
        <xyz>0 0 1</xyz>
        <limit>
          <lower>-1000</lower>
          <upper>1000</upper>
        </limit>
      </axis>
      <pose>0 0 0 0 -0 0</pose>
    </joint>
    
      <link name="shaftA3_bridge">
        <pose>0.223837 0 0.355381 1.5707963267948966 -0 0</pose>
      </link>    
      <link name="shaftA3">
        <pose>0.223837 0 0.355381 1.5707963267948966 -0 0</pose>
        <visual name='rod'>
          <pose>0 0 0 0 -0 0</pose>
          <geometry>
            <cylinder>
              <radius>0.00779907</radius>
              <length>1.2</length>
            </cylinder>
          </geometry>
          <material>
            <script>
              <uri>file://media/materials/scripts/gazebo.material</uri>
              <name>Gazebo/Grey</name>
            </script>
          </material>
        </visual>
        <collision name='rod'>
          <pose>0 0 0 0 -0 0</pose>
          <geometry>
            <cylinder>
              <radius>0.00779907</radius>
              <length>1.2</length>
            </cylinder>
          </geometry>
        </collision>
        
        <visual name='player_center'>
          <pose>0 0 0 1.5707963267948966 -0 0</pose>
          <geometry>
            <polyline>
              <height>0.1</height>
              <point>-0.00935486 -0.00548224</point>
              <point>-0.00935486 0.00548224</point>
              <point>-0.00887948 0.00844526</point>
              <point>-0.00755453 0.011014</point>
              <point>-0.00553179 0.0130368</point>
              <point>-0.00296304 0.0143617</point>
              <point>-3.95112e-08 0.0148371</point>
              <point>0.002963 0.0143617</point>
              <point>0.00553178 0.0130368</point>
              <point>0.00755453 0.011014</point>
              <point>0.00887948 0.00844526</point>
              <point>0.00935486 0.00548224</point>
              <point>0.00935486 -0.00548224</point>
              <point>0.00887948 -0.00844525</point>
              <point>0.00755453 -0.011014</point>
              <point>0.00553178 -0.0130368</point>
              <point>0.002963 -0.0143617</point>
              <point>-3.95112e-08 -0.0148371</point>
              <point>-0.00296304 -0.0143617</point>
              <point>-0.00553179 -0.0130368</point>
              <point>-0.00755453 -0.011014</point>
              <point>-0.00887948 -0.00844525</point>
              <point>-0.00935486 -0.00548224</point>
            </polyline>
          </geometry>
          <material>
            <emissive>0 1 0 1</emissive>
          </material>
        </visual>
        <collision name='player_center'>
          <pose>0 0 0 1.5707963267948966 -0 0</pose>
          <geometry>
            <polyline>
              <height>0.1</height>
              <point>-0.00935486 -0.00548224</point>
              <point>-0.00935486 0.00548224</point>
              <point>-0.00887948 0.00844526</point>
              <point>-0.00755453 0.011014</point>
              <point>-0.00553179 0.0130368</point>
              <point>-0.00296304 0.0143617</point>
              <point>-3.95112e-08 0.0148371</point>
              <point>0.002963 0.0143617</point>
              <point>0.00553178 0.0130368</point>
              <point>0.00755453 0.011014</point>
              <point>0.00887948 0.00844526</point>
              <point>0.00935486 0.00548224</point>
              <point>0.00935486 -0.00548224</point>
              <point>0.00887948 -0.00844525</point>
              <point>0.00755453 -0.011014</point>
              <point>0.00553178 -0.0130368</point>
              <point>0.002963 -0.0143617</point>
              <point>-3.95112e-08 -0.0148371</point>
              <point>-0.00296304 -0.0143617</point>
              <point>-0.00553179 -0.0130368</point>
              <point>-0.00755453 -0.011014</point>
              <point>-0.00887948 -0.00844525</point>
              <point>-0.00935486 -0.00548224</point>
            </polyline>
          </geometry>
        </collision>
     
     
      
       <visual name='player_side_1'>
        <pose>0 0 0.15 1.5707963267948966 -0 0</pose>
        <geometry>
          <polyline>
            <height>0.1</height>
            <point>-0.00935486 -0.00548224</point>
            <point>-0.00935486 0.00548224</point>
            <point>-0.00887948 0.00844526</point>
            <point>-0.00755453 0.011014</point>
            <point>-0.00553179 0.0130368</point>
            <point>-0.00296304 0.0143617</point>
            <point>-3.95112e-08 0.0148371</point>
            <point>0.002963 0.0143617</point>
            <point>0.00553178 0.0130368</point>
            <point>0.00755453 0.011014</point>
            <point>0.00887948 0.00844526</point>
            <point>0.00935486 0.00548224</point>
            <point>0.00935486 -0.00548224</point>
            <point>0.00887948 -0.00844525</point>
            <point>0.00755453 -0.011014</point>
            <point>0.00553178 -0.0130368</point>
            <point>0.002963 -0.0143617</point>
            <point>-3.95112e-08 -0.0148371</point>
            <point>-0.00296304 -0.0143617</point>
            <point>-0.00553179 -0.0130368</point>
            <point>-0.00755453 -0.011014</point>
            <point>-0.00887948 -0.00844525</point>
            <point>-0.00935486 -0.00548224</point>
          </polyline>
        </geometry>
        <material>
          <emissive>0 1 0 1</emissive>
        </material>
      </visual>
      <collision name='player_side_1'>
        <pose>0 0 0.15 1.5707963267948966 -0 0</pose>
        <geometry>
          <polyline>
            <height>0.1</height>
            <point>-0.00935486 -0.00548224</point>
            <point>-0.00935486 0.00548224</point>
            <point>-0.00887948 0.00844526</point>
            <point>-0.00755453 0.011014</point>
            <point>-0.00553179 0.0130368</point>
            <point>-0.00296304 0.0143617</point>
            <point>-3.95112e-08 0.0148371</point>
            <point>0.002963 0.0143617</point>
            <point>0.00553178 0.0130368</point>
            <point>0.00755453 0.011014</point>
            <point>0.00887948 0.00844526</point>
            <point>0.00935486 0.00548224</point>
            <point>0.00935486 -0.00548224</point>
            <point>0.00887948 -0.00844525</point>
            <point>0.00755453 -0.011014</point>
            <point>0.00553178 -0.0130368</point>
            <point>0.002963 -0.0143617</point>
            <point>-3.95112e-08 -0.0148371</point>
            <point>-0.00296304 -0.0143617</point>
            <point>-0.00553179 -0.0130368</point>
            <point>-0.00755453 -0.011014</point>
            <point>-0.00887948 -0.00844525</point>
            <point>-0.00935486 -0.00548224</point>
          </polyline>
        </geometry>
      </collision>
      <visual name='player_side_2'>
        <pose>0 0 -0.15 1.5707963267948966 -0 0</pose>
        <geometry>
          <polyline>
            <height>0.1</height>
            <point>-0.00935486 -0.00548224</point>
            <point>-0.00935486 0.00548224</point>
            <point>-0.00887948 0.00844526</point>
            <point>-0.00755453 0.011014</point>
            <point>-0.00553179 0.0130368</point>
            <point>-0.00296304 0.0143617</point>
            <point>-3.95112e-08 0.0148371</point>
            <point>0.002963 0.0143617</point>
            <point>0.00553178 0.0130368</point>
            <point>0.00755453 0.011014</point>
            <point>0.00887948 0.00844526</point>
            <point>0.00935486 0.00548224</point>
            <point>0.00935486 -0.00548224</point>
            <point>0.00887948 -0.00844525</point>
            <point>0.00755453 -0.011014</point>
            <point>0.00553178 -0.0130368</point>
            <point>0.002963 -0.0143617</point>
            <point>-3.95112e-08 -0.0148371</point>
            <point>-0.00296304 -0.0143617</point>
            <point>-0.00553179 -0.0130368</point>
            <point>-0.00755453 -0.011014</point>
            <point>-0.00887948 -0.00844525</point>
            <point>-0.00935486 -0.00548224</point>
          </polyline>
        </geometry>
        <material>
          <emissive>0 1 0 1</emissive>
        </material>
      </visual>
      <collision name='player_side_2'>
        <pose>0 0 -0.15 1.5707963267948966 -0 0</pose>
        <geometry>
          <polyline>
            <height>0.1</height>
            <point>-0.00935486 -0.00548224</point>
            <point>-0.00935486 0.00548224</point>
            <point>-0.00887948 0.00844526</point>
            <point>-0.00755453 0.011014</point>
            <point>-0.00553179 0.0130368</point>
            <point>-0.00296304 0.0143617</point>
            <point>-3.95112e-08 0.0148371</point>
            <point>0.002963 0.0143617</point>
            <point>0.00553178 0.0130368</point>
            <point>0.00755453 0.011014</point>
            <point>0.00887948 0.00844526</point>
            <point>0.00935486 0.00548224</point>
            <point>0.00935486 -0.00548224</point>
            <point>0.00887948 -0.00844525</point>
            <point>0.00755453 -0.011014</point>
            <point>0.00553178 -0.0130368</point>
            <point>0.002963 -0.0143617</point>
            <point>-3.95112e-08 -0.0148371</point>
            <point>-0.00296304 -0.0143617</point>
            <point>-0.00553179 -0.0130368</point>
            <point>-0.00755453 -0.011014</point>
            <point>-0.00887948 -0.00844525</point>
            <point>-0.00935486 -0.00548224</point>
          </polyline>
        </geometry>
      </collision>
      
      </link>
    
    <joint name="transA3" type="prismatic">
      <parent>world</parent>
      <child>shaftA3_bridge</child>
      <axis>
        <xyz>0 0 1</xyz>
        <use_parent_model_frame>0</use_parent_model_frame>
        <limit>
          <lower>-0.18</lower>
          <upper>0.18</upper>
        </limit>
      </axis>
      <pose>0 0 0 0 -0 0</pose>
    </joint>
    <joint name="rotA3" type="revolute">
      <parent>shaftA3_bridge</parent>
      <child>shaftA3</child>
      <axis>
        <xyz>0 0 1</xyz>
        <limit>
          <lower>-1000</lower>
          <upper>1000</upper>
        </limit>
      </axis>
      <pose>0 0 0 0 -0 0</pose>
    </joint>
     
      <link name="shaftB0_bridge">
        <pose>-0.522287 0 0.355381 1.5707963267948966 -0 0</pose>
      </link>    
      <link name="shaftB0">
        <pose>-0.522287 0 0.355381 1.5707963267948966 -0 0</pose>
        <visual name='rod'>
          <pose>0 0 0 0 -0 0</pose>
          <geometry>
            <cylinder>
              <radius>0.00779907</radius>
              <length>1.2</length>
            </cylinder>
          </geometry>
          <material>
            <script>
              <uri>file://media/materials/scripts/gazebo.material</uri>
              <name>Gazebo/Grey</name>
            </script>
          </material>
        </visual>
        <collision name='rod'>
          <pose>0 0 0 0 -0 0</pose>
          <geometry>
            <cylinder>
              <radius>0.00779907</radius>
              <length>1.2</length>
            </cylinder>
          </geometry>
        </collision>
        
        <visual name='player_center'>
          <pose>0 0 0 1.5707963267948966 -0 0</pose>
          <geometry>
            <polyline>
              <height>0.1</height>
              <point>-0.00935486 -0.00548224</point>
              <point>-0.00935486 0.00548224</point>
              <point>-0.00887948 0.00844526</point>
              <point>-0.00755453 0.011014</point>
              <point>-0.00553179 0.0130368</point>
              <point>-0.00296304 0.0143617</point>
              <point>-3.95112e-08 0.0148371</point>
              <point>0.002963 0.0143617</point>
              <point>0.00553178 0.0130368</point>
              <point>0.00755453 0.011014</point>
              <point>0.00887948 0.00844526</point>
              <point>0.00935486 0.00548224</point>
              <point>0.00935486 -0.00548224</point>
              <point>0.00887948 -0.00844525</point>
              <point>0.00755453 -0.011014</point>
              <point>0.00553178 -0.0130368</point>
              <point>0.002963 -0.0143617</point>
              <point>-3.95112e-08 -0.0148371</point>
              <point>-0.00296304 -0.0143617</point>
              <point>-0.00553179 -0.0130368</point>
              <point>-0.00755453 -0.011014</point>
              <point>-0.00887948 -0.00844525</point>
              <point>-0.00935486 -0.00548224</point>
            </polyline>
          </geometry>
          <material>
            <emissive>1 1 0 1</emissive>
          </material>
        </visual>
        <collision name='player_center'>
          <pose>0 0 0 1.5707963267948966 -0 0</pose>
          <geometry>
            <polyline>
              <height>0.1</height>
              <point>-0.00935486 -0.00548224</point>
              <point>-0.00935486 0.00548224</point>
              <point>-0.00887948 0.00844526</point>
              <point>-0.00755453 0.011014</point>
              <point>-0.00553179 0.0130368</point>
              <point>-0.00296304 0.0143617</point>
              <point>-3.95112e-08 0.0148371</point>
              <point>0.002963 0.0143617</point>
              <point>0.00553178 0.0130368</point>
              <point>0.00755453 0.011014</point>
              <point>0.00887948 0.00844526</point>
              <point>0.00935486 0.00548224</point>
              <point>0.00935486 -0.00548224</point>
              <point>0.00887948 -0.00844525</point>
              <point>0.00755453 -0.011014</point>
              <point>0.00553178 -0.0130368</point>
              <point>0.002963 -0.0143617</point>
              <point>-3.95112e-08 -0.0148371</point>
              <point>-0.00296304 -0.0143617</point>
              <point>-0.00553179 -0.0130368</point>
              <point>-0.00755453 -0.011014</point>
              <point>-0.00887948 -0.00844525</point>
              <point>-0.00935486 -0.00548224</point>
            </polyline>
          </geometry>
        </collision>
     
     
     
      </link>
    
    <joint name="transB0" type="prismatic">
      <parent>world</parent>
      <child>shaftB0_bridge</child>
      <axis>
        <xyz>0 0 1</xyz>
        <use_parent_model_frame>0</use_parent_model_frame>
        <limit>
          <lower>-0.09</lower>
          <upper>0.09</upper>
        </limit>
      </axis>
      <pose>0 0 0 0 -0 0</pose>
    </joint>
    <joint name="rotB0" type="revolute">
      <parent>shaftB0_bridge</parent>
      <child>shaftB0</child>
      <axis>
        <xyz>0 0 1</xyz>
        <limit>
          <lower>-1000</lower>
          <upper>1000</upper>
        </limit>
      </axis>
      <pose>0 0 0 0 -0 0</pose>
    </joint>
    
      <link name="shaftB1_bridge">
        <pose>-0.373062 0 0.355381 1.5707963267948966 -0 0</pose>
      </link>    
      <link name="shaftB1">
        <pose>-0.373062 0 0.355381 1.5707963267948966 -0 0</pose>
        <visual name='rod'>
          <pose>0 0 0 0 -0 0</pose>
          <geometry>
            <cylinder>
              <radius>0.00779907</radius>
              <length>1.2</length>
            </cylinder>
          </geometry>
          <material>
            <script>
              <uri>file://media/materials/scripts/gazebo.material</uri>
              <name>Gazebo/Grey</name>
            </script>
          </material>
        </visual>
        <collision name='rod'>
          <pose>0 0 0 0 -0 0</pose>
          <geometry>
            <cylinder>
              <radius>0.00779907</radius>
              <length>1.2</length>
            </cylinder>
          </geometry>
        </collision>
        
     
      
       <visual name='player_side_1'>
        <pose>0 0 0.1 1.5707963267948966 -0 0</pose>
        <geometry>
          <polyline>
            <height>0.1</height>
            <point>-0.00935486 -0.00548224</point>
            <point>-0.00935486 0.00548224</point>
            <point>-0.00887948 0.00844526</point>
            <point>-0.00755453 0.011014</point>
            <point>-0.00553179 0.0130368</point>
            <point>-0.00296304 0.0143617</point>
            <point>-3.95112e-08 0.0148371</point>
            <point>0.002963 0.0143617</point>
            <point>0.00553178 0.0130368</point>
            <point>0.00755453 0.011014</point>
            <point>0.00887948 0.00844526</point>
            <point>0.00935486 0.00548224</point>
            <point>0.00935486 -0.00548224</point>
            <point>0.00887948 -0.00844525</point>
            <point>0.00755453 -0.011014</point>
            <point>0.00553178 -0.0130368</point>
            <point>0.002963 -0.0143617</point>
            <point>-3.95112e-08 -0.0148371</point>
            <point>-0.00296304 -0.0143617</point>
            <point>-0.00553179 -0.0130368</point>
            <point>-0.00755453 -0.011014</point>
            <point>-0.00887948 -0.00844525</point>
            <point>-0.00935486 -0.00548224</point>
          </polyline>
        </geometry>
        <material>
          <emissive>1 1 0 1</emissive>
        </material>
      </visual>
      <collision name='player_side_1'>
        <pose>0 0 0.1 1.5707963267948966 -0 0</pose>
        <geometry>
          <polyline>
            <height>0.1</height>
            <point>-0.00935486 -0.00548224</point>
            <point>-0.00935486 0.00548224</point>
            <point>-0.00887948 0.00844526</point>
            <point>-0.00755453 0.011014</point>
            <point>-0.00553179 0.0130368</point>
            <point>-0.00296304 0.0143617</point>
            <point>-3.95112e-08 0.0148371</point>
            <point>0.002963 0.0143617</point>
            <point>0.00553178 0.0130368</point>
            <point>0.00755453 0.011014</point>
            <point>0.00887948 0.00844526</point>
            <point>0.00935486 0.00548224</point>
            <point>0.00935486 -0.00548224</point>
            <point>0.00887948 -0.00844525</point>
            <point>0.00755453 -0.011014</point>
            <point>0.00553178 -0.0130368</point>
            <point>0.002963 -0.0143617</point>
            <point>-3.95112e-08 -0.0148371</point>
            <point>-0.00296304 -0.0143617</point>
            <point>-0.00553179 -0.0130368</point>
            <point>-0.00755453 -0.011014</point>
            <point>-0.00887948 -0.00844525</point>
            <point>-0.00935486 -0.00548224</point>
          </polyline>
        </geometry>
      </collision>
      <visual name='player_side_2'>
        <pose>0 0 -0.1 1.5707963267948966 -0 0</pose>
        <geometry>
          <polyline>
            <height>0.1</height>
            <point>-0.00935486 -0.00548224</point>
            <point>-0.00935486 0.00548224</point>
            <point>-0.00887948 0.00844526</point>
            <point>-0.00755453 0.011014</point>
            <point>-0.00553179 0.0130368</point>
            <point>-0.00296304 0.0143617</point>
            <point>-3.95112e-08 0.0148371</point>
            <point>0.002963 0.0143617</point>
            <point>0.00553178 0.0130368</point>
            <point>0.00755453 0.011014</point>
            <point>0.00887948 0.00844526</point>
            <point>0.00935486 0.00548224</point>
            <point>0.00935486 -0.00548224</point>
            <point>0.00887948 -0.00844525</point>
            <point>0.00755453 -0.011014</point>
            <point>0.00553178 -0.0130368</point>
            <point>0.002963 -0.0143617</point>
            <point>-3.95112e-08 -0.0148371</point>
            <point>-0.00296304 -0.0143617</point>
            <point>-0.00553179 -0.0130368</point>
            <point>-0.00755453 -0.011014</point>
            <point>-0.00887948 -0.00844525</point>
            <point>-0.00935486 -0.00548224</point>
          </polyline>
        </geometry>
        <material>
          <emissive>1 1 0 1</emissive>
        </material>
      </visual>
      <collision name='player_side_2'>
        <pose>0 0 -0.1 1.5707963267948966 -0 0</pose>
        <geometry>
          <polyline>
            <height>0.1</height>
            <point>-0.00935486 -0.00548224</point>
            <point>-0.00935486 0.00548224</point>
            <point>-0.00887948 0.00844526</point>
            <point>-0.00755453 0.011014</point>
            <point>-0.00553179 0.0130368</point>
            <point>-0.00296304 0.0143617</point>
            <point>-3.95112e-08 0.0148371</point>
            <point>0.002963 0.0143617</point>
            <point>0.00553178 0.0130368</point>
            <point>0.00755453 0.011014</point>
            <point>0.00887948 0.00844526</point>
            <point>0.00935486 0.00548224</point>
            <point>0.00935486 -0.00548224</point>
            <point>0.00887948 -0.00844525</point>
            <point>0.00755453 -0.011014</point>
            <point>0.00553178 -0.0130368</point>
            <point>0.002963 -0.0143617</point>
            <point>-3.95112e-08 -0.0148371</point>
            <point>-0.00296304 -0.0143617</point>
            <point>-0.00553179 -0.0130368</point>
            <point>-0.00755453 -0.011014</point>
            <point>-0.00887948 -0.00844525</point>
            <point>-0.00935486 -0.00548224</point>
          </polyline>
        </geometry>
      </collision>
      
      </link>
    
    <joint name="transB1" type="prismatic">
      <parent>world</parent>
      <child>shaftB1_bridge</child>
      <axis>
        <xyz>0 0 1</xyz>
        <use_parent_model_frame>0</use_parent_model_frame>
        <limit>
          <lower>-0.23</lower>
          <upper>0.23</upper>
        </limit>
      </axis>
      <pose>0 0 0 0 -0 0</pose>
    </joint>
    <joint name="rotB1" type="revolute">
      <parent>shaftB1_bridge</parent>
      <child>shaftB1</child>
      <axis>
        <xyz>0 0 1</xyz>
        <limit>
          <lower>-1000</lower>
          <upper>1000</upper>
        </limit>
      </axis>
      <pose>0 0 0 0 -0 0</pose>
    </joint>
    
      <link name="shaftB2_bridge">
        <pose>-0.074612 0 0.355381 1.5707963267948966 -0 0</pose>
      </link>    
      <link name="shaftB2">
        <pose>-0.074612 0 0.355381 1.5707963267948966 -0 0</pose>
        <visual name='rod'>
          <pose>0 0 0 0 -0 0</pose>
          <geometry>
            <cylinder>
              <radius>0.00779907</radius>
              <length>1.2</length>
            </cylinder>
          </geometry>
          <material>
            <script>
              <uri>file://media/materials/scripts/gazebo.material</uri>
              <name>Gazebo/Grey</name>
            </script>
          </material>
        </visual>
        <collision name='rod'>
          <pose>0 0 0 0 -0 0</pose>
          <geometry>
            <cylinder>
              <radius>0.00779907</radius>
              <length>1.2</length>
            </cylinder>
          </geometry>
        </collision>
        
        <visual name='player_center'>
          <pose>0 0 0 1.5707963267948966 -0 0</pose>
          <geometry>
            <polyline>
              <height>0.1</height>
              <point>-0.00935486 -0.00548224</point>
              <point>-0.00935486 0.00548224</point>
              <point>-0.00887948 0.00844526</point>
              <point>-0.00755453 0.011014</point>
              <point>-0.00553179 0.0130368</point>
              <point>-0.00296304 0.0143617</point>
              <point>-3.95112e-08 0.0148371</point>
              <point>0.002963 0.0143617</point>
              <point>0.00553178 0.0130368</point>
              <point>0.00755453 0.011014</point>
              <point>0.00887948 0.00844526</point>
              <point>0.00935486 0.00548224</point>
              <point>0.00935486 -0.00548224</point>
              <point>0.00887948 -0.00844525</point>
              <point>0.00755453 -0.011014</point>
              <point>0.00553178 -0.0130368</point>
              <point>0.002963 -0.0143617</point>
              <point>-3.95112e-08 -0.0148371</point>
              <point>-0.00296304 -0.0143617</point>
              <point>-0.00553179 -0.0130368</point>
              <point>-0.00755453 -0.011014</point>
              <point>-0.00887948 -0.00844525</point>
              <point>-0.00935486 -0.00548224</point>
            </polyline>
          </geometry>
          <material>
            <emissive>1 1 0 1</emissive>
          </material>
        </visual>
        <collision name='player_center'>
          <pose>0 0 0 1.5707963267948966 -0 0</pose>
          <geometry>
            <polyline>
              <height>0.1</height>
              <point>-0.00935486 -0.00548224</point>
              <point>-0.00935486 0.00548224</point>
              <point>-0.00887948 0.00844526</point>
              <point>-0.00755453 0.011014</point>
              <point>-0.00553179 0.0130368</point>
              <point>-0.00296304 0.0143617</point>
              <point>-3.95112e-08 0.0148371</point>
              <point>0.002963 0.0143617</point>
              <point>0.00553178 0.0130368</point>
              <point>0.00755453 0.011014</point>
              <point>0.00887948 0.00844526</point>
              <point>0.00935486 0.00548224</point>
              <point>0.00935486 -0.00548224</point>
              <point>0.00887948 -0.00844525</point>
              <point>0.00755453 -0.011014</point>
              <point>0.00553178 -0.0130368</point>
              <point>0.002963 -0.0143617</point>
              <point>-3.95112e-08 -0.0148371</point>
              <point>-0.00296304 -0.0143617</point>
              <point>-0.00553179 -0.0130368</point>
              <point>-0.00755453 -0.011014</point>
              <point>-0.00887948 -0.00844525</point>
              <point>-0.00935486 -0.00548224</point>
            </polyline>
          </geometry>
        </collision>
     
      
       <visual name='player_mid_1'>
        <pose>0 0 0.26 1.5707963267948966 -0 0</pose>
        <geometry>
          <polyline>
            <height>0.1</height>
            <point>-0.00935486 -0.00548224</point>
            <point>-0.00935486 0.00548224</point>
            <point>-0.00887948 0.00844526</point>
            <point>-0.00755453 0.011014</point>
            <point>-0.00553179 0.0130368</point>
            <point>-0.00296304 0.0143617</point>
            <point>-3.95112e-08 0.0148371</point>
            <point>0.002963 0.0143617</point>
            <point>0.00553178 0.0130368</point>
            <point>0.00755453 0.011014</point>
            <point>0.00887948 0.00844526</point>
            <point>0.00935486 0.00548224</point>
            <point>0.00935486 -0.00548224</point>
            <point>0.00887948 -0.00844525</point>
            <point>0.00755453 -0.011014</point>
            <point>0.00553178 -0.0130368</point>
            <point>0.002963 -0.0143617</point>
            <point>-3.95112e-08 -0.0148371</point>
            <point>-0.00296304 -0.0143617</point>
            <point>-0.00553179 -0.0130368</point>
            <point>-0.00755453 -0.011014</point>
            <point>-0.00887948 -0.00844525</point>
            <point>-0.00935486 -0.00548224</point>
          </polyline>
        </geometry>
        <material>
          <emissive>1 1 0 1</emissive>
        </material>
      </visual>
      <collision name='player_mid_1'>
        <pose>0 0 0.26 1.5707963267948966 -0 0</pose>
        <geometry>
          <polyline>
            <height>0.1</height>
            <point>-0.00935486 -0.00548224</point>
            <point>-0.00935486 0.00548224</point>
            <point>-0.00887948 0.00844526</point>
            <point>-0.00755453 0.011014</point>
            <point>-0.00553179 0.0130368</point>
            <point>-0.00296304 0.0143617</point>
            <point>-3.95112e-08 0.0148371</point>
            <point>0.002963 0.0143617</point>
            <point>0.00553178 0.0130368</point>
            <point>0.00755453 0.011014</point>
            <point>0.00887948 0.00844526</point>
            <point>0.00935486 0.00548224</point>
            <point>0.00935486 -0.00548224</point>
            <point>0.00887948 -0.00844525</point>
            <point>0.00755453 -0.011014</point>
            <point>0.00553178 -0.0130368</point>
            <point>0.002963 -0.0143617</point>
            <point>-3.95112e-08 -0.0148371</point>
            <point>-0.00296304 -0.0143617</point>
            <point>-0.00553179 -0.0130368</point>
            <point>-0.00755453 -0.011014</point>
            <point>-0.00887948 -0.00844525</point>
            <point>-0.00935486 -0.00548224</point>
          </polyline>
        </geometry>
      </collision>
      <visual name='player_mid_2'>
        <pose>0 0 -0.26 1.5707963267948966 -0 0</pose>
        <geometry>
          <polyline>
            <height>0.1</height>
            <point>-0.00935486 -0.00548224</point>
            <point>-0.00935486 0.00548224</point>
            <point>-0.00887948 0.00844526</point>
            <point>-0.00755453 0.011014</point>
            <point>-0.00553179 0.0130368</point>
            <point>-0.00296304 0.0143617</point>
            <point>-3.95112e-08 0.0148371</point>
            <point>0.002963 0.0143617</point>
            <point>0.00553178 0.0130368</point>
            <point>0.00755453 0.011014</point>
            <point>0.00887948 0.00844526</point>
            <point>0.00935486 0.00548224</point>
            <point>0.00935486 -0.00548224</point>
            <point>0.00887948 -0.00844525</point>
            <point>0.00755453 -0.011014</point>
            <point>0.00553178 -0.0130368</point>
            <point>0.002963 -0.0143617</point>
            <point>-3.95112e-08 -0.0148371</point>
            <point>-0.00296304 -0.0143617</point>
            <point>-0.00553179 -0.0130368</point>
            <point>-0.00755453 -0.011014</point>
            <point>-0.00887948 -0.00844525</point>
            <point>-0.00935486 -0.00548224</point>
          </polyline>
        </geometry>
        <material>
          <emissive>1 1 0 1</emissive>
        </material>
      </visual>
      <collision name='player_mid_2'>
        <pose>0 0 -0.26 1.5707963267948966 -0 0</pose>
        <geometry>
          <polyline>
            <height>0.1</height>
            <point>-0.00935486 -0.00548224</point>
            <point>-0.00935486 0.00548224</point>
            <point>-0.00887948 0.00844526</point>
            <point>-0.00755453 0.011014</point>
            <point>-0.00553179 0.0130368</point>
            <point>-0.00296304 0.0143617</point>
            <point>-3.95112e-08 0.0148371</point>
            <point>0.002963 0.0143617</point>
            <point>0.00553178 0.0130368</point>
            <point>0.00755453 0.011014</point>
            <point>0.00887948 0.00844526</point>
            <point>0.00935486 0.00548224</point>
            <point>0.00935486 -0.00548224</point>
            <point>0.00887948 -0.00844525</point>
            <point>0.00755453 -0.011014</point>
            <point>0.00553178 -0.0130368</point>
            <point>0.002963 -0.0143617</point>
            <point>-3.95112e-08 -0.0148371</point>
            <point>-0.00296304 -0.0143617</point>
            <point>-0.00553179 -0.0130368</point>
            <point>-0.00755453 -0.011014</point>
            <point>-0.00887948 -0.00844525</point>
            <point>-0.00935486 -0.00548224</point>
          </polyline>
        </geometry>
      </collision>
     
      
       <visual name='player_side_1'>
        <pose>0 0 0.13 1.5707963267948966 -0 0</pose>
        <geometry>
          <polyline>
            <height>0.1</height>
            <point>-0.00935486 -0.00548224</point>
            <point>-0.00935486 0.00548224</point>
            <point>-0.00887948 0.00844526</point>
            <point>-0.00755453 0.011014</point>
            <point>-0.00553179 0.0130368</point>
            <point>-0.00296304 0.0143617</point>
            <point>-3.95112e-08 0.0148371</point>
            <point>0.002963 0.0143617</point>
            <point>0.00553178 0.0130368</point>
            <point>0.00755453 0.011014</point>
            <point>0.00887948 0.00844526</point>
            <point>0.00935486 0.00548224</point>
            <point>0.00935486 -0.00548224</point>
            <point>0.00887948 -0.00844525</point>
            <point>0.00755453 -0.011014</point>
            <point>0.00553178 -0.0130368</point>
            <point>0.002963 -0.0143617</point>
            <point>-3.95112e-08 -0.0148371</point>
            <point>-0.00296304 -0.0143617</point>
            <point>-0.00553179 -0.0130368</point>
            <point>-0.00755453 -0.011014</point>
            <point>-0.00887948 -0.00844525</point>
            <point>-0.00935486 -0.00548224</point>
          </polyline>
        </geometry>
        <material>
          <emissive>1 1 0 1</emissive>
        </material>
      </visual>
      <collision name='player_side_1'>
        <pose>0 0 0.13 1.5707963267948966 -0 0</pose>
        <geometry>
          <polyline>
            <height>0.1</height>
            <point>-0.00935486 -0.00548224</point>
            <point>-0.00935486 0.00548224</point>
            <point>-0.00887948 0.00844526</point>
            <point>-0.00755453 0.011014</point>
            <point>-0.00553179 0.0130368</point>
            <point>-0.00296304 0.0143617</point>
            <point>-3.95112e-08 0.0148371</point>
            <point>0.002963 0.0143617</point>
            <point>0.00553178 0.0130368</point>
            <point>0.00755453 0.011014</point>
            <point>0.00887948 0.00844526</point>
            <point>0.00935486 0.00548224</point>
            <point>0.00935486 -0.00548224</point>
            <point>0.00887948 -0.00844525</point>
            <point>0.00755453 -0.011014</point>
            <point>0.00553178 -0.0130368</point>
            <point>0.002963 -0.0143617</point>
            <point>-3.95112e-08 -0.0148371</point>
            <point>-0.00296304 -0.0143617</point>
            <point>-0.00553179 -0.0130368</point>
            <point>-0.00755453 -0.011014</point>
            <point>-0.00887948 -0.00844525</point>
            <point>-0.00935486 -0.00548224</point>
          </polyline>
        </geometry>
      </collision>
      <visual name='player_side_2'>
        <pose>0 0 -0.13 1.5707963267948966 -0 0</pose>
        <geometry>
          <polyline>
            <height>0.1</height>
            <point>-0.00935486 -0.00548224</point>
            <point>-0.00935486 0.00548224</point>
            <point>-0.00887948 0.00844526</point>
            <point>-0.00755453 0.011014</point>
            <point>-0.00553179 0.0130368</point>
            <point>-0.00296304 0.0143617</point>
            <point>-3.95112e-08 0.0148371</point>
            <point>0.002963 0.0143617</point>
            <point>0.00553178 0.0130368</point>
            <point>0.00755453 0.011014</point>
            <point>0.00887948 0.00844526</point>
            <point>0.00935486 0.00548224</point>
            <point>0.00935486 -0.00548224</point>
            <point>0.00887948 -0.00844525</point>
            <point>0.00755453 -0.011014</point>
            <point>0.00553178 -0.0130368</point>
            <point>0.002963 -0.0143617</point>
            <point>-3.95112e-08 -0.0148371</point>
            <point>-0.00296304 -0.0143617</point>
            <point>-0.00553179 -0.0130368</point>
            <point>-0.00755453 -0.011014</point>
            <point>-0.00887948 -0.00844525</point>
            <point>-0.00935486 -0.00548224</point>
          </polyline>
        </geometry>
        <material>
          <emissive>1 1 0 1</emissive>
        </material>
      </visual>
      <collision name='player_side_2'>
        <pose>0 0 -0.13 1.5707963267948966 -0 0</pose>
        <geometry>
          <polyline>
            <height>0.1</height>
            <point>-0.00935486 -0.00548224</point>
            <point>-0.00935486 0.00548224</point>
            <point>-0.00887948 0.00844526</point>
            <point>-0.00755453 0.011014</point>
            <point>-0.00553179 0.0130368</point>
            <point>-0.00296304 0.0143617</point>
            <point>-3.95112e-08 0.0148371</point>
            <point>0.002963 0.0143617</point>
            <point>0.00553178 0.0130368</point>
            <point>0.00755453 0.011014</point>
            <point>0.00887948 0.00844526</point>
            <point>0.00935486 0.00548224</point>
            <point>0.00935486 -0.00548224</point>
            <point>0.00887948 -0.00844525</point>
            <point>0.00755453 -0.011014</point>
            <point>0.00553178 -0.0130368</point>
            <point>0.002963 -0.0143617</point>
            <point>-3.95112e-08 -0.0148371</point>
            <point>-0.00296304 -0.0143617</point>
            <point>-0.00553179 -0.0130368</point>
            <point>-0.00755453 -0.011014</point>
            <point>-0.00887948 -0.00844525</point>
            <point>-0.00935486 -0.00548224</point>
          </polyline>
        </geometry>
      </collision>
      
      </link>
    
    <joint name="transB2" type="prismatic">
      <parent>world</parent>
      <child>shaftB2_bridge</child>
      <axis>
        <xyz>0 0 1</xyz>
        <use_parent_model_frame>0</use_parent_model_frame>
        <limit>
          <lower>-0.07</lower>
          <upper>0.07</upper>
        </limit>
      </axis>
      <pose>0 0 0 0 -0 0</pose>
    </joint>
    <joint name="rotB2" type="revolute">
      <parent>shaftB2_bridge</parent>
      <child>shaftB2</child>
      <axis>
        <xyz>0 0 1</xyz>
        <limit>
          <lower>-1000</lower>
          <upper>1000</upper>
        </limit>
      </axis>
      <pose>0 0 0 0 -0 0</pose>
    </joint>
    
      <link name="shaftB3_bridge">
        <pose>-0.223837 0 0.355381 1.5707963267948966 -0 0</pose>
      </link>    
      <link name="shaftB3">
        <pose>-0.223837 0 0.355381 1.5707963267948966 -0 0</pose>
        <visual name='rod'>
          <pose>0 0 0 0 -0 0</pose>
          <geometry>
            <cylinder>
              <radius>0.00779907</radius>
              <length>1.2</length>
            </cylinder>
          </geometry>
          <material>
            <script>
              <uri>file://media/materials/scripts/gazebo.material</uri>
              <name>Gazebo/Grey</name>
            </script>
          </material>
        </visual>
        <collision name='rod'>
          <pose>0 0 0 0 -0 0</pose>
          <geometry>
            <cylinder>
              <radius>0.00779907</radius>
              <length>1.2</length>
            </cylinder>
          </geometry>
        </collision>
        
        <visual name='player_center'>
          <pose>0 0 0 1.5707963267948966 -0 0</pose>
          <geometry>
            <polyline>
              <height>0.1</height>
              <point>-0.00935486 -0.00548224</point>
              <point>-0.00935486 0.00548224</point>
              <point>-0.00887948 0.00844526</point>
              <point>-0.00755453 0.011014</point>
              <point>-0.00553179 0.0130368</point>
              <point>-0.00296304 0.0143617</point>
              <point>-3.95112e-08 0.0148371</point>
              <point>0.002963 0.0143617</point>
              <point>0.00553178 0.0130368</point>
              <point>0.00755453 0.011014</point>
              <point>0.00887948 0.00844526</point>
              <point>0.00935486 0.00548224</point>
              <point>0.00935486 -0.00548224</point>
              <point>0.00887948 -0.00844525</point>
              <point>0.00755453 -0.011014</point>
              <point>0.00553178 -0.0130368</point>
              <point>0.002963 -0.0143617</point>
              <point>-3.95112e-08 -0.0148371</point>
              <point>-0.00296304 -0.0143617</point>
              <point>-0.00553179 -0.0130368</point>
              <point>-0.00755453 -0.011014</point>
              <point>-0.00887948 -0.00844525</point>
              <point>-0.00935486 -0.00548224</point>
            </polyline>
          </geometry>
          <material>
            <emissive>1 1 0 1</emissive>
          </material>
        </visual>
        <collision name='player_center'>
          <pose>0 0 0 1.5707963267948966 -0 0</pose>
          <geometry>
            <polyline>
              <height>0.1</height>
              <point>-0.00935486 -0.00548224</point>
              <point>-0.00935486 0.00548224</point>
              <point>-0.00887948 0.00844526</point>
              <point>-0.00755453 0.011014</point>
              <point>-0.00553179 0.0130368</point>
              <point>-0.00296304 0.0143617</point>
              <point>-3.95112e-08 0.0148371</point>
              <point>0.002963 0.0143617</point>
              <point>0.00553178 0.0130368</point>
              <point>0.00755453 0.011014</point>
              <point>0.00887948 0.00844526</point>
              <point>0.00935486 0.00548224</point>
              <point>0.00935486 -0.00548224</point>
              <point>0.00887948 -0.00844525</point>
              <point>0.00755453 -0.011014</point>
              <point>0.00553178 -0.0130368</point>
              <point>0.002963 -0.0143617</point>
              <point>-3.95112e-08 -0.0148371</point>
              <point>-0.00296304 -0.0143617</point>
              <point>-0.00553179 -0.0130368</point>
              <point>-0.00755453 -0.011014</point>
              <point>-0.00887948 -0.00844525</point>
              <point>-0.00935486 -0.00548224</point>
            </polyline>
          </geometry>
        </collision>
     
     
      
       <visual name='player_side_1'>
        <pose>0 0 0.15 1.5707963267948966 -0 0</pose>
        <geometry>
          <polyline>
            <height>0.1</height>
            <point>-0.00935486 -0.00548224</point>
            <point>-0.00935486 0.00548224</point>
            <point>-0.00887948 0.00844526</point>
            <point>-0.00755453 0.011014</point>
            <point>-0.00553179 0.0130368</point>
            <point>-0.00296304 0.0143617</point>
            <point>-3.95112e-08 0.0148371</point>
            <point>0.002963 0.0143617</point>
            <point>0.00553178 0.0130368</point>
            <point>0.00755453 0.011014</point>
            <point>0.00887948 0.00844526</point>
            <point>0.00935486 0.00548224</point>
            <point>0.00935486 -0.00548224</point>
            <point>0.00887948 -0.00844525</point>
            <point>0.00755453 -0.011014</point>
            <point>0.00553178 -0.0130368</point>
            <point>0.002963 -0.0143617</point>
            <point>-3.95112e-08 -0.0148371</point>
            <point>-0.00296304 -0.0143617</point>
            <point>-0.00553179 -0.0130368</point>
            <point>-0.00755453 -0.011014</point>
            <point>-0.00887948 -0.00844525</point>
            <point>-0.00935486 -0.00548224</point>
          </polyline>
        </geometry>
        <material>
          <emissive>1 1 0 1</emissive>
        </material>
      </visual>
      <collision name='player_side_1'>
        <pose>0 0 0.15 1.5707963267948966 -0 0</pose>
        <geometry>
          <polyline>
            <height>0.1</height>
            <point>-0.00935486 -0.00548224</point>
            <point>-0.00935486 0.00548224</point>
            <point>-0.00887948 0.00844526</point>
            <point>-0.00755453 0.011014</point>
            <point>-0.00553179 0.0130368</point>
            <point>-0.00296304 0.0143617</point>
            <point>-3.95112e-08 0.0148371</point>
            <point>0.002963 0.0143617</point>
            <point>0.00553178 0.0130368</point>
            <point>0.00755453 0.011014</point>
            <point>0.00887948 0.00844526</point>
            <point>0.00935486 0.00548224</point>
            <point>0.00935486 -0.00548224</point>
            <point>0.00887948 -0.00844525</point>
            <point>0.00755453 -0.011014</point>
            <point>0.00553178 -0.0130368</point>
            <point>0.002963 -0.0143617</point>
            <point>-3.95112e-08 -0.0148371</point>
            <point>-0.00296304 -0.0143617</point>
            <point>-0.00553179 -0.0130368</point>
            <point>-0.00755453 -0.011014</point>
            <point>-0.00887948 -0.00844525</point>
            <point>-0.00935486 -0.00548224</point>
          </polyline>
        </geometry>
      </collision>
      <visual name='player_side_2'>
        <pose>0 0 -0.15 1.5707963267948966 -0 0</pose>
        <geometry>
          <polyline>
            <height>0.1</height>
            <point>-0.00935486 -0.00548224</point>
            <point>-0.00935486 0.00548224</point>
            <point>-0.00887948 0.00844526</point>
            <point>-0.00755453 0.011014</point>
            <point>-0.00553179 0.0130368</point>
            <point>-0.00296304 0.0143617</point>
            <point>-3.95112e-08 0.0148371</point>
            <point>0.002963 0.0143617</point>
            <point>0.00553178 0.0130368</point>
            <point>0.00755453 0.011014</point>
            <point>0.00887948 0.00844526</point>
            <point>0.00935486 0.00548224</point>
            <point>0.00935486 -0.00548224</point>
            <point>0.00887948 -0.00844525</point>
            <point>0.00755453 -0.011014</point>
            <point>0.00553178 -0.0130368</point>
            <point>0.002963 -0.0143617</point>
            <point>-3.95112e-08 -0.0148371</point>
            <point>-0.00296304 -0.0143617</point>
            <point>-0.00553179 -0.0130368</point>
            <point>-0.00755453 -0.011014</point>
            <point>-0.00887948 -0.00844525</point>
            <point>-0.00935486 -0.00548224</point>
          </polyline>
        </geometry>
        <material>
          <emissive>1 1 0 1</emissive>
        </material>
      </visual>
      <collision name='player_side_2'>
        <pose>0 0 -0.15 1.5707963267948966 -0 0</pose>
        <geometry>
          <polyline>
            <height>0.1</height>
            <point>-0.00935486 -0.00548224</point>
            <point>-0.00935486 0.00548224</point>
            <point>-0.00887948 0.00844526</point>
            <point>-0.00755453 0.011014</point>
            <point>-0.00553179 0.0130368</point>
            <point>-0.00296304 0.0143617</point>
            <point>-3.95112e-08 0.0148371</point>
            <point>0.002963 0.0143617</point>
            <point>0.00553178 0.0130368</point>
            <point>0.00755453 0.011014</point>
            <point>0.00887948 0.00844526</point>
            <point>0.00935486 0.00548224</point>
            <point>0.00935486 -0.00548224</point>
            <point>0.00887948 -0.00844525</point>
            <point>0.00755453 -0.011014</point>
            <point>0.00553178 -0.0130368</point>
            <point>0.002963 -0.0143617</point>
            <point>-3.95112e-08 -0.0148371</point>
            <point>-0.00296304 -0.0143617</point>
            <point>-0.00553179 -0.0130368</point>
            <point>-0.00755453 -0.011014</point>
            <point>-0.00887948 -0.00844525</point>
            <point>-0.00935486 -0.00548224</point>
          </polyline>
        </geometry>
      </collision>
      
      </link>
    
    <joint name="transB3" type="prismatic">
      <parent>world</parent>
      <child>shaftB3_bridge</child>
      <axis>
        <xyz>0 0 1</xyz>
        <use_parent_model_frame>0</use_parent_model_frame>
        <limit>
          <lower>-0.18</lower>
          <upper>0.18</upper>
        </limit>
      </axis>
      <pose>0 0 0 0 -0 0</pose>
    </joint>
    <joint name="rotB3" type="revolute">
      <parent>shaftB3_bridge</parent>
      <child>shaftB3</child>
      <axis>
        <xyz>0 0 1</xyz>
        <limit>
          <lower>-1000</lower>
          <upper>1000</upper>
        </limit>
      </axis>
      <pose>0 0 0 0 -0 0</pose>
    </joint>
     

    <static>0</static>
  </model>
</sdf>
