<?xml version='1.0'?>

<sdf version='1.5'>
  <model name='Foosball'>
    <link name='table'>
      <pose>0 0 0.425 0 0 0</pose>

      <visual name='table'>
        <pose>0 0 0 1.5707963267948966 0 0</pose>
        <geometry>
          <mesh>
            <uri>model://foosball/meshes/table.dae</uri>
          </mesh>
        </geometry>
        <material>
          <script>
            <uri>file://media/materials/scripts/gazebo.material</uri>
            <name>Gazebo/Orange</name>
          </script>
        </material>
      </visual>

      

        <collision name="sideRed">
          <pose>0 -0.375 0.367 0 0 0</pose>
          <geometry>
            <box>
              <size>1.1 0.02 0.19</size>
            </box>
          </geometry>
        </collision>
      

        <collision name="sideBlue">
          <pose>0 0.375 0.367 0 0 0</pose>
          <geometry>
            <box>
              <size>1.1 0.02 0.19</size>
            </box>
          </geometry>
        </collision>
      

      
        <collision name="goalRed">
          <pose>0.55 0 0.367 0 1.5707963267948966 0</pose>
          <geometry>
            <polyline>
              <height>0.02</height>
              <point>0.095 -0.385</point>
              <point>-0.095 -0.385</point>
              <point>-0.095 0.385</point>
              <point>0.095 0.385</point>
              <point>0.095 0.09</point>
              <point>-0.0019 0.09</point>
              <point>-0.0019 -0.09</point>
              <point>0.095 -0.09</point>
            </polyline>
          </geometry>
        </collision>
      
        <collision name="goalBlue">
          <pose>-0.55 0 0.367 3.141592653589793 1.5707963267948966 0</pose>
          <geometry>
            <polyline>
              <height>0.02</height>
              <point>0.095 -0.385</point>
              <point>-0.095 -0.385</point>
              <point>-0.095 0.385</point>
              <point>0.095 0.385</point>
              <point>0.095 0.09</point>
              <point>-0.0019 0.09</point>
              <point>-0.0019 -0.09</point>
              <point>0.095 -0.09</point>
            </polyline>
          </geometry>
        </collision>
      

      <visual name='ground'>
        <pose>0 0 0.28200000000000003 0 0 0</pose>
        <geometry>
          <box>
            <size>1.1 0.73 0.02</size>
          </box>
        </geometry>
        <material>
          <script>
            <uri>model://foosball/materials/scripts/</uri>
            <uri>model://foosball/materials/textures/</uri>
            <name>Foosball/Field</name>
          </script>
        </material>
      </visual>
      <collision name='ground'>
        <pose>0 0 0.28200000000000003 0 0 0</pose>
        <geometry>
          <box>
            <size>1.1 0.73 0.02</size>
          </box>
        </geometry>
      </collision>
    </link>

    <joint name='table_world' type='prismatic'>
      <parent>world</parent>
      <child>table</child>
      <axis>
        <xyz>0 0 1</xyz>
        <limit>
          <lower>0</lower>
          <upper>0.1</upper>
        </limit>
      </axis>
      <pose>0 0 0 0 0 0</pose>
    </joint>

    
      <link name="shaftRed0_bridge">
        <pose>0.508 0 0.8 1.5707963267948966 0 0</pose>
      </link>
      <link name="shaftRed0">
        <pose>0.508 0 0.8 1.5707963267948966 0 0</pose>

        <visual name='rod'>
          <pose>0 0 0 0 0 0</pose>
          <geometry>
            <cylinder>
              <radius>0.00779907</radius>
              <length>1.2</length>
            </cylinder>
          </geometry>
          <material>
            <script>
              <uri>file://media/materials/scripts/gazebo.material</uri>
              <name>Gazebo/Grey</name>
            </script>
          </material>
        </visual>

        <visual name='handle'>
          <pose>0 0 -0.6 0 0 0</pose>
          <geometry>
            <mesh>
              <uri>model://foosball/meshes/handle.dae</uri>
            </mesh>
          </geometry>
          <material>
              <script><name>Gazebo/Black</name></script>
          </material>
        </visual>

        <collision name='handle'>
          <pose>0 0 -0.6675 0 0 0</pose>
          <geometry>
            <cylinder>
              <radius>0.022</radius>
              <length>0.135</length>
            </cylinder>
          </geometry>
        </collision>

        <collision name='rod'>
          <pose>0 0 0 0 0 0</pose>
          <geometry>
            <cylinder>
              <radius>0.00779907</radius>
              <length>1.2</length>
            </cylinder>
          </geometry>
        </collision>


     

        <visual name='player_center'>
          <pose>0 0 0 -1.5707963267948966 0 0</pose>
          <geometry>
            <mesh>
              <uri>model://foosball/meshes/player.dae</uri>
            </mesh>
          </geometry>
          <material>
            <script><name>Gazebo/Red</name></script>
          </material>
        </visual>

        <collision name='player_center'>
          <pose>0 -0.005 0 0 0 0</pose>
          <geometry> <box> <size>0.045 0.13 0.055</size> </box> </geometry>
        </collision>

     
     
     
      </link>

    <joint name="transRed0" type="prismatic">
      <parent>world</parent>
      <child>shaftRed0_bridge</child>
      <axis>
        <xyz>0 0 1</xyz>
        <use_parent_model_frame>0</use_parent_model_frame>
        <limit>
          <lower>-0.09</lower>
          <upper>0.09</upper>
        </limit>
      </axis>
      <pose>0 0 0 0 0 0</pose>
    </joint>
    <joint name="rotRed0" type="revolute">
      <parent>shaftRed0_bridge</parent>
      <child>shaftRed0</child>
      <axis>
        <xyz>0 0 1</xyz>
        <limit>
          <lower>-1000</lower>
          <upper>1000</upper>
        </limit>
      </axis>
      <pose>0 0 0 0 0 0</pose>
    </joint>
    
      <link name="shaftRed1_bridge">
        <pose>0.3675 0 0.8 1.5707963267948966 0 0</pose>
      </link>
      <link name="shaftRed1">
        <pose>0.3675 0 0.8 1.5707963267948966 0 0</pose>

        <visual name='rod'>
          <pose>0 0 0 0 0 0</pose>
          <geometry>
            <cylinder>
              <radius>0.00779907</radius>
              <length>1.2</length>
            </cylinder>
          </geometry>
          <material>
            <script>
              <uri>file://media/materials/scripts/gazebo.material</uri>
              <name>Gazebo/Grey</name>
            </script>
          </material>
        </visual>

        <visual name='handle'>
          <pose>0 0 -0.6 0 0 0</pose>
          <geometry>
            <mesh>
              <uri>model://foosball/meshes/handle.dae</uri>
            </mesh>
          </geometry>
          <material>
              <script><name>Gazebo/Black</name></script>
          </material>
        </visual>

        <collision name='handle'>
          <pose>0 0 -0.6675 0 0 0</pose>
          <geometry>
            <cylinder>
              <radius>0.022</radius>
              <length>0.135</length>
            </cylinder>
          </geometry>
        </collision>

        <collision name='rod'>
          <pose>0 0 0 0 0 0</pose>
          <geometry>
            <cylinder>
              <radius>0.00779907</radius>
              <length>1.2</length>
            </cylinder>
          </geometry>
        </collision>


     
     
     

        <visual name='player_side_1'>
          <pose>0 0 0.1 -1.5707963267948966 0 0</pose>
          <geometry>
            <mesh>
              <uri>model://foosball/meshes/player.dae</uri>
            </mesh>
          </geometry>
          <material>
            <script><name>Gazebo/Red</name></script>
          </material>
        </visual>

      <collision name='player_side_1'>
        <pose>0 -0.005 0.1 0 0 0</pose>
        <geometry> <box> <size>0.045 0.13 0.055</size> </box> </geometry>
      </collision>

        <visual name='player_side_2'>
          <pose>0 0 -0.1 -1.5707963267948966 0 0</pose>
          <geometry>
            <mesh>
              <uri>model://foosball/meshes/player.dae</uri>
            </mesh>
          </geometry>
          <material>
            <script><name>Gazebo/Red</name></script>
          </material>
        </visual>

      <collision name='player_side_2'>
        <pose>0 -0.005 -0.1 0 0 0</pose>
        <geometry> <box> <size>0.045 0.13 0.055</size> </box> </geometry>
      </collision>

      
      </link>

    <joint name="transRed1" type="prismatic">
      <parent>world</parent>
      <child>shaftRed1_bridge</child>
      <axis>
        <xyz>0 0 1</xyz>
        <use_parent_model_frame>0</use_parent_model_frame>
        <limit>
          <lower>-0.23</lower>
          <upper>0.23</upper>
        </limit>
      </axis>
      <pose>0 0 0 0 0 0</pose>
    </joint>
    <joint name="rotRed1" type="revolute">
      <parent>shaftRed1_bridge</parent>
      <child>shaftRed1</child>
      <axis>
        <xyz>0 0 1</xyz>
        <limit>
          <lower>-1000</lower>
          <upper>1000</upper>
        </limit>
      </axis>
      <pose>0 0 0 0 0 0</pose>
    </joint>
    
      <link name="shaftRed2_bridge">
        <pose>0.087 0 0.8 1.5707963267948966 0 0</pose>
      </link>
      <link name="shaftRed2">
        <pose>0.087 0 0.8 1.5707963267948966 0 0</pose>

        <visual name='rod'>
          <pose>0 0 0 0 0 0</pose>
          <geometry>
            <cylinder>
              <radius>0.00779907</radius>
              <length>1.2</length>
            </cylinder>
          </geometry>
          <material>
            <script>
              <uri>file://media/materials/scripts/gazebo.material</uri>
              <name>Gazebo/Grey</name>
            </script>
          </material>
        </visual>

        <visual name='handle'>
          <pose>0 0 -0.6 0 0 0</pose>
          <geometry>
            <mesh>
              <uri>model://foosball/meshes/handle.dae</uri>
            </mesh>
          </geometry>
          <material>
              <script><name>Gazebo/Black</name></script>
          </material>
        </visual>

        <collision name='handle'>
          <pose>0 0 -0.6675 0 0 0</pose>
          <geometry>
            <cylinder>
              <radius>0.022</radius>
              <length>0.135</length>
            </cylinder>
          </geometry>
        </collision>

        <collision name='rod'>
          <pose>0 0 0 0 0 0</pose>
          <geometry>
            <cylinder>
              <radius>0.00779907</radius>
              <length>1.2</length>
            </cylinder>
          </geometry>
        </collision>


     

        <visual name='player_center'>
          <pose>0 0 0 -1.5707963267948966 0 0</pose>
          <geometry>
            <mesh>
              <uri>model://foosball/meshes/player.dae</uri>
            </mesh>
          </geometry>
          <material>
            <script><name>Gazebo/Red</name></script>
          </material>
        </visual>

        <collision name='player_center'>
          <pose>0 -0.005 0 0 0 0</pose>
          <geometry> <box> <size>0.045 0.13 0.055</size> </box> </geometry>
        </collision>

     
     

        <visual name='player_mid_1'>
        <pose>0 0 0.26 -1.5707963267948966 0 0</pose>
          <geometry>
            <mesh>
              <uri>model://foosball/meshes/player.dae</uri>
            </mesh>
          </geometry>
          <material>
            <script>
              <name>Gazebo/Red</name>
            </script>
          </material>
        </visual>

      <collision name='player_mid_1'>
        <pose>0 -0.005 0.26 0 0 0</pose>
        <geometry> <box> <size>0.045 0.13 0.055</size> </box> </geometry>
      </collision>

        <visual name='player_mid_2'>
          <pose>0 0 -0.26 -1.5707963267948966 0 0</pose>
          <geometry>
            <mesh>
              <uri>model://foosball/meshes/player.dae</uri>
            </mesh>
          </geometry>
          <material>
            <script><name>Gazebo/Red</name></script>
          </material>
        </visual>

       <collision name='player_mid_2'>
        <pose>0 -0.005 -0.26 0 0 0</pose>
        <geometry> <box> <size>0.045 0.13 0.055</size> </box> </geometry>
      </collision>
     
     

        <visual name='player_side_1'>
          <pose>0 0 0.13 -1.5707963267948966 0 0</pose>
          <geometry>
            <mesh>
              <uri>model://foosball/meshes/player.dae</uri>
            </mesh>
          </geometry>
          <material>
            <script><name>Gazebo/Red</name></script>
          </material>
        </visual>

      <collision name='player_side_1'>
        <pose>0 -0.005 0.13 0 0 0</pose>
        <geometry> <box> <size>0.045 0.13 0.055</size> </box> </geometry>
      </collision>

        <visual name='player_side_2'>
          <pose>0 0 -0.13 -1.5707963267948966 0 0</pose>
          <geometry>
            <mesh>
              <uri>model://foosball/meshes/player.dae</uri>
            </mesh>
          </geometry>
          <material>
            <script><name>Gazebo/Red</name></script>
          </material>
        </visual>

      <collision name='player_side_2'>
        <pose>0 -0.005 -0.13 0 0 0</pose>
        <geometry> <box> <size>0.045 0.13 0.055</size> </box> </geometry>
      </collision>

      
      </link>

    <joint name="transRed2" type="prismatic">
      <parent>world</parent>
      <child>shaftRed2_bridge</child>
      <axis>
        <xyz>0 0 1</xyz>
        <use_parent_model_frame>0</use_parent_model_frame>
        <limit>
          <lower>-0.07</lower>
          <upper>0.07</upper>
        </limit>
      </axis>
      <pose>0 0 0 0 0 0</pose>
    </joint>
    <joint name="rotRed2" type="revolute">
      <parent>shaftRed2_bridge</parent>
      <child>shaftRed2</child>
      <axis>
        <xyz>0 0 1</xyz>
        <limit>
          <lower>-1000</lower>
          <upper>1000</upper>
        </limit>
      </axis>
      <pose>0 0 0 0 0 0</pose>
    </joint>
    
      <link name="shaftRed3_bridge">
        <pose>-0.227 0 0.8 1.5707963267948966 0 0</pose>
      </link>
      <link name="shaftRed3">
        <pose>-0.227 0 0.8 1.5707963267948966 0 0</pose>

        <visual name='rod'>
          <pose>0 0 0 0 0 0</pose>
          <geometry>
            <cylinder>
              <radius>0.00779907</radius>
              <length>1.2</length>
            </cylinder>
          </geometry>
          <material>
            <script>
              <uri>file://media/materials/scripts/gazebo.material</uri>
              <name>Gazebo/Grey</name>
            </script>
          </material>
        </visual>

        <visual name='handle'>
          <pose>0 0 -0.6 0 0 0</pose>
          <geometry>
            <mesh>
              <uri>model://foosball/meshes/handle.dae</uri>
            </mesh>
          </geometry>
          <material>
              <script><name>Gazebo/Black</name></script>
          </material>
        </visual>

        <collision name='handle'>
          <pose>0 0 -0.6675 0 0 0</pose>
          <geometry>
            <cylinder>
              <radius>0.022</radius>
              <length>0.135</length>
            </cylinder>
          </geometry>
        </collision>

        <collision name='rod'>
          <pose>0 0 0 0 0 0</pose>
          <geometry>
            <cylinder>
              <radius>0.00779907</radius>
              <length>1.2</length>
            </cylinder>
          </geometry>
        </collision>


     

        <visual name='player_center'>
          <pose>0 0 0 -1.5707963267948966 0 0</pose>
          <geometry>
            <mesh>
              <uri>model://foosball/meshes/player.dae</uri>
            </mesh>
          </geometry>
          <material>
            <script><name>Gazebo/Red</name></script>
          </material>
        </visual>

        <collision name='player_center'>
          <pose>0 -0.005 0 0 0 0</pose>
          <geometry> <box> <size>0.045 0.13 0.055</size> </box> </geometry>
        </collision>

     
     
     

        <visual name='player_side_1'>
          <pose>0 0 0.15 -1.5707963267948966 0 0</pose>
          <geometry>
            <mesh>
              <uri>model://foosball/meshes/player.dae</uri>
            </mesh>
          </geometry>
          <material>
            <script><name>Gazebo/Red</name></script>
          </material>
        </visual>

      <collision name='player_side_1'>
        <pose>0 -0.005 0.15 0 0 0</pose>
        <geometry> <box> <size>0.045 0.13 0.055</size> </box> </geometry>
      </collision>

        <visual name='player_side_2'>
          <pose>0 0 -0.15 -1.5707963267948966 0 0</pose>
          <geometry>
            <mesh>
              <uri>model://foosball/meshes/player.dae</uri>
            </mesh>
          </geometry>
          <material>
            <script><name>Gazebo/Red</name></script>
          </material>
        </visual>

      <collision name='player_side_2'>
        <pose>0 -0.005 -0.15 0 0 0</pose>
        <geometry> <box> <size>0.045 0.13 0.055</size> </box> </geometry>
      </collision>

      
      </link>

    <joint name="transRed3" type="prismatic">
      <parent>world</parent>
      <child>shaftRed3_bridge</child>
      <axis>
        <xyz>0 0 1</xyz>
        <use_parent_model_frame>0</use_parent_model_frame>
        <limit>
          <lower>-0.18</lower>
          <upper>0.18</upper>
        </limit>
      </axis>
      <pose>0 0 0 0 0 0</pose>
    </joint>
    <joint name="rotRed3" type="revolute">
      <parent>shaftRed3_bridge</parent>
      <child>shaftRed3</child>
      <axis>
        <xyz>0 0 1</xyz>
        <limit>
          <lower>-1000</lower>
          <upper>1000</upper>
        </limit>
      </axis>
      <pose>0 0 0 0 0 0</pose>
    </joint>
     
      <link name="shaftBlue0_bridge">
        <pose>-0.508 0 0.8 1.5707963267948966 0 0</pose>
      </link>
      <link name="shaftBlue0">
        <pose>-0.508 0 0.8 1.5707963267948966 0 0</pose>

        <visual name='rod'>
          <pose>0 0 0 0 0 0</pose>
          <geometry>
            <cylinder>
              <radius>0.00779907</radius>
              <length>1.2</length>
            </cylinder>
          </geometry>
          <material>
            <script>
              <uri>file://media/materials/scripts/gazebo.material</uri>
              <name>Gazebo/Grey</name>
            </script>
          </material>
        </visual>

        <visual name='handle'>
          <pose>0 0 0.6 0 -3.141592653589793 0</pose>
          <geometry>
            <mesh>
              <uri>model://foosball/meshes/handle.dae</uri>
            </mesh>
          </geometry>
          <material>
              <script><name>Gazebo/Black</name></script>
          </material>
        </visual>

        <collision name='handle'>
          <pose>0 0 0.6675 0 0 0</pose>
          <geometry>
            <cylinder>
              <radius>0.022</radius>
              <length>0.135</length>
            </cylinder>
          </geometry>
        </collision>

        <collision name='rod'>
          <pose>0 0 0 0 0 0</pose>
          <geometry>
            <cylinder>
              <radius>0.00779907</radius>
              <length>1.2</length>
            </cylinder>
          </geometry>
        </collision>


     

        <visual name='player_center'>
          <pose>0 0 0 -1.5707963267948966 0 0</pose>
          <geometry>
            <mesh>
              <uri>model://foosball/meshes/player.dae</uri>
            </mesh>
          </geometry>
          <material>
            <script><name>Gazebo/Blue</name></script>
          </material>
        </visual>

        <collision name='player_center'>
          <pose>0 -0.005 0 0 0 0</pose>
          <geometry> <box> <size>0.045 0.13 0.055</size> </box> </geometry>
        </collision>

     
     
     
      </link>

    <joint name="transBlue0" type="prismatic">
      <parent>world</parent>
      <child>shaftBlue0_bridge</child>
      <axis>
        <xyz>0 0 1</xyz>
        <use_parent_model_frame>0</use_parent_model_frame>
        <limit>
          <lower>-0.09</lower>
          <upper>0.09</upper>
        </limit>
      </axis>
      <pose>0 0 0 0 0 0</pose>
    </joint>
    <joint name="rotBlue0" type="revolute">
      <parent>shaftBlue0_bridge</parent>
      <child>shaftBlue0</child>
      <axis>
        <xyz>0 0 1</xyz>
        <limit>
          <lower>-1000</lower>
          <upper>1000</upper>
        </limit>
      </axis>
      <pose>0 0 0 0 0 0</pose>
    </joint>
    
      <link name="shaftBlue1_bridge">
        <pose>-0.3675 0 0.8 1.5707963267948966 0 0</pose>
      </link>
      <link name="shaftBlue1">
        <pose>-0.3675 0 0.8 1.5707963267948966 0 0</pose>

        <visual name='rod'>
          <pose>0 0 0 0 0 0</pose>
          <geometry>
            <cylinder>
              <radius>0.00779907</radius>
              <length>1.2</length>
            </cylinder>
          </geometry>
          <material>
            <script>
              <uri>file://media/materials/scripts/gazebo.material</uri>
              <name>Gazebo/Grey</name>
            </script>
          </material>
        </visual>

        <visual name='handle'>
          <pose>0 0 0.6 0 -3.141592653589793 0</pose>
          <geometry>
            <mesh>
              <uri>model://foosball/meshes/handle.dae</uri>
            </mesh>
          </geometry>
          <material>
              <script><name>Gazebo/Black</name></script>
          </material>
        </visual>

        <collision name='handle'>
          <pose>0 0 0.6675 0 0 0</pose>
          <geometry>
            <cylinder>
              <radius>0.022</radius>
              <length>0.135</length>
            </cylinder>
          </geometry>
        </collision>

        <collision name='rod'>
          <pose>0 0 0 0 0 0</pose>
          <geometry>
            <cylinder>
              <radius>0.00779907</radius>
              <length>1.2</length>
            </cylinder>
          </geometry>
        </collision>


     
     
     

        <visual name='player_side_1'>
          <pose>0 0 0.1 -1.5707963267948966 0 0</pose>
          <geometry>
            <mesh>
              <uri>model://foosball/meshes/player.dae</uri>
            </mesh>
          </geometry>
          <material>
            <script><name>Gazebo/Blue</name></script>
          </material>
        </visual>

      <collision name='player_side_1'>
        <pose>0 -0.005 0.1 0 0 0</pose>
        <geometry> <box> <size>0.045 0.13 0.055</size> </box> </geometry>
      </collision>

        <visual name='player_side_2'>
          <pose>0 0 -0.1 -1.5707963267948966 0 0</pose>
          <geometry>
            <mesh>
              <uri>model://foosball/meshes/player.dae</uri>
            </mesh>
          </geometry>
          <material>
            <script><name>Gazebo/Blue</name></script>
          </material>
        </visual>

      <collision name='player_side_2'>
        <pose>0 -0.005 -0.1 0 0 0</pose>
        <geometry> <box> <size>0.045 0.13 0.055</size> </box> </geometry>
      </collision>

      
      </link>

    <joint name="transBlue1" type="prismatic">
      <parent>world</parent>
      <child>shaftBlue1_bridge</child>
      <axis>
        <xyz>0 0 1</xyz>
        <use_parent_model_frame>0</use_parent_model_frame>
        <limit>
          <lower>-0.23</lower>
          <upper>0.23</upper>
        </limit>
      </axis>
      <pose>0 0 0 0 0 0</pose>
    </joint>
    <joint name="rotBlue1" type="revolute">
      <parent>shaftBlue1_bridge</parent>
      <child>shaftBlue1</child>
      <axis>
        <xyz>0 0 1</xyz>
        <limit>
          <lower>-1000</lower>
          <upper>1000</upper>
        </limit>
      </axis>
      <pose>0 0 0 0 0 0</pose>
    </joint>
    
      <link name="shaftBlue2_bridge">
        <pose>-0.087 0 0.8 1.5707963267948966 0 0</pose>
      </link>
      <link name="shaftBlue2">
        <pose>-0.087 0 0.8 1.5707963267948966 0 0</pose>

        <visual name='rod'>
          <pose>0 0 0 0 0 0</pose>
          <geometry>
            <cylinder>
              <radius>0.00779907</radius>
              <length>1.2</length>
            </cylinder>
          </geometry>
          <material>
            <script>
              <uri>file://media/materials/scripts/gazebo.material</uri>
              <name>Gazebo/Grey</name>
            </script>
          </material>
        </visual>

        <visual name='handle'>
          <pose>0 0 0.6 0 -3.141592653589793 0</pose>
          <geometry>
            <mesh>
              <uri>model://foosball/meshes/handle.dae</uri>
            </mesh>
          </geometry>
          <material>
              <script><name>Gazebo/Black</name></script>
          </material>
        </visual>

        <collision name='handle'>
          <pose>0 0 0.6675 0 0 0</pose>
          <geometry>
            <cylinder>
              <radius>0.022</radius>
              <length>0.135</length>
            </cylinder>
          </geometry>
        </collision>

        <collision name='rod'>
          <pose>0 0 0 0 0 0</pose>
          <geometry>
            <cylinder>
              <radius>0.00779907</radius>
              <length>1.2</length>
            </cylinder>
          </geometry>
        </collision>


     

        <visual name='player_center'>
          <pose>0 0 0 -1.5707963267948966 0 0</pose>
          <geometry>
            <mesh>
              <uri>model://foosball/meshes/player.dae</uri>
            </mesh>
          </geometry>
          <material>
            <script><name>Gazebo/Blue</name></script>
          </material>
        </visual>

        <collision name='player_center'>
          <pose>0 -0.005 0 0 0 0</pose>
          <geometry> <box> <size>0.045 0.13 0.055</size> </box> </geometry>
        </collision>

     
     

        <visual name='player_mid_1'>
        <pose>0 0 0.26 -1.5707963267948966 0 0</pose>
          <geometry>
            <mesh>
              <uri>model://foosball/meshes/player.dae</uri>
            </mesh>
          </geometry>
          <material>
            <script>
              <name>Gazebo/Blue</name>
            </script>
          </material>
        </visual>

      <collision name='player_mid_1'>
        <pose>0 -0.005 0.26 0 0 0</pose>
        <geometry> <box> <size>0.045 0.13 0.055</size> </box> </geometry>
      </collision>

        <visual name='player_mid_2'>
          <pose>0 0 -0.26 -1.5707963267948966 0 0</pose>
          <geometry>
            <mesh>
              <uri>model://foosball/meshes/player.dae</uri>
            </mesh>
          </geometry>
          <material>
            <script><name>Gazebo/Blue</name></script>
          </material>
        </visual>

       <collision name='player_mid_2'>
        <pose>0 -0.005 -0.26 0 0 0</pose>
        <geometry> <box> <size>0.045 0.13 0.055</size> </box> </geometry>
      </collision>
     
     

        <visual name='player_side_1'>
          <pose>0 0 0.13 -1.5707963267948966 0 0</pose>
          <geometry>
            <mesh>
              <uri>model://foosball/meshes/player.dae</uri>
            </mesh>
          </geometry>
          <material>
            <script><name>Gazebo/Blue</name></script>
          </material>
        </visual>

      <collision name='player_side_1'>
        <pose>0 -0.005 0.13 0 0 0</pose>
        <geometry> <box> <size>0.045 0.13 0.055</size> </box> </geometry>
      </collision>

        <visual name='player_side_2'>
          <pose>0 0 -0.13 -1.5707963267948966 0 0</pose>
          <geometry>
            <mesh>
              <uri>model://foosball/meshes/player.dae</uri>
            </mesh>
          </geometry>
          <material>
            <script><name>Gazebo/Blue</name></script>
          </material>
        </visual>

      <collision name='player_side_2'>
        <pose>0 -0.005 -0.13 0 0 0</pose>
        <geometry> <box> <size>0.045 0.13 0.055</size> </box> </geometry>
      </collision>

      
      </link>

    <joint name="transBlue2" type="prismatic">
      <parent>world</parent>
      <child>shaftBlue2_bridge</child>
      <axis>
        <xyz>0 0 1</xyz>
        <use_parent_model_frame>0</use_parent_model_frame>
        <limit>
          <lower>-0.07</lower>
          <upper>0.07</upper>
        </limit>
      </axis>
      <pose>0 0 0 0 0 0</pose>
    </joint>
    <joint name="rotBlue2" type="revolute">
      <parent>shaftBlue2_bridge</parent>
      <child>shaftBlue2</child>
      <axis>
        <xyz>0 0 1</xyz>
        <limit>
          <lower>-1000</lower>
          <upper>1000</upper>
        </limit>
      </axis>
      <pose>0 0 0 0 0 0</pose>
    </joint>
    
      <link name="shaftBlue3_bridge">
        <pose>0.227 0 0.8 1.5707963267948966 0 0</pose>
      </link>
      <link name="shaftBlue3">
        <pose>0.227 0 0.8 1.5707963267948966 0 0</pose>

        <visual name='rod'>
          <pose>0 0 0 0 0 0</pose>
          <geometry>
            <cylinder>
              <radius>0.00779907</radius>
              <length>1.2</length>
            </cylinder>
          </geometry>
          <material>
            <script>
              <uri>file://media/materials/scripts/gazebo.material</uri>
              <name>Gazebo/Grey</name>
            </script>
          </material>
        </visual>

        <visual name='handle'>
          <pose>0 0 0.6 0 -3.141592653589793 0</pose>
          <geometry>
            <mesh>
              <uri>model://foosball/meshes/handle.dae</uri>
            </mesh>
          </geometry>
          <material>
              <script><name>Gazebo/Black</name></script>
          </material>
        </visual>

        <collision name='handle'>
          <pose>0 0 0.6675 0 0 0</pose>
          <geometry>
            <cylinder>
              <radius>0.022</radius>
              <length>0.135</length>
            </cylinder>
          </geometry>
        </collision>

        <collision name='rod'>
          <pose>0 0 0 0 0 0</pose>
          <geometry>
            <cylinder>
              <radius>0.00779907</radius>
              <length>1.2</length>
            </cylinder>
          </geometry>
        </collision>


     

        <visual name='player_center'>
          <pose>0 0 0 -1.5707963267948966 0 0</pose>
          <geometry>
            <mesh>
              <uri>model://foosball/meshes/player.dae</uri>
            </mesh>
          </geometry>
          <material>
            <script><name>Gazebo/Blue</name></script>
          </material>
        </visual>

        <collision name='player_center'>
          <pose>0 -0.005 0 0 0 0</pose>
          <geometry> <box> <size>0.045 0.13 0.055</size> </box> </geometry>
        </collision>

     
     
     

        <visual name='player_side_1'>
          <pose>0 0 0.15 -1.5707963267948966 0 0</pose>
          <geometry>
            <mesh>
              <uri>model://foosball/meshes/player.dae</uri>
            </mesh>
          </geometry>
          <material>
            <script><name>Gazebo/Blue</name></script>
          </material>
        </visual>

      <collision name='player_side_1'>
        <pose>0 -0.005 0.15 0 0 0</pose>
        <geometry> <box> <size>0.045 0.13 0.055</size> </box> </geometry>
      </collision>

        <visual name='player_side_2'>
          <pose>0 0 -0.15 -1.5707963267948966 0 0</pose>
          <geometry>
            <mesh>
              <uri>model://foosball/meshes/player.dae</uri>
            </mesh>
          </geometry>
          <material>
            <script><name>Gazebo/Blue</name></script>
          </material>
        </visual>

      <collision name='player_side_2'>
        <pose>0 -0.005 -0.15 0 0 0</pose>
        <geometry> <box> <size>0.045 0.13 0.055</size> </box> </geometry>
      </collision>

      
      </link>

    <joint name="transBlue3" type="prismatic">
      <parent>world</parent>
      <child>shaftBlue3_bridge</child>
      <axis>
        <xyz>0 0 1</xyz>
        <use_parent_model_frame>0</use_parent_model_frame>
        <limit>
          <lower>-0.18</lower>
          <upper>0.18</upper>
        </limit>
      </axis>
      <pose>0 0 0 0 0 0</pose>
    </joint>
    <joint name="rotBlue3" type="revolute">
      <parent>shaftBlue3_bridge</parent>
      <child>shaftBlue3</child>
      <axis>
        <xyz>0 0 1</xyz>
        <limit>
          <lower>-1000</lower>
          <upper>1000</upper>
        </limit>
      </axis>
      <pose>0 0 0 0 0 0</pose>
    </joint>
     

    <static>0</static>
  </model>
</sdf>
