<?xml version="1.0" ?>
<!-- =================================================================================== -->
<!-- |    This document was autogenerated by xacro from src/srsim/sr_description/robots/forearm_and_hand_motor.urdf.xacro | -->
<!-- |    EDITING THIS FILE BY HAND IS NOT RECOMMENDED                                 | -->
<!-- =================================================================================== -->
<robot name="arm_and_hand" xmlns:body="http://playerstage.sourceforge.net/gazebo/xmlschema/#body" xmlns:controller="http://playerstage.sourceforge.net/gazebo/xmlschema/#controller" xmlns:geom="http://playerstage.sourceforge.net/gazebo/xmlschema/#geom" xmlns:interface="http://playerstage.sourceforge.net/gazebo/xmlschema/#interface" xmlns:joint="http://playerstage.sourceforge.net/gazebo/xmlschema/#slider" xmlns:sensor="http://playerstage.sourceforge.net/gazebo/xmlschema/#sensor" xmlns:xacro="http://ros.org/wiki/xacro">
  <material name="Blue">
    <color rgba="0.0 0.0 0.8 1.0"/>
  </material>
  <material name="Green">
    <color rgba="0.0 0.8 0.0 1.0"/>
  </material>
  <material name="BiotacGreen">
    <color rgba="0.31 0.85 0.42 1.0"/>
  </material>
  <material name="Grey">
    <color rgba="0.2 0.2 0.2 1.0"/>
  </material>
  <material name="LightGrey">
    <color rgba="0.6 0.6 0.6 1.0"/>
  </material>
  <material name="Red">
    <color rgba="0.8 0.0 0.0 1.0"/>
  </material>
  <material name="White">
    <color rgba="1.0 1.0 1.0 1.0"/>
  </material>
  <!--
  <xacro:include filename="$(find sr_description)/arm/xacro/full_arm_motor.urdf.xacro" />
-->
  <link name="world"/>
  <!--
  <joint name="arm_to_world_fixed" type="fixed">
    <parent link="world"/>
    <child link="shadowarm_lowerarm"/>
    <origin xyz="0 0 1.2" rpy="${1.57} ${3.14} ${1.57}" />
  </joint>
  -->
  <link name="shadowarm_lowerarm">
    <inertial>
      <origin rpy="0 0 0" xyz="0 0 0"/>
      <mass value="0.5"/>
      <inertia ixx="0.0001" ixy="0.0" ixz="0.0" iyy="0.0001" iyz="0.0" izz="0.0001"/>
    </inertial>
    <visual>
      <origin rpy="0 0 0" xyz="0.03 0 0.036"/>
      <geometry name="shadowarm_visual">
        <mesh filename="package://sr_description/arm/model/elbow_flex.dae" scale="0.001 0.001 0.001"/>
      </geometry>
      <material name="Grey"/>
    </visual>
    <collision>
      <origin rpy="0 0 0" xyz="0.03 0 0.036"/>
      <geometry name="shadowarm_collision_geom">
        <mesh filename="package://sr_description/arm/model/elbow_flex.dae" scale="0.001 0.001 0.001"/>
      </geometry>
    </collision>
  </link>
  <gazebo reference="shadowarm_lowerarm">
    <material>LightGrey</material>
    <selfCollide>false</selfCollide>
  </gazebo>
  <joint name="ElbowJSwing" type="revolute">
    <parent link="world"/>
    <child link="shadowarm_lowerarm"/>
    <origin rpy="0 0 0" xyz="0 0 0.369"/>
    <axis xyz="0 -1 0"/>
    <limit effort="1000.0" lower="0.52" upper="2.09439510239" velocity="10.0"/>
    <dynamics damping="20.0"/>
  </joint>
  <gazebo reference="ElbowJSwing">
    <provideFeedback>1</provideFeedback>
    <implicitSpringDamper>1</implicitSpringDamper>
  </gazebo>
  <transmission name="elbow_abduction_transmission" type="sr_mechanism_model/SimpleTransmission">
    <actuator name="elbow_abduction"/>
    <joint name="ElbowJSwing"/>
    <mechanicalReduction>1</mechanicalReduction>
    <motorTorqueConstant>1</motorTorqueConstant>
    <pulsesPerRevolution>90000</pulsesPerRevolution>
  </transmission>
  <link name="shadowarm_handsupport">
    <inertial>
      <origin rpy="0 0 0" xyz="0 0 0"/>
      <mass value="0.75"/>
      <inertia ixx="0.0001" ixy="0.0" ixz="0.0" iyy="0.0001" iyz="0.0" izz="0.0001"/>
    </inertial>
    <visual>
      <origin rpy="0 0 0" xyz="0 0 -0.04"/>
      <geometry name="shadowarm_handsupport_visual">
        <mesh filename="package://sr_description/arm/model/elbow_rotate_motor.dae" scale="0.001 0.001 0.001"/>
      </geometry>
      <material name="LightGrey"/>
    </visual>
    <collision>
      <origin rpy="0 0 0" xyz="0 0 -0.005"/>
      <geometry name="shadowarm_handsupport_collision">
        <cylinder length="0.001" radius="0.06"/>
      </geometry>
    </collision>
  </link>
  <gazebo reference="shadowarm_handsupport">
    <material>Gazebo/Grey</material>
    <selfCollide>false</selfCollide>
  </gazebo>
  <joint name="ElbowJRotate" type="revolute">
    <parent link="shadowarm_lowerarm"/>
    <child link="shadowarm_handsupport"/>
    <origin rpy="0.0 0 0" xyz="0.08 0 0.125"/>
    <axis xyz="0 0 -1"/>
    <limit effort="1000.0" lower="-1.57079632679" upper="1.57079632679" velocity="10.0"/>
    <dynamics damping="30.0"/>
  </joint>
  <gazebo reference="ElbowJRotate">
    <provideFeedback>1</provideFeedback>
    <implicitSpringDamper>1</implicitSpringDamper>
  </gazebo>
  <transmission name="forearm_rotation_transmission" type="sr_mechanism_model/SimpleTransmission">
    <actuator name="forearm_rotation"/>
    <joint name="ElbowJRotate"/>
    <mechanicalReduction>1</mechanicalReduction>
    <motorTorqueConstant>1</motorTorqueConstant>
    <pulsesPerRevolution>90000</pulsesPerRevolution>
  </transmission>
  <!-- connects forearm to lowerarm -->
  <joint name="arm_link" type="fixed">
    <parent link="shadowarm_lowerarm"/>
    <child link="forearm"/>
    <origin rpy="0 0 2.35619449" xyz="0.08 0 0.121"/>
  </joint>
  <link name="forearm">
    <inertial>
      <origin rpy="0 0 0" xyz="0 0 0.09"/>
      <mass value="3.0"/>
      <inertia ixx="0.001" ixy="0.0" ixz="0.0" iyy="0.001" iyz="0.0" izz="0.001"/>
    </inertial>
    <visual>
      <origin rpy="0 0 0" xyz="0 0 0"/>
      <geometry name="shadow_forearm_geom">
        <mesh filename="package://sr_description/hand/model/forearm.dae" scale="0.001 0.001 0.001"/>
      </geometry>
      <material name="Grey"/>
    </visual>
    <collision>
      <origin rpy="0 0 0" xyz="0 0 0.09"/>
      <geometry name="shadow_forearm_collision">
        <cylinder length="0.180" radius="0.06"/>
      </geometry>
    </collision>
  </link>
  <gazebo reference="forearm">
    <material>LightGrey</material>
    <selfCollide>false</selfCollide>
  </gazebo>
  <link name="wrist">
    <inertial>
      <origin rpy="0 0 0" xyz="0 0.0 0.0"/>
      <!--<insert_block name="origin" />-->
      <mass value="0.1"/>
      <inertia ixx="0.000120" ixy="0.0" ixz="0.0" iyy="0.000148" iyz="0.0" izz="0.0000438"/>
    </inertial>
    <visual>
      <origin rpy="0 0 0" xyz="0 0 0"/>
      <geometry name="wrist_visual">
        <mesh filename="package://sr_description/hand/model/wrist.dae" scale="0.001 0.001 0.001"/>
      </geometry>
      <material name="LightGrey"/>
    </visual>
    <collision>
      <origin rpy="0 0 0" xyz="0 0 0"/>
      <geometry name="wrist_collision_geom">
        <box size="0.02 0.02 0.02"/>
      </geometry>
    </collision>
  </link>
  <gazebo reference="wrist">
    <material>PR2/Grey2</material>
    <selfCollide>false</selfCollide>
  </gazebo>
  <joint name="WRJ2" type="revolute">
    <parent link="forearm"/>
    <child link="wrist"/>
    <!--<origin xyz="0 -0.010 0.213" rpy="0 0 0" />-->
    <origin rpy="0 0 0" xyz="0 -0.010 0.213"/>
    <axis xyz="0 1 0"/>
    <limit effort="1000.0" lower="-0.52359877559829882" upper="0.17453292519943295" velocity="10.0"/>
    <dynamics damping="30.0"/>
  </joint>
  <gazebo reference="WRJ2">
    <provideFeedback>1</provideFeedback>
    <implicitSpringDamper>1</implicitSpringDamper>
  </gazebo>
  <transmission name="wrist_transmission" type="sr_mechanism_model/SimpleTransmission">
    <actuator name="WRJ2"/>
    <joint name="WRJ2"/>
    <mechanicalReduction>1</mechanicalReduction>
    <motorTorqueConstant>1</motorTorqueConstant>
    <pulsesPerRevolution>90000</pulsesPerRevolution>
  </transmission>
  <link name="palm">
    <inertial>
      <origin rpy="0 0 0" xyz="0 0 0.035"/>
      <mass value="0.3"/>
      <inertia ixx="0.0005" ixy="0.0" ixz="0.0" iyy="0.0005" iyz="0.0" izz="0.0003"/>
    </inertial>
    <visual>
      <origin rpy="0 0 0" xyz="0 0 0"/>
      <geometry name="palm_visual">
        <mesh filename="package://sr_description/hand/model/palm.dae" scale="0.001 0.001 0.001"/>
      </geometry>
      <material name="Grey"/>
    </visual>
    <collision>
      <origin rpy="0 0 0" xyz="0.005 0 0.035"/>
      <geometry name="palm_collision_geom">
        <box size="0.05 0.02 0.07"/>
      </geometry>
    </collision>
  </link>
  <gazebo reference="palm">
    <sensor name="palm_contact" type="contact">
      <always_on>1</always_on>
      <update_rate>1000.0</update_rate>
      <contact>
        <collision>palm_collision</collision>
        <topic>palm_collision</topic>
      </contact>
      <plugin filename="libgazebo_ros_bumper.so" name="palm_gazebo_ros_bumper_controller">
        <updateRate>100.0</updateRate>
        <frameName>palm</frameName>
        <bumperTopicName>contacts/palm</bumperTopicName>
      </plugin>
    </sensor>
    <material>LightGrey</material>
  </gazebo>
  <joint name="WRJ1" type="revolute">
    <parent link="wrist"/>
    <child link="palm"/>
    <origin rpy="0 0 0" xyz="0 0 0.034"/>
    <axis xyz="1 0 0"/>
    <limit effort="1000.0" lower="-0.7854" upper="0.5236" velocity="10.0"/>
    <dynamics damping="30.0"/>
  </joint>
  <gazebo reference="WRJ1">
    <provideFeedback>1</provideFeedback>
    <implicitSpringDamper>1</implicitSpringDamper>
  </gazebo>
  <transmission name="palm_transmission" type="sr_mechanism_model/SimpleTransmission">
    <actuator name="WRJ1"/>
    <joint name="WRJ1"/>
    <mechanicalReduction>1</mechanicalReduction>
    <motorTorqueConstant>1</motorTorqueConstant>
    <pulsesPerRevolution>90000</pulsesPerRevolution>
  </transmission>
  <link name="ffknuckle">
    <inertial>
      <origin rpy="0 0 0" xyz="0 0 0"/>
      <!--<insert_block name="origin" /> -->
      <mass value="0.008"/>
      <inertia ixx="1e-6" ixy="0.0" ixz="0.0" iyy="1e-6" iyz="0.0" izz="1e-6"/>
    </inertial>
    <visual>
      <origin rpy="0 0 0" xyz="0 0 0.0005"/>
      <geometry name="ffknuckle_visual">
        <mesh filename="package://sr_description/hand/model/knuckle.dae" scale="0.001 0.001 0.001"/>
      </geometry>
      <material name="LightGrey"/>
    </visual>
    <collision>
      <origin rpy="0 0 0" xyz="0 0 0"/>
      <geometry name="ffknuckle_collision_geom">
        <box size="0.005 0.005 0.005"/>
      </geometry>
    </collision>
  </link>
  <gazebo reference="ffknuckle">
    <sensor name="ffknuckle_contact" type="contact">
      <always_on>1</always_on>
      <update_rate>1000.0</update_rate>
      <contact>
        <collision>ffknuckle_collision</collision>
        <topic>ffknuckle_collision</topic>
      </contact>
      <plugin filename="libgazebo_ros_bumper.so" name="ffknuckle_gazebo_ros_bumper_controller">
        <updateRate>100.0</updateRate>
        <frameName>ffknuckle</frameName>
        <bumperTopicName>contacts/ff/knuckle</bumperTopicName>
      </plugin>
    </sensor>
    <material>Gazebo/Grey</material>
  </gazebo>
  <joint name="FFJ4" type="revolute">
    <parent link="palm"/>
    <child link="ffknuckle"/>
    <!--<origin xyz="0.033 0 0.095" rpy="0 0 0" />-->
    <origin rpy="0 0 0" xyz="0.033 0 0.095"/>
    <axis xyz="0 -1 0"/>
    <limit effort="1000.0" lower="-0.3491" upper="0.3491" velocity="10.0"/>
    <dynamics damping="10.0"/>
  </joint>
  <gazebo reference="FFJ4">
    <provideFeedback>1</provideFeedback>
    <implicitSpringDamper>1</implicitSpringDamper>
  </gazebo>
  <transmission name="ffknuckle_transmission" type="sr_mechanism_model/SimpleTransmission">
    <actuator name="FFJ4"/>
    <joint name="FFJ4"/>
    <mechanicalReduction>1</mechanicalReduction>
    <motorTorqueConstant>1</motorTorqueConstant>
    <pulsesPerRevolution>90000</pulsesPerRevolution>
  </transmission>
  <link name="ffproximal">
    <inertial>
      <mass value="0.014"/>
      <origin xyz="0 0 0.0225"/>
      <inertia ixx="0.00001" ixy="0.0" ixz="0.0" iyy="0.00001" iyz="0.0" izz="0.00001"/>
    </inertial>
    <visual>
      <origin rpy="0 0 0" xyz="0 0 0"/>
      <geometry name="proximal_visual">
        <mesh filename="package://sr_description/hand/model/F3.dae" scale="0.001 0.001 0.001"/>
      </geometry>
      <material name="Grey"/>
    </visual>
    <collision>
      <origin rpy="0 0 0 " xyz="0 0 0.025"/>
      <geometry name="proximal_collision_geom">
        <box size="0.008 0.008 0.04"/>
      </geometry>
    </collision>
  </link>
  <gazebo reference="ffproximal">
    <sensor name="ffproximal_contact" type="contact">
      <always_on>1</always_on>
      <update_rate>1000.0</update_rate>
      <contact>
        <collision>ffproximal_collision</collision>
        <topic>ffproximal_collision</topic>
      </contact>
      <plugin filename="libgazebo_ros_bumper.so" name="ffproximal_gazebo_ros_bumper_controller">
        <updateRate>100.0</updateRate>
        <frameName>ffproximal</frameName>
        <bumperTopicName>contacts/ff/proximal</bumperTopicName>
      </plugin>
    </sensor>
    <material>LightGrey</material>
  </gazebo>
  <joint name="FFJ3" type="revolute">
    <parent link="ffknuckle"/>
    <child link="ffproximal"/>
    <origin rpy="0 0 0" xyz="0 0 0"/>
    <axis xyz="1 0 0"/>
    <limit effort="1000.0" lower="0" upper="1.57079632679" velocity="10.0"/>
    <dynamics damping="10.0"/>
  </joint>
  <gazebo reference="FFJ3">
    <provideFeedback>1</provideFeedback>
    <implicitSpringDamper>1</implicitSpringDamper>
  </gazebo>
  <transmission name="ffproximal_transmission" type="sr_mechanism_model/SimpleTransmission">
    <actuator name="FFJ3"/>
    <joint name="FFJ3"/>
    <mechanicalReduction>1</mechanicalReduction>
    <motorTorqueConstant>1</motorTorqueConstant>
    <pulsesPerRevolution>90000</pulsesPerRevolution>
  </transmission>
  <link name="ffmiddle">
    <inertial>
      <origin rpy="0 0 0" xyz="0 0 0.0125"/>
      <mass value="0.012"/>
      <inertia ixx="0.0001" ixy="0.0" ixz="0.0" iyy="0.0001" iyz="0.0" izz="0.00001"/>
    </inertial>
    <visual>
      <origin rpy="0 0 0" xyz="0 0 0"/>
      <geometry name="ffmiddle_visual">
        <mesh filename="package://sr_description/hand/model/F2.dae" scale="0.001 0.001 0.001"/>
      </geometry>
      <material name="Grey"/>
    </visual>
    <collision>
      <origin rpy="0 0 0" xyz="0 0 0.0125"/>
      <geometry name="ffmiddle_collision_geom">
        <box size="0.008 0.008 0.015"/>
      </geometry>
    </collision>
  </link>
  <gazebo reference="ffmiddle">
    <sensor name="ffmiddle_contact" type="contact">
      <always_on>1</always_on>
      <update_rate>1000.0</update_rate>
      <contact>
        <collision>ffmiddle_collision</collision>
        <topic>ffmiddle_collision</topic>
      </contact>
      <plugin filename="libgazebo_ros_bumper.so" name="ffmiddle_gazebo_ros_bumper_controller">
        <updateRate>100.0</updateRate>
        <frameName>ffmiddle</frameName>
        <bumperTopicName>contacts/ff/middle</bumperTopicName>
      </plugin>
    </sensor>
    <material>LightGrey</material>
  </gazebo>
  <joint name="FFJ2" type="revolute">
    <parent link="ffproximal"/>
    <child link="ffmiddle"/>
    <origin rpy="0 0 0" xyz="0 0 0.045"/>
    <axis xyz="1 0 0"/>
    <limit effort="1000.0" lower="0" upper="1.57079632679" velocity="10.0"/>
    <dynamics damping="10.0"/>
  </joint>
  <gazebo reference="FFJ2">
    <provideFeedback>1</provideFeedback>
    <implicitSpringDamper>1</implicitSpringDamper>
  </gazebo>
  <transmission name="ffmiddle_transmission" type="sr_mechanism_model/J0Transmission">
    <actuator name="FFJ0"/>
    <joint1 name="FFJ1"/>
    <joint2 name="FFJ2"/>
    <mechanicalReduction>1</mechanicalReduction>
    <motorTorqueConstant>1</motorTorqueConstant>
    <pulsesPerRevolution>90000</pulsesPerRevolution>
  </transmission>
  <link name="ffdistal">
    <inertial>
      <mass value="0.010"/>
      <origin xyz="0 0 0.013"/>
      <inertia ixx="0.00001" ixy="0.0" ixz="0.0" iyy="0.00001" iyz="0.0" izz="0.00001"/>
    </inertial>
    <visual>
      <origin rpy="0 0 0" xyz="0 0 0"/>
      <geometry name="ffdistal_visual">
        <mesh filename="package://sr_description/hand/model/F1.dae" scale="0.001 0.001 0.001"/>
      </geometry>
      <material name="Grey"/>
    </visual>
    <collision>
      <origin rpy="0 0 0" xyz="0 0 0"/>
      <geometry name="ffdistal_collision_geom">
        <mesh filename="package://sr_description/hand/model/F1.dae" scale="0.001 0.001 0.001"/>
      </geometry>
    </collision>
  </link>
  <gazebo reference="ffdistal">
    <sensor name="ffdistal_contact" type="contact">
      <always_on>1</always_on>
      <update_rate>1000.0</update_rate>
      <contact>
        <collision>ffdistal_collision</collision>
        <topic>ffdistal_collision</topic>
      </contact>
      <plugin filename="libgazebo_ros_bumper.so" name="ffdistal_gazebo_ros_bumper_controller">
        <updateRate>100.0</updateRate>
        <frameName>ffdistal</frameName>
        <bumperTopicName>contacts/ff/distal</bumperTopicName>
      </plugin>
    </sensor>
    <selfCollide>true</selfCollide>
    <material>LightGrey</material>
  </gazebo>
  <joint name="FFJ1" type="revolute">
    <parent link="ffmiddle"/>
    <child link="ffdistal"/>
    <origin rpy="0 0 0" xyz="0 0 0.025"/>
    <axis xyz="1 0 0"/>
    <limit effort="1000.0" lower="0" upper="1.57079632679" velocity="10.0"/>
    <dynamics damping="10.0"/>
  </joint>
  <gazebo reference="FFJ1">
    <provideFeedback>1</provideFeedback>
    <implicitSpringDamper>1</implicitSpringDamper>
  </gazebo>
  <link name="fftip">
    <inertial>
      <mass value="0.001"/>
      <inertia ixx="0.0000001" ixy="0.0" ixz="0.0" iyy="0.0000001" iyz="0.0" izz="0.0000001"/>
    </inertial>
  </link>
  <joint name="FFtip" type="fixed">
    <parent link="ffdistal"/>
    <child link="fftip"/>
    <origin rpy="0 0 0" xyz="0 0 0.026"/>
  </joint>
  <link name="mfknuckle">
    <inertial>
      <origin rpy="0 0 0" xyz="0 0 0"/>
      <!--<insert_block name="origin" /> -->
      <mass value="0.008"/>
      <inertia ixx="1e-6" ixy="0.0" ixz="0.0" iyy="1e-6" iyz="0.0" izz="1e-6"/>
    </inertial>
    <visual>
      <origin rpy="0 0 0" xyz="0 0 0.0005"/>
      <geometry name="mfknuckle_visual">
        <mesh filename="package://sr_description/hand/model/knuckle.dae" scale="0.001 0.001 0.001"/>
      </geometry>
      <material name="LightGrey"/>
    </visual>
    <collision>
      <origin rpy="0 0 0" xyz="0 0 0"/>
      <geometry name="mfknuckle_collision_geom">
        <box size="0.005 0.005 0.005"/>
      </geometry>
    </collision>
  </link>
  <gazebo reference="mfknuckle">
    <sensor name="mfknuckle_contact" type="contact">
      <always_on>1</always_on>
      <update_rate>1000.0</update_rate>
      <contact>
        <collision>mfknuckle_collision</collision>
        <topic>mfknuckle_collision</topic>
      </contact>
      <plugin filename="libgazebo_ros_bumper.so" name="mfknuckle_gazebo_ros_bumper_controller">
        <updateRate>100.0</updateRate>
        <frameName>mfknuckle</frameName>
        <bumperTopicName>contacts/mf/knuckle</bumperTopicName>
      </plugin>
    </sensor>
    <material>Gazebo/Grey</material>
  </gazebo>
  <joint name="MFJ4" type="revolute">
    <parent link="palm"/>
    <child link="mfknuckle"/>
    <!--<origin xyz="0.033 0 0.095" rpy="0 0 0" />-->
    <origin rpy="0 0 0" xyz="0.011 0 0.099"/>
    <axis xyz="0 -1 0"/>
    <limit effort="1000.0" lower="-0.3491" upper="0.3491" velocity="10.0"/>
    <dynamics damping="10.0"/>
  </joint>
  <gazebo reference="MFJ4">
    <provideFeedback>1</provideFeedback>
    <implicitSpringDamper>1</implicitSpringDamper>
  </gazebo>
  <transmission name="mfknuckle_transmission" type="sr_mechanism_model/SimpleTransmission">
    <actuator name="MFJ4"/>
    <joint name="MFJ4"/>
    <mechanicalReduction>1</mechanicalReduction>
    <motorTorqueConstant>1</motorTorqueConstant>
    <pulsesPerRevolution>90000</pulsesPerRevolution>
  </transmission>
  <link name="mfproximal">
    <inertial>
      <mass value="0.014"/>
      <origin xyz="0 0 0.0225"/>
      <inertia ixx="0.00001" ixy="0.0" ixz="0.0" iyy="0.00001" iyz="0.0" izz="0.00001"/>
    </inertial>
    <visual>
      <origin rpy="0 0 0" xyz="0 0 0"/>
      <geometry name="proximal_visual">
        <mesh filename="package://sr_description/hand/model/F3.dae" scale="0.001 0.001 0.001"/>
      </geometry>
      <material name="Grey"/>
    </visual>
    <collision>
      <origin rpy="0 0 0 " xyz="0 0 0.025"/>
      <geometry name="proximal_collision_geom">
        <box size="0.008 0.008 0.04"/>
      </geometry>
    </collision>
  </link>
  <gazebo reference="mfproximal">
    <sensor name="mfproximal_contact" type="contact">
      <always_on>1</always_on>
      <update_rate>1000.0</update_rate>
      <contact>
        <collision>mfproximal_collision</collision>
        <topic>mfproximal_collision</topic>
      </contact>
      <plugin filename="libgazebo_ros_bumper.so" name="mfproximal_gazebo_ros_bumper_controller">
        <updateRate>100.0</updateRate>
        <frameName>mfproximal</frameName>
        <bumperTopicName>contacts/mf/proximal</bumperTopicName>
      </plugin>
    </sensor>
    <material>LightGrey</material>
  </gazebo>
  <joint name="MFJ3" type="revolute">
    <parent link="mfknuckle"/>
    <child link="mfproximal"/>
    <origin rpy="0 0 0" xyz="0 0 0"/>
    <axis xyz="1 0 0"/>
    <limit effort="1000.0" lower="0" upper="1.57079632679" velocity="10.0"/>
    <dynamics damping="10.0"/>
  </joint>
  <gazebo reference="MFJ3">
    <provideFeedback>1</provideFeedback>
    <implicitSpringDamper>1</implicitSpringDamper>
  </gazebo>
  <transmission name="mfproximal_transmission" type="sr_mechanism_model/SimpleTransmission">
    <actuator name="MFJ3"/>
    <joint name="MFJ3"/>
    <mechanicalReduction>1</mechanicalReduction>
    <motorTorqueConstant>1</motorTorqueConstant>
    <pulsesPerRevolution>90000</pulsesPerRevolution>
  </transmission>
  <link name="mfmiddle">
    <inertial>
      <origin rpy="0 0 0" xyz="0 0 0.0125"/>
      <mass value="0.012"/>
      <inertia ixx="0.0001" ixy="0.0" ixz="0.0" iyy="0.0001" iyz="0.0" izz="0.00001"/>
    </inertial>
    <visual>
      <origin rpy="0 0 0" xyz="0 0 0"/>
      <geometry name="mfmiddle_visual">
        <mesh filename="package://sr_description/hand/model/F2.dae" scale="0.001 0.001 0.001"/>
      </geometry>
      <material name="Grey"/>
    </visual>
    <collision>
      <origin rpy="0 0 0" xyz="0 0 0.0125"/>
      <geometry name="mfmiddle_collision_geom">
        <box size="0.008 0.008 0.015"/>
      </geometry>
    </collision>
  </link>
  <gazebo reference="mfmiddle">
    <sensor name="mfmiddle_contact" type="contact">
      <always_on>1</always_on>
      <update_rate>1000.0</update_rate>
      <contact>
        <collision>mfmiddle_collision</collision>
        <topic>mfmiddle_collision</topic>
      </contact>
      <plugin filename="libgazebo_ros_bumper.so" name="mfmiddle_gazebo_ros_bumper_controller">
        <updateRate>100.0</updateRate>
        <frameName>mfmiddle</frameName>
        <bumperTopicName>contacts/mf/middle</bumperTopicName>
      </plugin>
    </sensor>
    <material>LightGrey</material>
  </gazebo>
  <joint name="MFJ2" type="revolute">
    <parent link="mfproximal"/>
    <child link="mfmiddle"/>
    <origin rpy="0 0 0" xyz="0 0 0.045"/>
    <axis xyz="1 0 0"/>
    <limit effort="1000.0" lower="0" upper="1.57079632679" velocity="10.0"/>
    <dynamics damping="10.0"/>
  </joint>
  <gazebo reference="MFJ2">
    <provideFeedback>1</provideFeedback>
    <implicitSpringDamper>1</implicitSpringDamper>
  </gazebo>
  <transmission name="mfmiddle_transmission" type="sr_mechanism_model/J0Transmission">
    <actuator name="MFJ0"/>
    <joint1 name="MFJ1"/>
    <joint2 name="MFJ2"/>
    <mechanicalReduction>1</mechanicalReduction>
    <motorTorqueConstant>1</motorTorqueConstant>
    <pulsesPerRevolution>90000</pulsesPerRevolution>
  </transmission>
  <link name="mfdistal">
    <inertial>
      <mass value="0.010"/>
      <origin xyz="0 0 0.013"/>
      <inertia ixx="0.00001" ixy="0.0" ixz="0.0" iyy="0.00001" iyz="0.0" izz="0.00001"/>
    </inertial>
    <visual>
      <origin rpy="0 0 0" xyz="0 0 0"/>
      <geometry name="mfdistal_visual">
        <mesh filename="package://sr_description/hand/model/F1.dae" scale="0.001 0.001 0.001"/>
      </geometry>
      <material name="Grey"/>
    </visual>
    <collision>
      <origin rpy="0 0 0" xyz="0 0 0"/>
      <geometry name="mfdistal_collision_geom">
        <mesh filename="package://sr_description/hand/model/F1.dae" scale="0.001 0.001 0.001"/>
      </geometry>
    </collision>
  </link>
  <gazebo reference="mfdistal">
    <sensor name="mfdistal_contact" type="contact">
      <always_on>1</always_on>
      <update_rate>1000.0</update_rate>
      <contact>
        <collision>mfdistal_collision</collision>
        <topic>mfdistal_collision</topic>
      </contact>
      <plugin filename="libgazebo_ros_bumper.so" name="mfdistal_gazebo_ros_bumper_controller">
        <updateRate>100.0</updateRate>
        <frameName>mfdistal</frameName>
        <bumperTopicName>contacts/mf/distal</bumperTopicName>
      </plugin>
    </sensor>
    <selfCollide>true</selfCollide>
    <material>LightGrey</material>
  </gazebo>
  <joint name="MFJ1" type="revolute">
    <parent link="mfmiddle"/>
    <child link="mfdistal"/>
    <origin rpy="0 0 0" xyz="0 0 0.025"/>
    <axis xyz="1 0 0"/>
    <limit effort="1000.0" lower="0" upper="1.57079632679" velocity="10.0"/>
    <dynamics damping="10.0"/>
  </joint>
  <gazebo reference="MFJ1">
    <provideFeedback>1</provideFeedback>
    <implicitSpringDamper>1</implicitSpringDamper>
  </gazebo>
  <link name="mftip">
    <inertial>
      <mass value="0.001"/>
      <inertia ixx="0.0000001" ixy="0.0" ixz="0.0" iyy="0.0000001" iyz="0.0" izz="0.0000001"/>
    </inertial>
  </link>
  <joint name="MFtip" type="fixed">
    <parent link="mfdistal"/>
    <child link="mftip"/>
    <origin rpy="0 0 0" xyz="0 0 0.026"/>
  </joint>
  <link name="rfknuckle">
    <inertial>
      <origin rpy="0 0 0" xyz="0 0 0"/>
      <!--<insert_block name="origin" /> -->
      <mass value="0.008"/>
      <inertia ixx="1e-6" ixy="0.0" ixz="0.0" iyy="1e-6" iyz="0.0" izz="1e-6"/>
    </inertial>
    <visual>
      <origin rpy="0 0 0" xyz="0 0 0.0005"/>
      <geometry name="rfknuckle_visual">
        <mesh filename="package://sr_description/hand/model/knuckle.dae" scale="0.001 0.001 0.001"/>
      </geometry>
      <material name="LightGrey"/>
    </visual>
    <collision>
      <origin rpy="0 0 0" xyz="0 0 0"/>
      <geometry name="rfknuckle_collision_geom">
        <box size="0.005 0.005 0.005"/>
      </geometry>
    </collision>
  </link>
  <gazebo reference="rfknuckle">
    <sensor name="rfknuckle_contact" type="contact">
      <always_on>1</always_on>
      <update_rate>1000.0</update_rate>
      <contact>
        <collision>rfknuckle_collision</collision>
        <topic>rfknuckle_collision</topic>
      </contact>
      <plugin filename="libgazebo_ros_bumper.so" name="rfknuckle_gazebo_ros_bumper_controller">
        <updateRate>100.0</updateRate>
        <frameName>rfknuckle</frameName>
        <bumperTopicName>contacts/rf/knuckle</bumperTopicName>
      </plugin>
    </sensor>
    <material>Gazebo/Grey</material>
  </gazebo>
  <joint name="RFJ4" type="revolute">
    <parent link="palm"/>
    <child link="rfknuckle"/>
    <!--<origin xyz="0.033 0 0.095" rpy="0 0 0" />-->
    <origin rpy="0 0 0" xyz="-0.011 0 0.095"/>
    <axis xyz="0 1 0"/>
    <limit effort="1000.0" lower="-0.3491" upper="0.3491" velocity="10.0"/>
    <dynamics damping="10.0"/>
  </joint>
  <gazebo reference="RFJ4">
    <provideFeedback>1</provideFeedback>
    <implicitSpringDamper>1</implicitSpringDamper>
  </gazebo>
  <transmission name="rfknuckle_transmission" type="sr_mechanism_model/SimpleTransmission">
    <actuator name="RFJ4"/>
    <joint name="RFJ4"/>
    <mechanicalReduction>1</mechanicalReduction>
    <motorTorqueConstant>1</motorTorqueConstant>
    <pulsesPerRevolution>90000</pulsesPerRevolution>
  </transmission>
  <link name="rfproximal">
    <inertial>
      <mass value="0.014"/>
      <origin xyz="0 0 0.0225"/>
      <inertia ixx="0.00001" ixy="0.0" ixz="0.0" iyy="0.00001" iyz="0.0" izz="0.00001"/>
    </inertial>
    <visual>
      <origin rpy="0 0 0" xyz="0 0 0"/>
      <geometry name="proximal_visual">
        <mesh filename="package://sr_description/hand/model/F3.dae" scale="0.001 0.001 0.001"/>
      </geometry>
      <material name="Grey"/>
    </visual>
    <collision>
      <origin rpy="0 0 0 " xyz="0 0 0.025"/>
      <geometry name="proximal_collision_geom">
        <box size="0.008 0.008 0.04"/>
      </geometry>
    </collision>
  </link>
  <gazebo reference="rfproximal">
    <sensor name="rfproximal_contact" type="contact">
      <always_on>1</always_on>
      <update_rate>1000.0</update_rate>
      <contact>
        <collision>rfproximal_collision</collision>
        <topic>rfproximal_collision</topic>
      </contact>
      <plugin filename="libgazebo_ros_bumper.so" name="rfproximal_gazebo_ros_bumper_controller">
        <updateRate>100.0</updateRate>
        <frameName>rfproximal</frameName>
        <bumperTopicName>contacts/rf/proximal</bumperTopicName>
      </plugin>
    </sensor>
    <material>LightGrey</material>
  </gazebo>
  <joint name="RFJ3" type="revolute">
    <parent link="rfknuckle"/>
    <child link="rfproximal"/>
    <origin rpy="0 0 0" xyz="0 0 0"/>
    <axis xyz="1 0 0"/>
    <limit effort="1000.0" lower="0" upper="1.57079632679" velocity="10.0"/>
    <dynamics damping="10.0"/>
  </joint>
  <gazebo reference="RFJ3">
    <provideFeedback>1</provideFeedback>
    <implicitSpringDamper>1</implicitSpringDamper>
  </gazebo>
  <transmission name="rfproximal_transmission" type="sr_mechanism_model/SimpleTransmission">
    <actuator name="RFJ3"/>
    <joint name="RFJ3"/>
    <mechanicalReduction>1</mechanicalReduction>
    <motorTorqueConstant>1</motorTorqueConstant>
    <pulsesPerRevolution>90000</pulsesPerRevolution>
  </transmission>
  <link name="rfmiddle">
    <inertial>
      <origin rpy="0 0 0" xyz="0 0 0.0125"/>
      <mass value="0.012"/>
      <inertia ixx="0.0001" ixy="0.0" ixz="0.0" iyy="0.0001" iyz="0.0" izz="0.00001"/>
    </inertial>
    <visual>
      <origin rpy="0 0 0" xyz="0 0 0"/>
      <geometry name="rfmiddle_visual">
        <mesh filename="package://sr_description/hand/model/F2.dae" scale="0.001 0.001 0.001"/>
      </geometry>
      <material name="Grey"/>
    </visual>
    <collision>
      <origin rpy="0 0 0" xyz="0 0 0.0125"/>
      <geometry name="rfmiddle_collision_geom">
        <box size="0.008 0.008 0.015"/>
      </geometry>
    </collision>
  </link>
  <gazebo reference="rfmiddle">
    <sensor name="rfmiddle_contact" type="contact">
      <always_on>1</always_on>
      <update_rate>1000.0</update_rate>
      <contact>
        <collision>rfmiddle_collision</collision>
        <topic>rfmiddle_collision</topic>
      </contact>
      <plugin filename="libgazebo_ros_bumper.so" name="rfmiddle_gazebo_ros_bumper_controller">
        <updateRate>100.0</updateRate>
        <frameName>rfmiddle</frameName>
        <bumperTopicName>contacts/rf/middle</bumperTopicName>
      </plugin>
    </sensor>
    <material>LightGrey</material>
  </gazebo>
  <joint name="RFJ2" type="revolute">
    <parent link="rfproximal"/>
    <child link="rfmiddle"/>
    <origin rpy="0 0 0" xyz="0 0 0.045"/>
    <axis xyz="1 0 0"/>
    <limit effort="1000.0" lower="0" upper="1.57079632679" velocity="10.0"/>
    <dynamics damping="10.0"/>
  </joint>
  <gazebo reference="RFJ2">
    <provideFeedback>1</provideFeedback>
    <implicitSpringDamper>1</implicitSpringDamper>
  </gazebo>
  <transmission name="rfmiddle_transmission" type="sr_mechanism_model/J0Transmission">
    <actuator name="RFJ0"/>
    <joint1 name="RFJ1"/>
    <joint2 name="RFJ2"/>
    <mechanicalReduction>1</mechanicalReduction>
    <motorTorqueConstant>1</motorTorqueConstant>
    <pulsesPerRevolution>90000</pulsesPerRevolution>
  </transmission>
  <link name="rfdistal">
    <inertial>
      <mass value="0.010"/>
      <origin xyz="0 0 0.013"/>
      <inertia ixx="0.00001" ixy="0.0" ixz="0.0" iyy="0.00001" iyz="0.0" izz="0.00001"/>
    </inertial>
    <visual>
      <origin rpy="0 0 0" xyz="0 0 0"/>
      <geometry name="rfdistal_visual">
        <mesh filename="package://sr_description/hand/model/F1.dae" scale="0.001 0.001 0.001"/>
      </geometry>
      <material name="Grey"/>
    </visual>
    <collision>
      <origin rpy="0 0 0" xyz="0 0 0"/>
      <geometry name="rfdistal_collision_geom">
        <mesh filename="package://sr_description/hand/model/F1.dae" scale="0.001 0.001 0.001"/>
      </geometry>
    </collision>
  </link>
  <gazebo reference="rfdistal">
    <sensor name="rfdistal_contact" type="contact">
      <always_on>1</always_on>
      <update_rate>1000.0</update_rate>
      <contact>
        <collision>rfdistal_collision</collision>
        <topic>rfdistal_collision</topic>
      </contact>
      <plugin filename="libgazebo_ros_bumper.so" name="rfdistal_gazebo_ros_bumper_controller">
        <updateRate>100.0</updateRate>
        <frameName>rfdistal</frameName>
        <bumperTopicName>contacts/rf/distal</bumperTopicName>
      </plugin>
    </sensor>
    <selfCollide>true</selfCollide>
    <material>LightGrey</material>
  </gazebo>
  <joint name="RFJ1" type="revolute">
    <parent link="rfmiddle"/>
    <child link="rfdistal"/>
    <origin rpy="0 0 0" xyz="0 0 0.025"/>
    <axis xyz="1 0 0"/>
    <limit effort="1000.0" lower="0" upper="1.57079632679" velocity="10.0"/>
    <dynamics damping="10.0"/>
  </joint>
  <gazebo reference="RFJ1">
    <provideFeedback>1</provideFeedback>
    <implicitSpringDamper>1</implicitSpringDamper>
  </gazebo>
  <link name="rftip">
    <inertial>
      <mass value="0.001"/>
      <inertia ixx="0.0000001" ixy="0.0" ixz="0.0" iyy="0.0000001" iyz="0.0" izz="0.0000001"/>
    </inertial>
  </link>
  <joint name="RFtip" type="fixed">
    <parent link="rfdistal"/>
    <child link="rftip"/>
    <origin rpy="0 0 0" xyz="0 0 0.026"/>
  </joint>
  <link name="lfmetacarpal">
    <inertial>
      <origin rpy="0 0 0" xyz="0 0 0.04"/>
      <mass value="0.075"/>
      <inertia ixx="1e-6" ixy="0.0" ixz="0.0" iyy="1e-6" iyz="0.0" izz="1e-6"/>
    </inertial>
    <visual>
      <origin rpy="0 0 0" xyz="0 0 0"/>
      <geometry name="lfmetacarpal_visual">
        <mesh filename="package://sr_description/hand/model/lfmetacarpal.dae" scale="0.001 0.001 0.001"/>
      </geometry>
      <material name="Grey"/>
    </visual>
    <collision>
      <origin rpy="0 0 0" xyz="0 0 0.04"/>
      <geometry name="lfmetacarpal_collision_geom">
        <box size="0.008 0.008 0.03"/>
      </geometry>
    </collision>
  </link>
  <gazebo reference="lfmetacarpal">
    <sensor name="lfmetacarpal_contact" type="contact">
      <always_on>1</always_on>
      <update_rate>1000.0</update_rate>
      <contact>
        <collision>lfmetacarpal_collision</collision>
        <topic>lfmetacarpal_collision</topic>
      </contact>
      <plugin filename="libgazebo_ros_bumper.so" name="lfmetacarpal_gazebo_ros_bumper_controller">
        <updateRate>100.0</updateRate>
        <frameName>lfmetacarpal</frameName>
        <bumperTopicName>contacts/lf/metacarpal</bumperTopicName>
      </plugin>
    </sensor>
    <material>LightGrey</material>
  </gazebo>
  <joint name="LFJ5" type="revolute">
    <parent link="palm"/>
    <child link="lfmetacarpal"/>
    <origin rpy="0 0 0" xyz="-0.033 0 0.02071"/>
    <axis xyz="0.573576436 0 0.819152044"/>
    <limit effort="1000.0" lower="0" upper="0.785398163" velocity="10.0"/>
    <dynamics damping="10.0"/>
  </joint>
  <gazebo reference="LFJ5">
    <provideFeedback>1</provideFeedback>
    <implicitSpringDamper>1</implicitSpringDamper>
  </gazebo>
  <transmission name="lfmetacarpal_transmission" type="sr_mechanism_model/SimpleTransmission">
    <actuator name="LFJ5"/>
    <joint name="LFJ5"/>
    <mechanicalReduction>1</mechanicalReduction>
    <motorTorqueConstant>1</motorTorqueConstant>
    <pulsesPerRevolution>90000</pulsesPerRevolution>
  </transmission>
  <link name="lfknuckle">
    <inertial>
      <origin rpy="0 0 0" xyz="0 0 0"/>
      <!--<insert_block name="origin" /> -->
      <mass value="0.008"/>
      <inertia ixx="1e-6" ixy="0.0" ixz="0.0" iyy="1e-6" iyz="0.0" izz="1e-6"/>
    </inertial>
    <visual>
      <origin rpy="0 0 0" xyz="0 0 0.0005"/>
      <geometry name="lfknuckle_visual">
        <mesh filename="package://sr_description/hand/model/knuckle.dae" scale="0.001 0.001 0.001"/>
      </geometry>
      <material name="LightGrey"/>
    </visual>
    <collision>
      <origin rpy="0 0 0" xyz="0 0 0"/>
      <geometry name="lfknuckle_collision_geom">
        <box size="0.005 0.005 0.005"/>
      </geometry>
    </collision>
  </link>
  <gazebo reference="lfknuckle">
    <sensor name="lfknuckle_contact" type="contact">
      <always_on>1</always_on>
      <update_rate>1000.0</update_rate>
      <contact>
        <collision>lfknuckle_collision</collision>
        <topic>lfknuckle_collision</topic>
      </contact>
      <plugin filename="libgazebo_ros_bumper.so" name="lfknuckle_gazebo_ros_bumper_controller">
        <updateRate>100.0</updateRate>
        <frameName>lfknuckle</frameName>
        <bumperTopicName>contacts/lf/knuckle</bumperTopicName>
      </plugin>
    </sensor>
    <material>Gazebo/Grey</material>
  </gazebo>
  <joint name="LFJ4" type="revolute">
    <parent link="lfmetacarpal"/>
    <child link="lfknuckle"/>
    <!--<origin xyz="0.033 0 0.095" rpy="0 0 0" />-->
    <origin rpy="0 0 0" xyz="0 0 0.06579"/>
    <axis xyz="0 1 0"/>
    <limit effort="1000.0" lower="-0.3491" upper="0.3491" velocity="10.0"/>
    <dynamics damping="10.0"/>
  </joint>
  <gazebo reference="LFJ4">
    <provideFeedback>1</provideFeedback>
    <implicitSpringDamper>1</implicitSpringDamper>
  </gazebo>
  <transmission name="lfknuckle_transmission" type="sr_mechanism_model/SimpleTransmission">
    <actuator name="LFJ4"/>
    <joint name="LFJ4"/>
    <mechanicalReduction>1</mechanicalReduction>
    <motorTorqueConstant>1</motorTorqueConstant>
    <pulsesPerRevolution>90000</pulsesPerRevolution>
  </transmission>
  <link name="lfproximal">
    <inertial>
      <mass value="0.014"/>
      <origin xyz="0 0 0.0225"/>
      <inertia ixx="0.00001" ixy="0.0" ixz="0.0" iyy="0.00001" iyz="0.0" izz="0.00001"/>
    </inertial>
    <visual>
      <origin rpy="0 0 0" xyz="0 0 0"/>
      <geometry name="proximal_visual">
        <mesh filename="package://sr_description/hand/model/F3.dae" scale="0.001 0.001 0.001"/>
      </geometry>
      <material name="Grey"/>
    </visual>
    <collision>
      <origin rpy="0 0 0 " xyz="0 0 0.025"/>
      <geometry name="proximal_collision_geom">
        <box size="0.008 0.008 0.04"/>
      </geometry>
    </collision>
  </link>
  <gazebo reference="lfproximal">
    <sensor name="lfproximal_contact" type="contact">
      <always_on>1</always_on>
      <update_rate>1000.0</update_rate>
      <contact>
        <collision>lfproximal_collision</collision>
        <topic>lfproximal_collision</topic>
      </contact>
      <plugin filename="libgazebo_ros_bumper.so" name="lfproximal_gazebo_ros_bumper_controller">
        <updateRate>100.0</updateRate>
        <frameName>lfproximal</frameName>
        <bumperTopicName>contacts/lf/proximal</bumperTopicName>
      </plugin>
    </sensor>
    <material>LightGrey</material>
  </gazebo>
  <joint name="LFJ3" type="revolute">
    <parent link="lfknuckle"/>
    <child link="lfproximal"/>
    <origin rpy="0 0 0" xyz="0 0 0"/>
    <axis xyz="1 0 0"/>
    <limit effort="1000.0" lower="0" upper="1.57079632679" velocity="10.0"/>
    <dynamics damping="10.0"/>
  </joint>
  <gazebo reference="LFJ3">
    <provideFeedback>1</provideFeedback>
    <implicitSpringDamper>1</implicitSpringDamper>
  </gazebo>
  <transmission name="lfproximal_transmission" type="sr_mechanism_model/SimpleTransmission">
    <actuator name="LFJ3"/>
    <joint name="LFJ3"/>
    <mechanicalReduction>1</mechanicalReduction>
    <motorTorqueConstant>1</motorTorqueConstant>
    <pulsesPerRevolution>90000</pulsesPerRevolution>
  </transmission>
  <link name="lfmiddle">
    <inertial>
      <origin rpy="0 0 0" xyz="0 0 0.0125"/>
      <mass value="0.012"/>
      <inertia ixx="0.0001" ixy="0.0" ixz="0.0" iyy="0.0001" iyz="0.0" izz="0.00001"/>
    </inertial>
    <visual>
      <origin rpy="0 0 0" xyz="0 0 0"/>
      <geometry name="lfmiddle_visual">
        <mesh filename="package://sr_description/hand/model/F2.dae" scale="0.001 0.001 0.001"/>
      </geometry>
      <material name="Grey"/>
    </visual>
    <collision>
      <origin rpy="0 0 0" xyz="0 0 0.0125"/>
      <geometry name="lfmiddle_collision_geom">
        <box size="0.008 0.008 0.015"/>
      </geometry>
    </collision>
  </link>
  <gazebo reference="lfmiddle">
    <sensor name="lfmiddle_contact" type="contact">
      <always_on>1</always_on>
      <update_rate>1000.0</update_rate>
      <contact>
        <collision>lfmiddle_collision</collision>
        <topic>lfmiddle_collision</topic>
      </contact>
      <plugin filename="libgazebo_ros_bumper.so" name="lfmiddle_gazebo_ros_bumper_controller">
        <updateRate>100.0</updateRate>
        <frameName>lfmiddle</frameName>
        <bumperTopicName>contacts/lf/middle</bumperTopicName>
      </plugin>
    </sensor>
    <material>LightGrey</material>
  </gazebo>
  <joint name="LFJ2" type="revolute">
    <parent link="lfproximal"/>
    <child link="lfmiddle"/>
    <origin rpy="0 0 0" xyz="0 0 0.045"/>
    <axis xyz="1 0 0"/>
    <limit effort="1000.0" lower="0" upper="1.57079632679" velocity="10.0"/>
    <dynamics damping="10.0"/>
  </joint>
  <gazebo reference="LFJ2">
    <provideFeedback>1</provideFeedback>
    <implicitSpringDamper>1</implicitSpringDamper>
  </gazebo>
  <transmission name="lfmiddle_transmission" type="sr_mechanism_model/J0Transmission">
    <actuator name="LFJ0"/>
    <joint1 name="LFJ1"/>
    <joint2 name="LFJ2"/>
    <mechanicalReduction>1</mechanicalReduction>
    <motorTorqueConstant>1</motorTorqueConstant>
    <pulsesPerRevolution>90000</pulsesPerRevolution>
  </transmission>
  <link name="lfdistal">
    <inertial>
      <mass value="0.010"/>
      <origin xyz="0 0 0.013"/>
      <inertia ixx="0.00001" ixy="0.0" ixz="0.0" iyy="0.00001" iyz="0.0" izz="0.00001"/>
    </inertial>
    <visual>
      <origin rpy="0 0 0" xyz="0 0 0"/>
      <geometry name="lfdistal_visual">
        <mesh filename="package://sr_description/hand/model/F1.dae" scale="0.001 0.001 0.001"/>
      </geometry>
      <material name="Grey"/>
    </visual>
    <collision>
      <origin rpy="0 0 0" xyz="0 0 0"/>
      <geometry name="lfdistal_collision_geom">
        <mesh filename="package://sr_description/hand/model/F1.dae" scale="0.001 0.001 0.001"/>
      </geometry>
    </collision>
  </link>
  <gazebo reference="lfdistal">
    <sensor name="lfdistal_contact" type="contact">
      <always_on>1</always_on>
      <update_rate>1000.0</update_rate>
      <contact>
        <collision>lfdistal_collision</collision>
        <topic>lfdistal_collision</topic>
      </contact>
      <plugin filename="libgazebo_ros_bumper.so" name="lfdistal_gazebo_ros_bumper_controller">
        <updateRate>100.0</updateRate>
        <frameName>lfdistal</frameName>
        <bumperTopicName>contacts/lf/distal</bumperTopicName>
      </plugin>
    </sensor>
    <selfCollide>true</selfCollide>
    <material>LightGrey</material>
  </gazebo>
  <joint name="LFJ1" type="revolute">
    <parent link="lfmiddle"/>
    <child link="lfdistal"/>
    <origin rpy="0 0 0" xyz="0 0 0.025"/>
    <axis xyz="1 0 0"/>
    <limit effort="1000.0" lower="0" upper="1.57079632679" velocity="10.0"/>
    <dynamics damping="10.0"/>
  </joint>
  <gazebo reference="LFJ1">
    <provideFeedback>1</provideFeedback>
    <implicitSpringDamper>1</implicitSpringDamper>
  </gazebo>
  <link name="lftip">
    <inertial>
      <mass value="0.001"/>
      <inertia ixx="0.0000001" ixy="0.0" ixz="0.0" iyy="0.0000001" iyz="0.0" izz="0.0000001"/>
    </inertial>
  </link>
  <joint name="LFtip" type="fixed">
    <parent link="lfdistal"/>
    <child link="lftip"/>
    <origin rpy="0 0 0" xyz="0 0 0.026"/>
  </joint>
  <link name="thbase">
    <inertial>
      <mass value="0.010"/>
      <origin rpy="0 0 0" xyz="0 0 0"/>
      <inertia ixx="0.00001" ixy="0.0" ixz="0.0" iyy="0.00001" iyz="0.0" izz="0.00001"/>
    </inertial>
    <visual>
      <origin rpy="0 0 0" xyz="0 0 0"/>
      <geometry name="thbase_visual">
        <box size="0.001 0.001 0.001"/>
      </geometry>
      <material name="shadow_thbase_material">
        <color rgba="0.5 0.5 0.5 1.0"/>
      </material>
    </visual>
    <collision>
      <origin rpy="0 0 0 " xyz="0 0 0"/>
      <geometry name="thbase_collision_geom">
        <box size="0.001 0.001 0.001"/>
      </geometry>
    </collision>
  </link>
  <gazebo reference="thbase">
    <sensor name="thbase_contact" type="contact">
      <always_on>1</always_on>
      <update_rate>1000.0</update_rate>
      <contact>
        <collision>thbase_collision</collision>
        <topic>thbase_collision</topic>
      </contact>
      <plugin filename="libgazebo_ros_bumper.so" name="thbase_gazebo_ros_bumper_controller">
        <updateRate>100.0</updateRate>
        <frameName>thbase</frameName>
        <bumperTopicName>contacts/th/base</bumperTopicName>
      </plugin>
    </sensor>
    <material>LightGrey</material>
  </gazebo>
  <joint name="THJ5" type="revolute">
    <parent link="palm"/>
    <child link="thbase"/>
    <origin rpy="0 0.785398163397 0" xyz="0.034 -0.0085 0.029"/>
    <axis xyz="0 0 -1.0"/>
    <limit effort="1000.0" lower="-1.047" upper="1.047" velocity="10.0"/>
    <dynamics damping="10.0"/>
  </joint>
  <gazebo reference="THJ5">
    <provideFeedback>1</provideFeedback>
    <implicitSpringDamper>1</implicitSpringDamper>
  </gazebo>
  <transmission name="thbase_transmission" type="sr_mechanism_model/SimpleTransmission">
    <actuator name="THJ5"/>
    <joint name="THJ5"/>
    <mechanicalReduction>1</mechanicalReduction>
    <motorTorqueConstant>1</motorTorqueConstant>
    <pulsesPerRevolution>90000</pulsesPerRevolution>
  </transmission>
  <link name="thproximal">
    <inertial>
      <mass value="0.016"/>
      <origin rpy="0 0 0" xyz="0 0 0.019"/>
      <inertia ixx="1e-6" ixy="0.0" ixz="0.0" iyy="1e-6" iyz="0.0" izz="1e-6"/>
    </inertial>
    <visual>
      <origin rpy="0 0 0" xyz="0 0 0"/>
      <geometry name="thproximal_visual">
        <mesh filename="package://sr_description/hand/model/TH3_z.dae" scale="0.001 0.001 0.001"/>
      </geometry>
      <material name="shadow_thproximal_material">
        <color rgba="0.2 0.2 0.2 1.0"/>
      </material>
    </visual>
    <collision>
      <origin rpy="0 0 0" xyz="0 0 0.019"/>
      <geometry name="thproximal_collision_geom">
        <box size="0.008 0.008 0.020"/>
      </geometry>
    </collision>
  </link>
  <gazebo reference="thproximal">
    <sensor name="thproximal_contact" type="contact">
      <always_on>1</always_on>
      <update_rate>1000.0</update_rate>
      <contact>
        <collision>thproximal_collision</collision>
        <topic>thproximal_collision</topic>
      </contact>
      <plugin filename="libgazebo_ros_bumper.so" name="thproximal_gazebo_ros_bumper_controller">
        <updateRate>100.0</updateRate>
        <frameName>thproximal</frameName>
        <bumperTopicName>contacts/th/proximal</bumperTopicName>
      </plugin>
    </sensor>
    <material>LightGrey</material>
  </gazebo>
  <joint name="THJ4" type="revolute">
    <parent link="thbase"/>
    <child link="thproximal"/>
    <origin rpy="0 0 0" xyz="0 0 0"/>
    <axis xyz="1.0 0 0"/>
    <limit effort="1000.0" lower="0" upper="1.309" velocity="10.0"/>
    <dynamics damping="10.0"/>
  </joint>
  <gazebo reference="THJ4">
    <provideFeedback>1</provideFeedback>
    <implicitSpringDamper>1</implicitSpringDamper>
  </gazebo>
  <transmission name="thproximal_transmission" type="sr_mechanism_model/SimpleTransmission">
    <actuator name="THJ4"/>
    <joint name="THJ4"/>
    <mechanicalReduction>1</mechanicalReduction>
    <motorTorqueConstant>1</motorTorqueConstant>
    <pulsesPerRevolution>90000</pulsesPerRevolution>
  </transmission>
  <link name="thhub">
    <inertial>
      <mass value="0.002"/>
      <origin rpy="0 0 0" xyz="0 0 0"/>
      <inertia ixx="1e-6" ixy="0.0" ixz="0.0" iyy="1e-6" iyz="0.0" izz="1e-6"/>
    </inertial>
    <visual>
      <origin rpy="0 0 0" xyz="0 0 0"/>
      <geometry name="thhub_visual">
        <box size="0.001 0.001 0.001"/>
      </geometry>
      <material name="shadow_thhub_material">
        <color rgba="0.7 0.7 0.7 1.0"/>
      </material>
    </visual>
    <collision>
      <origin rpy="0 0 0 " xyz="0 0 0"/>
      <geometry name="thhub_collision_geom">
        <box size="0.001 0.001 0.001"/>
      </geometry>
    </collision>
  </link>
  <gazebo reference="thhub">
    <sensor name="thhub_contact" type="contact">
      <always_on>1</always_on>
      <update_rate>1000.0</update_rate>
      <contact>
        <collision>thhub_collision</collision>
        <topic>thhub_collision</topic>
      </contact>
      <plugin filename="libgazebo_ros_bumper.so" name="thhub_gazebo_ros_bumper_controller">
        <updateRate>100.0</updateRate>
        <frameName>thhub</frameName>
        <bumperTopicName>contacts/th/hub</bumperTopicName>
      </plugin>
    </sensor>
    <material>LightGrey</material>
  </gazebo>
  <joint name="THJ3" type="revolute">
    <parent link="thproximal"/>
    <child link="thhub"/>
    <origin rpy="0 0 0" xyz="0 0 0.038"/>
    <axis xyz="1 0 0"/>
    <limit effort="1000.0" lower="-0.2618" upper="0.2618" velocity="10.0"/>
    <dynamics damping="10.0"/>
  </joint>
  <gazebo reference="THJ3">
    <provideFeedback>1</provideFeedback>
    <implicitSpringDamper>1</implicitSpringDamper>
  </gazebo>
  <transmission name="thhub_transmission" type="sr_mechanism_model/SimpleTransmission">
    <actuator name="THJ3"/>
    <joint name="THJ3"/>
    <mechanicalReduction>1</mechanicalReduction>
    <motorTorqueConstant>1</motorTorqueConstant>
    <pulsesPerRevolution>90000</pulsesPerRevolution>
  </transmission>
  <link name="thmiddle">
    <inertial>
      <mass value="0.016"/>
      <origin rpy="0 0 0" xyz="0 0 0.016"/>
      <inertia ixx="1e-6" ixy="0.0" ixz="0.0" iyy="1e-6" iyz="0.0" izz="1e-6"/>
    </inertial>
    <visual>
      <origin rpy="0 0 0" xyz="0 0 0"/>
      <geometry name="thmiddle_visual">
        <mesh filename="package://sr_description/hand/model/TH2_z.dae" scale="0.001 0.001 0.001"/>
      </geometry>
      <material name="shadow_thmiddle_material">
        <color rgba="0.2 0.2 0.2 1.0"/>
      </material>
    </visual>
    <collision>
      <origin rpy="0 0 0 " xyz="0 0 0.016"/>
      <geometry name="thmiddle_collision_geom">
        <box size="0.008 0.008 0.015"/>
      </geometry>
    </collision>
  </link>
  <gazebo reference="thmiddle">
    <sensor name="thmiddle_contact" type="contact">
      <always_on>1</always_on>
      <update_rate>1000.0</update_rate>
      <contact>
        <collision>thmiddle_collision</collision>
        <topic>thmiddle_collision</topic>
      </contact>
      <plugin filename="libgazebo_ros_bumper.so" name="thmiddle_gazebo_ros_bumper_controller">
        <updateRate>100.0</updateRate>
        <frameName>thmiddle</frameName>
        <bumperTopicName>contacts/th/middle</bumperTopicName>
      </plugin>
    </sensor>
    <material>LightGrey</material>
  </gazebo>
  <joint name="THJ2" type="revolute">
    <parent link="thhub"/>
    <child link="thmiddle"/>
    <origin rpy="0 0 0" xyz="0 0 0"/>
    <axis xyz="0 -1 0"/>
    <limit effort="1000.0" lower="-0.6981" upper="0.6981" velocity="10.0"/>
    <dynamics damping="10.0"/>
  </joint>
  <gazebo reference="THJ2">
    <provideFeedback>1</provideFeedback>
    <implicitSpringDamper>1</implicitSpringDamper>
  </gazebo>
  <!-- test soft collision -->
  <gazebo reference="palm">
    <soft_contact>
      <dart>
        <flesh_mass_fraction>0.5</flesh_mass_fraction>
        <bone_attachment>500.0</bone_attachment>
        <stiffness>0.0</stiffness>
        <damping>5.0</damping>
      </dart>
    </soft_contact>
  </gazebo>
  <transmission name="thmiddle_transmission" type="sr_mechanism_model/SimpleTransmission">
    <actuator name="THJ2"/>
    <joint name="THJ2"/>
    <mechanicalReduction>1</mechanicalReduction>
    <motorTorqueConstant>1</motorTorqueConstant>
    <pulsesPerRevolution>90000</pulsesPerRevolution>
  </transmission>
  <link name="thdistal">
    <inertial>
      <mass value="0.016"/>
      <origin rpy="0 0 0" xyz="0 0 0.01375"/>
      <inertia ixx="1e-6" ixy="0.0" ixz="0.0" iyy="1e-6" iyz="0.0" izz="1e-6"/>
    </inertial>
    <visual>
      <origin rpy="0 0 0" xyz="0 0 0"/>
      <geometry name="thdistal_visual">
        <mesh filename="package://sr_description/hand/model/TH1_z.dae" scale="0.001 0.001 0.001"/>
      </geometry>
      <material name="shadow_thmiddle_material">
        <color rgba="0.2 0.2 0.2 1.0"/>
      </material>
    </visual>
    <collision>
      <origin rpy="0 0 0 " xyz="0 0 0"/>
      <geometry name="thmiddle_collision_geom">
        <mesh filename="package://sr_description/hand/model/TH1_z.dae" scale="0.001 0.001 0.001"/>
        <!--	  <box size="0.015 0.015 0.015" /> -->
      </geometry>
    </collision>
  </link>
  <gazebo reference="thdistal">
    <sensor name="thdistal_contact" type="contact">
      <always_on>1</always_on>
      <update_rate>1000.0</update_rate>
      <contact>
        <collision>thdistal_collision</collision>
        <topic>thdistal_collision</topic>
      </contact>
      <plugin filename="libgazebo_ros_bumper.so" name="thdistal_gazebo_ros_bumper_controller">
        <updateRate>100.0</updateRate>
        <frameName>thdistal</frameName>
        <bumperTopicName>contacts/th/distal</bumperTopicName>
      </plugin>
    </sensor>
    <material>LightGrey</material>
    <selfCollide>true</selfCollide>
  </gazebo>
  <joint name="THJ1" type="revolute">
    <parent link="thmiddle"/>
    <child link="thdistal"/>
    <origin rpy="0 0 -1.570796327" xyz="0 0 0.032"/>
    <axis xyz="1 0 0"/>
    <limit effort="1000.0" lower="0" upper="1.571" velocity="10.0"/>
    <dynamics damping="10.0"/>
  </joint>
  <gazebo reference="THJ1">
    <provideFeedback>1</provideFeedback>
    <implicitSpringDamper>1</implicitSpringDamper>
  </gazebo>
  <link name="thtip">
    <inertial>
      <mass value="0.001"/>
      <inertia ixx="0.00001" ixy="0.0" ixz="0.0" iyy="0.00001" iyz="0.0" izz="0.00001"/>
    </inertial>
  </link>
  <joint name="thtip" type="fixed">
    <parent link="thdistal"/>
    <child link="thtip"/>
    <origin rpy="0 0 0" xyz="0 0 0.0275"/>
  </joint>
  <transmission name="thdistal_transmission" type="sr_mechanism_model/SimpleTransmission">
    <actuator name="THJ1"/>
    <joint name="THJ1"/>
    <mechanicalReduction>1</mechanicalReduction>
    <motorTorqueConstant>1</motorTorqueConstant>
    <pulsesPerRevolution>90000</pulsesPerRevolution>
  </transmission>
</robot>

