<?xml version="1.0" ?>
<!-- =================================================================================== -->
<!-- |    This document was autogenerated by xacro from /home/hugo/catkin_birdseye/src/euroc_simulator/rotors_description/urdf/iris_base.xacro | -->
<!-- |    EDITING THIS FILE BY HAND IS NOT RECOMMENDED                                 | -->
<!-- =================================================================================== -->
<robot name="iris" xmlns:xacro="http://ros.org/wiki/xacro">
  <!-- Macro to add logging to a bag file. -->
  <!-- Macro to add a camera. -->
  <!-- Macro to add the controller interface. -->
  <!-- Macro to add an IMU. -->
  <!-- Macro to add a generic odometry sensor. -->
  <!-- Macro to add the wind plugin. -->
  <!-- VI sensor macros -->
  <!-- Macro to add a VI-sensor camera. -->
  <!-- Macro to add a depth camera on the VI-sensor. -->
  <!-- VI-Sensor Macro -->
  <!-- Instantiate iris "mechanics" -->
  <!-- Properties -->
  <!-- [kg] -->
  <!-- [m] -->
  <!-- [m] -->
  <!-- [kg] -->
  <!-- [m] -->
  <!-- [m] -->
  <!-- [m] -->
  <!-- [m] -->
  <!-- [m] -->
  <!-- [m] -->
  <!-- [kg·m/s^2] -->
  <!-- [m] -->
  <!-- [s] -->
  <!-- [s] -->
  <!-- [rad/s] -->
  <!-- Property Blocks -->
  <!-- inertia of a single rotor, assuming it is a cuboid. Height=3mm, width=15mm -->
  <!-- Included URDF Files -->
  <!-- Main multirotor link -->
  <!-- Rotor joint and link -->
  <!-- Instantiate multirotor_base_macro once -->
  <link name="base_link"/>
  <joint name="base_joint" type="fixed">
    <origin rpy="0 0 0" xyz="0 0 0"/>
    <parent link="base_link"/>
    <child link="base_link_inertia"/>
  </joint>
  <link name="base_link_inertia">
    <inertial>
      <mass value="1.5"/>
      <!-- [kg] -->
      <origin xyz="0 0 0"/>
      <inertia ixx="0.0347563" ixy="0.0" ixz="0.0" iyy="0.0458929" iyz="0.0" izz="0.0977"/>
    </inertial>
    <visual>
      <origin rpy="0 0 0" xyz="0 0 0"/>
      <geometry>
        <mesh filename="package://rotors_description/meshes/iris.dae" scale="1 1 1"/>
        <!-- <box size="${body_width} ${body_width} ${body_height}"/> -->
        <!-- [m] [m] [m] -->
      </geometry>
    </visual>
    <collision>
      <origin rpy="0 0 0" xyz="0 0 0"/>
      <geometry>
        <box size="0.47 0.47 0.11"/>
        <!-- [m] [m] [m] -->
      </geometry>
    </collision>
  </link>
  <!-- attach multirotor_base_plugin to the base_link -->
  <gazebo>
    <plugin filename="librotors_gazebo_multirotor_base_plugin.so" name="rosbag">
      <robotNamespace>iris</robotNamespace>
      <linkName>base_link</linkName>
      <rotorVelocitySlowdownSim>10</rotorVelocitySlowdownSim>
    </plugin>
  </gazebo>
  <gazebo reference="base_link">
    <material>Gazebo/DarkGrey</material>
  </gazebo>
  <!-- Instantiate rotors -->
  <joint name="rotor_0_joint" type="continuous">
    <origin rpy="0 0 0" xyz="0.13 -0.22 0.023"/>
    <axis xyz="0 0 1"/>
    <!-- TODO(ff): not currently set because it's not yet supported -->
    <!-- <limit effort="2000" velocity="${max_rot_velocity}" /> -->
    <parent link="base_link"/>
    <child link="rotor_0"/>
  </joint>
  <!-- TODO(ff): not currently set because it's not yet supported -->
  <!-- <gazebo reference="rotor_${motor_number}_joint"> <axis> <xyz>0 0 1</xyz>
      <limit> <velocity> ${max_rot_velocity} </velocity> </limit> </axis> </gazebo> -->
  <link name="rotor_0">
    <inertial>
      <mass value="0.005"/>
      <!-- [kg] -->
      <inertia ixx="9.75e-07" ixy="0.0" ixz="0.0" iyy="0.000166704166667" iyz="0.0" izz="0.000167604166667"/>
    </inertial>
    <visual>
      <geometry>
        <!-- <cylinder length="0.005" radius="${radius_rotor}"/> -->
        <!-- [m] -->
        <!-- <mesh filename="package://rotors_description/meshes/propeller_${direction}.dae" -->
        <mesh filename="package://rotors_description/meshes/iris_prop_ccw.dae" scale="1 1 1"/>
        <!-- <box size="${2*radius_rotor} 0.01 0.005"/> -->
      </geometry>
    </visual>
    <collision>
      <geometry>
        <cylinder length="0.005" radius="0.1"/>
        <!-- [m] -->
      </geometry>
    </collision>
  </link>
  <gazebo>
    <plugin filename="librotors_gazebo_motor_model.so" name="front_right_motor_model">
      <robotNamespace>iris</robotNamespace>
      <jointName>rotor_0_joint</jointName>
      <linkName>rotor_0</linkName>
      <turningDirection>ccw</turningDirection>
      <timeConstantUp>0.0125</timeConstantUp>
      <timeConstantDown>0.025</timeConstantDown>
      <maxRotVelocity>838</maxRotVelocity>
      <motorConstant>8.54858e-06</motorConstant>
      <momentConstant>0.016</momentConstant>
      <commandSubTopic>gazebo/command/motor_speed</commandSubTopic>
      <motorNumber>0</motorNumber>
      <rotorDragCoefficient>8.06428e-05</rotorDragCoefficient>
      <rollingMomentCoefficient>1e-06</rollingMomentCoefficient>
      <motorSpeedPubTopic>motor_speed/0</motorSpeedPubTopic>
      <rotorVelocitySlowdownSim>10</rotorVelocitySlowdownSim>
    </plugin>
  </gazebo>
  <gazebo reference="rotor_0">
    <material>Gazebo/Blue</material>
  </gazebo>
  <joint name="rotor_1_joint" type="continuous">
    <origin rpy="0 0 0" xyz="-0.13 0.2 0.023"/>
    <axis xyz="0 0 1"/>
    <!-- TODO(ff): not currently set because it's not yet supported -->
    <!-- <limit effort="2000" velocity="${max_rot_velocity}" /> -->
    <parent link="base_link"/>
    <child link="rotor_1"/>
  </joint>
  <!-- TODO(ff): not currently set because it's not yet supported -->
  <!-- <gazebo reference="rotor_${motor_number}_joint"> <axis> <xyz>0 0 1</xyz>
      <limit> <velocity> ${max_rot_velocity} </velocity> </limit> </axis> </gazebo> -->
  <link name="rotor_1">
    <inertial>
      <mass value="0.005"/>
      <!-- [kg] -->
      <inertia ixx="9.75e-07" ixy="0.0" ixz="0.0" iyy="0.000166704166667" iyz="0.0" izz="0.000167604166667"/>
    </inertial>
    <visual>
      <geometry>
        <!-- <cylinder length="0.005" radius="${radius_rotor}"/> -->
        <!-- [m] -->
        <!-- <mesh filename="package://rotors_description/meshes/propeller_${direction}.dae" -->
        <mesh filename="package://rotors_description/meshes/iris_prop_ccw.dae" scale="1 1 1"/>
        <!-- <box size="${2*radius_rotor} 0.01 0.005"/> -->
      </geometry>
    </visual>
    <collision>
      <geometry>
        <cylinder length="0.005" radius="0.1"/>
        <!-- [m] -->
      </geometry>
    </collision>
  </link>
  <gazebo>
    <plugin filename="librotors_gazebo_motor_model.so" name="back_left_motor_model">
      <robotNamespace>iris</robotNamespace>
      <jointName>rotor_1_joint</jointName>
      <linkName>rotor_1</linkName>
      <turningDirection>ccw</turningDirection>
      <timeConstantUp>0.0125</timeConstantUp>
      <timeConstantDown>0.025</timeConstantDown>
      <maxRotVelocity>838</maxRotVelocity>
      <motorConstant>8.54858e-06</motorConstant>
      <momentConstant>0.016</momentConstant>
      <commandSubTopic>gazebo/command/motor_speed</commandSubTopic>
      <motorNumber>1</motorNumber>
      <rotorDragCoefficient>8.06428e-05</rotorDragCoefficient>
      <rollingMomentCoefficient>1e-06</rollingMomentCoefficient>
      <motorSpeedPubTopic>motor_speed/1</motorSpeedPubTopic>
      <rotorVelocitySlowdownSim>10</rotorVelocitySlowdownSim>
    </plugin>
  </gazebo>
  <gazebo reference="rotor_1">
    <material>Gazebo/DarkGrey</material>
  </gazebo>
  <joint name="rotor_2_joint" type="continuous">
    <origin rpy="0 0 0" xyz="0.13 0.22 0.023"/>
    <axis xyz="0 0 1"/>
    <!-- TODO(ff): not currently set because it's not yet supported -->
    <!-- <limit effort="2000" velocity="${max_rot_velocity}" /> -->
    <parent link="base_link"/>
    <child link="rotor_2"/>
  </joint>
  <!-- TODO(ff): not currently set because it's not yet supported -->
  <!-- <gazebo reference="rotor_${motor_number}_joint"> <axis> <xyz>0 0 1</xyz>
      <limit> <velocity> ${max_rot_velocity} </velocity> </limit> </axis> </gazebo> -->
  <link name="rotor_2">
    <inertial>
      <mass value="0.005"/>
      <!-- [kg] -->
      <inertia ixx="9.75e-07" ixy="0.0" ixz="0.0" iyy="0.000166704166667" iyz="0.0" izz="0.000167604166667"/>
    </inertial>
    <visual>
      <geometry>
        <!-- <cylinder length="0.005" radius="${radius_rotor}"/> -->
        <!-- [m] -->
        <!-- <mesh filename="package://rotors_description/meshes/propeller_${direction}.dae" -->
        <mesh filename="package://rotors_description/meshes/iris_prop_cw.dae" scale="1 1 1"/>
        <!-- <box size="${2*radius_rotor} 0.01 0.005"/> -->
      </geometry>
    </visual>
    <collision>
      <geometry>
        <cylinder length="0.005" radius="0.1"/>
        <!-- [m] -->
      </geometry>
    </collision>
  </link>
  <gazebo>
    <plugin filename="librotors_gazebo_motor_model.so" name="front_left_motor_model">
      <robotNamespace>iris</robotNamespace>
      <jointName>rotor_2_joint</jointName>
      <linkName>rotor_2</linkName>
      <turningDirection>cw</turningDirection>
      <timeConstantUp>0.0125</timeConstantUp>
      <timeConstantDown>0.025</timeConstantDown>
      <maxRotVelocity>838</maxRotVelocity>
      <motorConstant>8.54858e-06</motorConstant>
      <momentConstant>0.016</momentConstant>
      <commandSubTopic>gazebo/command/motor_speed</commandSubTopic>
      <motorNumber>2</motorNumber>
      <rotorDragCoefficient>8.06428e-05</rotorDragCoefficient>
      <rollingMomentCoefficient>1e-06</rollingMomentCoefficient>
      <motorSpeedPubTopic>motor_speed/2</motorSpeedPubTopic>
      <rotorVelocitySlowdownSim>10</rotorVelocitySlowdownSim>
    </plugin>
  </gazebo>
  <gazebo reference="rotor_2">
    <material>Gazebo/Blue</material>
  </gazebo>
  <joint name="rotor_3_joint" type="continuous">
    <origin rpy="0 0 0" xyz="-0.13 -0.2 0.023"/>
    <axis xyz="0 0 1"/>
    <!-- TODO(ff): not currently set because it's not yet supported -->
    <!-- <limit effort="2000" velocity="${max_rot_velocity}" /> -->
    <parent link="base_link"/>
    <child link="rotor_3"/>
  </joint>
  <!-- TODO(ff): not currently set because it's not yet supported -->
  <!-- <gazebo reference="rotor_${motor_number}_joint"> <axis> <xyz>0 0 1</xyz>
      <limit> <velocity> ${max_rot_velocity} </velocity> </limit> </axis> </gazebo> -->
  <link name="rotor_3">
    <inertial>
      <mass value="0.005"/>
      <!-- [kg] -->
      <inertia ixx="9.75e-07" ixy="0.0" ixz="0.0" iyy="0.000166704166667" iyz="0.0" izz="0.000167604166667"/>
    </inertial>
    <visual>
      <geometry>
        <!-- <cylinder length="0.005" radius="${radius_rotor}"/> -->
        <!-- [m] -->
        <!-- <mesh filename="package://rotors_description/meshes/propeller_${direction}.dae" -->
        <mesh filename="package://rotors_description/meshes/iris_prop_cw.dae" scale="1 1 1"/>
        <!-- <box size="${2*radius_rotor} 0.01 0.005"/> -->
      </geometry>
    </visual>
    <collision>
      <geometry>
        <cylinder length="0.005" radius="0.1"/>
        <!-- [m] -->
      </geometry>
    </collision>
  </link>
  <gazebo>
    <plugin filename="librotors_gazebo_motor_model.so" name="back_right_motor_model">
      <robotNamespace>iris</robotNamespace>
      <jointName>rotor_3_joint</jointName>
      <linkName>rotor_3</linkName>
      <turningDirection>cw</turningDirection>
      <timeConstantUp>0.0125</timeConstantUp>
      <timeConstantDown>0.025</timeConstantDown>
      <maxRotVelocity>838</maxRotVelocity>
      <motorConstant>8.54858e-06</motorConstant>
      <momentConstant>0.016</momentConstant>
      <commandSubTopic>gazebo/command/motor_speed</commandSubTopic>
      <motorNumber>3</motorNumber>
      <rotorDragCoefficient>8.06428e-05</rotorDragCoefficient>
      <rollingMomentCoefficient>1e-06</rollingMomentCoefficient>
      <motorSpeedPubTopic>motor_speed/3</motorSpeedPubTopic>
      <rotorVelocitySlowdownSim>10</rotorVelocitySlowdownSim>
    </plugin>
  </gazebo>
  <gazebo reference="rotor_3">
    <material>Gazebo/DarkGrey</material>
  </gazebo>
  <!-- Instantiate a controller. -->
  <gazebo>
    <plugin filename="librotors_gazebo_controller_interface.so" name="controller_interface">
      <robotNamespace>iris</robotNamespace>
      <commandAttitudeThrustSubTopic>command/attitude</commandAttitudeThrustSubTopic>
      <commandRateThrustSubTopic>command/rate</commandRateThrustSubTopic>
      <commandMotorSpeedSubTopic>command/motor_speed</commandMotorSpeedSubTopic>
      <imuSubTopic>imu</imuSubTopic>
      <motorSpeedCommandPubTopic>gazebo/command/motor_speed</motorSpeedCommandPubTopic>
    </plugin>
  </gazebo>
  <!-- Mount an ADIS16448 IMU. -->
  <!-- IMU link -->
  <link name="iris/imu_link">
    <inertial>
      <inertia ixx="0.00001" ixy="0.0" ixz="0.0" iyy="0.00001" iyz="0.0" izz="0.00001"/>
      <mass value="0.015"/>
      <!-- [kg] -->
      <origin rpy="0 0 0" xyz="0 0 0"/>
    </inertial>
  </link>
  <!-- IMU joint -->
  <joint name="iris/imu_joint" type="revolute">
    <origin rpy="0 0 0" xyz="0 0 0"/>
    <parent link="base_link"/>
    <child link="iris/imu_link"/>
    <limit effort="0" lower="0" upper="0" velocity="0"/>
  </joint>
  <gazebo>
    <plugin filename="librotors_gazebo_imu_plugin.so" name="rotors_gazebo_imu_plugin">
      <!-- A good description of the IMU parameters can be found in the kalibr documentation:
           https://github.com/ethz-asl/kalibr/wiki/IMU-Noise-Model-and-Intrinsics -->
      <robotNamespace>iris</robotNamespace>
      <!-- (string, required): ros namespace in which the messages are published -->
      <linkName>iris/imu_link</linkName>
      <!-- (string, required): name of the body which holds the IMU sensor -->
      <imuTopic>imu</imuTopic>
      <!-- (string): name of the sensor output topic and prefix of service names (defaults to imu) -->
      <gyroscopeNoiseDensity>0.0003394</gyroscopeNoiseDensity>
      <!-- Gyroscope noise density (two-sided spectrum) [rad/s/sqrt(Hz)] -->
      <gyroscopeRandomWalk>3.8785e-05</gyroscopeRandomWalk>
      <!-- Gyroscope bias random walk [rad/s/s/sqrt(Hz)] -->
      <gyroscopeBiasCorrelationTime>1000.0</gyroscopeBiasCorrelationTime>
      <!-- Gyroscope bias correlation time constant [s] -->
      <gyroscopeTurnOnBiasSigma>0.0087</gyroscopeTurnOnBiasSigma>
      <!-- Gyroscope turn on bias standard deviation [rad/s] -->
      <accelerometerNoiseDensity>0.004</accelerometerNoiseDensity>
      <!-- Accelerometer noise density (two-sided spectrum) [m/s^2/sqrt(Hz)] -->
      <accelerometerRandomWalk>0.006</accelerometerRandomWalk>
      <!-- Accelerometer bias random walk. [m/s^2/s/sqrt(Hz)] -->
      <accelerometerBiasCorrelationTime>300.0</accelerometerBiasCorrelationTime>
      <!-- Accelerometer bias correlation time constant [s] -->
      <accelerometerTurnOnBiasSigma>0.196</accelerometerTurnOnBiasSigma>
      <!-- Accelerometer turn on bias standard deviation [m/s^2] -->
    </plugin>
  </gazebo>
  <!-- IMU link -->
  <link name="iris/imugt_link">
    <inertial>
      <inertia ixx="0.00001" ixy="0.0" ixz="0.0" iyy="0.00001" iyz="0.0" izz="0.00001"/>
      <mass value="1e-05"/>
      <!-- [kg] -->
      <origin rpy="0 0 0" xyz="0 0 0"/>
    </inertial>
  </link>
  <!-- IMU joint -->
  <joint name="iris/imugt_joint" type="revolute">
    <origin rpy="0 0 0" xyz="0 0 0"/>
    <parent link="base_link"/>
    <child link="iris/imugt_link"/>
    <limit effort="0" lower="0" upper="0" velocity="0"/>
  </joint>
  <gazebo>
    <plugin filename="librotors_gazebo_imu_plugin.so" name="rotors_gazebo_imugt_plugin">
      <!-- A good description of the IMU parameters can be found in the kalibr documentation:
           https://github.com/ethz-asl/kalibr/wiki/IMU-Noise-Model-and-Intrinsics -->
      <robotNamespace>iris</robotNamespace>
      <!-- (string, required): ros namespace in which the messages are published -->
      <linkName>iris/imugt_link</linkName>
      <!-- (string, required): name of the body which holds the IMU sensor -->
      <imuTopic>ground_truth/imu</imuTopic>
      <!-- (string): name of the sensor output topic and prefix of service names (defaults to imu) -->
      <gyroscopeNoiseDensity>0.0</gyroscopeNoiseDensity>
      <!-- Gyroscope noise density (two-sided spectrum) [rad/s/sqrt(Hz)] -->
      <gyroscopeRandomWalk>0.0</gyroscopeRandomWalk>
      <!-- Gyroscope bias random walk [rad/s/s/sqrt(Hz)] -->
      <gyroscopeBiasCorrelationTime>1000.0</gyroscopeBiasCorrelationTime>
      <!-- Gyroscope bias correlation time constant [s] -->
      <gyroscopeTurnOnBiasSigma>0.0</gyroscopeTurnOnBiasSigma>
      <!-- Gyroscope turn on bias standard deviation [rad/s] -->
      <accelerometerNoiseDensity>0.0</accelerometerNoiseDensity>
      <!-- Accelerometer noise density (two-sided spectrum) [m/s^2/sqrt(Hz)] -->
      <accelerometerRandomWalk>0.0</accelerometerRandomWalk>
      <!-- Accelerometer bias random walk. [m/s^2/s/sqrt(Hz)] -->
      <accelerometerBiasCorrelationTime>300.0</accelerometerBiasCorrelationTime>
      <!-- Accelerometer bias correlation time constant [s] -->
      <accelerometerTurnOnBiasSigma>0.0</accelerometerTurnOnBiasSigma>
      <!-- Accelerometer turn on bias standard deviation [m/s^2] -->
    </plugin>
  </gazebo>
  <!-- Mount a generic odometry sensor providing ground truth. -->
  <!-- odometry link -->
  <link name="iris/ground_truth/odometry_sensorgt_link">
    <inertial>
      <inertia ixx="0.00001" ixy="0.0" ixz="0.0" iyy="0.00001" iyz="0.0" izz="0.00001"/>
      <mass value="1e-05"/>
      <!-- [kg] -->
    </inertial>
  </link>
  <!-- odometry joint -->
  <joint name="iris/ground_truth/odometry_sensorgt_joint" type="revolute">
    <parent link="base_link"/>
    <origin rpy="0.0 0.0 0.0" xyz="0.0 0.0 0.0"/>
    <child link="iris/ground_truth/odometry_sensorgt_link"/>
    <limit effort="0" lower="0" upper="0" velocity="0"/>
  </joint>
  <gazebo>
    <plugin filename="librotors_gazebo_odometry_plugin.so" name="odometry_sensorgt">
      <linkName>iris/ground_truth/odometry_sensorgt_link</linkName>
      <robotNamespace>iris/ground_truth</robotNamespace>
      <poseTopic>pose</poseTopic>
      <poseWithCovarianceTopic>pose_with_covariance</poseWithCovarianceTopic>
      <positionTopic>position</positionTopic>
      <transformTopic>transform</transformTopic>
      <odometryTopic>odometry</odometryTopic>
      <parentFrameId>world</parentFrameId>
      <!-- Use the scoped link name here. e.g. Model::link. -->
      <measurementDivisor>1</measurementDivisor>
      <!-- only every (seq % measurementDivisor) == 0 measurement is published [int] -->
      <measurementDelay>0</measurementDelay>
      <!-- time that measurement gets held back before it's published in [simulation cycles (int)] -->
      <unknownDelay>0.0</unknownDelay>
      <!-- additional delay, that just gets added to the timestamp [s] -->
      <noiseNormalPosition>0 0 0</noiseNormalPosition>
      <!-- standard deviation of additive white gaussian noise [m] -->
      <noiseNormalQuaternion>0 0 0</noiseNormalQuaternion>
      <!-- standard deviation white gaussian noise [rad]: q_m = q*quaternionFromSmallAngleApproximation(noiseNormalQ) -->
      <noiseNormalLinearVelocity>0 0 0</noiseNormalLinearVelocity>
      <!-- standard deviation of additive white gaussian noise [m/s] -->
      <noiseNormalAngularVelocity>0 0 0</noiseNormalAngularVelocity>
      <!-- standard deviation of additive white gaussian noise [rad/s] -->
      <noiseUniformPosition>0 0 0</noiseUniformPosition>
      <!-- symmetric bounds of uniform noise [m] -->
      <noiseUniformQuaternion>0 0 0</noiseUniformQuaternion>
      <!-- symmetric bounds of uniform noise [rad], computation see above -->
      <noiseUniformLinearVelocity>0 0 0</noiseUniformLinearVelocity>
      <!-- symmetric bounds of uniform noise [m/s] -->
      <noiseUniformAngularVelocity>0 0 0</noiseUniformAngularVelocity>
      <!-- symmetric bounds of uniform noise [rad/s] -->
    </plugin>
  </gazebo>
</robot>

