<robot xmlns:xacro="http://ros.org/wiki/xacro"
        xmlns:sensor="http://playerstage.sourceforge.net/gazebo/xmlschema/#sensor"
       xmlns:controller="http://playerstage.sourceforge.net/gazebo/xmlschema/#controller"
       xmlns:joint="http://playerstage.sourceforge.net/gazebo/xmlschema/#slider"
       xmlns:interface="http://playerstage.sourceforge.net/gazebo/xmlschema/#interface"
       xmlns:body="http://playerstage.sourceforge.net/gazebo/xmlschema/#body"
       xmlns:geom="http://playerstage.sourceforge.net/gazebo/xmlschema/#geom">

  <xacro:include filename="$(find sr_description)/hand/xacro/finger/knuckle/edc_muscle_knuckle.transmission.xacro" />

  <xacro:macro name="knuckle" params="link_prefix joint_prefix parent *origin">

    <link name="${link_prefix}knuckle">
      <inertial>
	<origin xyz="0 0 0" rpy="0 0 0" />
	<!--<insert_block name="origin" /> -->
	<mass value="0.008" />
	<inertia  ixx="0.000001" ixy="0.0"  ixz="0.0"  iyy="0.000001"  iyz="0.0"
	izz="0.000001" />
      </inertial>
      <visual>
	<origin xyz="0 0 0.0005" rpy="0 0 0" />
	<geometry name="${link_prefix}knuckle_visual">
      <mesh filename="package://sr_description/hand/model/knuckle.dae" scale="0.001 0.001 0.001" />
      </geometry>
      <material name="LightGrey" />
      </visual>
      <collision>
	<origin xyz="0 0 0" rpy="0 0 0" />
	<geometry name="${link_prefix}knuckle_collision_geom">
	  <box size="0.005 0.005 0.005" />
	</geometry>
      </collision>
    </link>

    <gazebo reference="${link_prefix}knuckle">
      <sensor type="contact" name="${link_prefix}knuckle_contact" >
        <always_on>1</always_on>
        <update_rate>1000.0</update_rate>
        <contact>
          <collision>${link_prefix}knuckle_collision</collision>
          <topic>${link_prefix}knuckle_collision</topic>
        </contact>
        <plugin name="${link_prefix}knuckle_gazebo_ros_bumper_controller" filename="libgazebo_ros_bumper.so">
          <updateRate>100.0</updateRate>
	  <frameName>${link_prefix}knuckle</frameName>
	  <bumperTopicName>contacts/${link_prefix}/knuckle</bumperTopicName>
        </plugin>
      </sensor>
      <material>Gazebo/Grey</material>
    </gazebo>

    <joint name="${joint_prefix}J4" type="revolute">
      <parent link="${parent}"/>
      <child link="${link_prefix}knuckle"/>
      <!--<origin xyz="0.033 0 0.095" rpy="0 0 0" />-->
      <insert_block name="origin" />
      <insert_block name="axis"/>
      <limit lower="-0.43633231299858238" upper="0.43633231299858238"
      effort="1000.0" velocity="10.0"/>
      <dynamics damping="10.0"/>
    </joint>
    <gazebo reference="${joint_prefix}J4">
    <provideFeedback>1</provideFeedback>
    <implicitSpringDamper>1</implicitSpringDamper>
    </gazebo>

    <xacro:knuckle_transmission />

  </xacro:macro>

</robot>
