<robot xmlns:xacro="http://www.ros.org/wiki/xacro">

  <xacro:include filename="$(find sr_description)/arm/xacro/upper_arm/shadowarm_upperarm.transmission.xacro" />

  <xacro:macro name="shadowarm_upperarm" params="parent">
    <link name="shadowarm_upperarm">
      <inertial>
        <origin xyz="0 0 0.0" rpy="0 0 0" />
        <mass value="0.5" />
        <inertia  ixx="0.0001" ixy="0.0"  ixz="0.0"  iyy="0.0001"  iyz="0.0" izz="0.0001" />
      </inertial>
      <visual>
	<origin xyz="0 0.067 0" rpy="0 0 0" />
	<geometry name="shadowarm_visual">
          <mesh filename="package://sr_description/arm/model/upper_arm.dae" scale="0.001 0.001 0.001" />
        </geometry>
        <material name="Grey" />
      </visual>
      <collision>
	<origin xyz="0 0.067 0" rpy="0 0 0" />
	<geometry name="shadowarm_collision_geom">
          <mesh filename="package://sr_description/arm/model/upper_arm.dae" scale="0.001 0.001 0.001" />
        </geometry>
      </collision>
    </link>
    <gazebo reference="shadowarm_upperarm">
      <material>LightGrey</material>
      <selfCollide>false</selfCollide>
    </gazebo>

    <joint name="ShoulderJSwing" type="revolute">
      <parent link="${parent}"/>
      <child link="shadowarm_upperarm"/>
      <origin xyz="0 -0.134 0.5305" rpy="0 -${M_PI} 0.0" /> <!-- yaw=-0.026 -->
      <axis xyz="0 -1 0" />
      <limit lower="0" upper="${M_PI/2}" effort="1000.0" velocity="10.0"/>
      <dynamics damping="30.0"/>
    </joint>
    <gazebo reference="ShoulderJSwing">
      <provideFeedback>1</provideFeedback>
      <implicitSpringDamper>1</implicitSpringDamper>
    </gazebo>

    <xacro:shadowarm_upperarm_transmission />

  </xacro:macro>

</robot>
