<?xml version="1.0" ?>
<sdf version="1.5">
  <model name="cessna">

    <!-- Body of the plane -->
    <link name="body">
      <inertial>
        <mass>680.389</mass>
        <inertia>
          <ixx>1285.315427874</ixx>
          <ixy>0.0</ixy>
          <iyy>1824.930976707</iyy>
          <ixz>0.0</ixz>
          <iyz>0.0</iyz>
          <izz>2666.893931043</izz>
        </inertia>
        <pose>-1.0414 0 0.9271 0 0 0</pose>
      </inertial>

      <collision name="collision">
        <geometry>
          <mesh>
            <uri>model://cessna/meshes/cessna_body.dae</uri>
          </mesh>
        </geometry>
      </collision>

      <visual name="visual">
        <geometry>
          <mesh>
            <uri>model://cessna/meshes/cessna_body.dae</uri>
          </mesh>
        </geometry>
      </visual>
    </link>

    <!-- The propeller attached to the body -->
    <link name="propeller">
      <pose>1.54 0 0.84 0 0 0</pose>
      <inertial>
        <mass>18.37</mass>
        <inertia>
          <ixx>7.5067</ixx>
          <ixy>0</ixy>
          <iyy>7.5150</iyy>
          <ixz>0</ixz>
          <iyz>0</iyz>
          <izz>0.068275</izz>
        </inertia>
        <pose>-0.35 0 0 0 0 0</pose>
      </inertial>

      <collision name="collision">
        <geometry>
          <!-- In case a simple shape is preferred -->
          <!--box><size>0.05 0.14 2.21</size></box>-->
          <mesh>
            <uri>model://cessna/meshes/cessna_prop.dae</uri>
          </mesh>
        </geometry>
      </collision>
      <visual name="visual">
        <geometry>
          <mesh>
            <uri>model://cessna/meshes/cessna_prop.dae</uri>
          </mesh>
        </geometry>
        <material>
          <script>
            <name>Gazebo/Grey</name>
          </script>
        </material>
      </visual>
    </link>

    <!-- Joint to make the propeller spin -->
    <joint name='spinning_joint' type='revolute'>
      <parent>body</parent>
      <child>propeller</child>
      <axis>
        <xyz>1 0 0</xyz>
        <use_parent_model_frame>1</use_parent_model_frame>
        <limit>
          <lower>-1e+12</lower>
          <upper>1e+12</upper>
          <effort>1000</effort>
          <velocity>-1</velocity>
        </limit>
      </axis>
    </joint>

  </model>
</sdf>
