<?xml version="1.0" ?>
<sdf version="1.5">
  <model name="cessna">

    <!-- Body of the plane -->
    <link name="body">
      <inertial>
        <mass>680.389</mass>
        <inertia>
          <ixx>1285.315427874</ixx>
          <ixy>0.0</ixy>
          <iyy>1824.930976707</iyy>
          <ixz>0.0</ixz>
          <iyz>0.0</iyz>
          <izz>2666.893931043</izz>
        </inertia>
        <pose>-1.0414 0 0.9271 0 0 0</pose>
      </inertial>

      <collision name="collision">
        <geometry>
          <mesh>
            <uri>model://cessna/meshes/cessna_body.dae</uri>
          </mesh>
        </geometry>
      </collision>

      <visual name="visual">
        <geometry>
          <mesh>
            <uri>model://cessna/meshes/cessna_body.dae</uri>
          </mesh>
        </geometry>
      </visual>

      <!-- Debug - Centers of pressure -->
      <visual name="pp1">
        <pose>-1 2.205 1.5 0 0 0</pose>
        <geometry>
          <sphere><radius>0.1</radius></sphere>
        </geometry>
        <material>
          <script>
            <uri>file://media/materials/scripts/gazebo.material</uri>
            <name>Gazebo/Black</name>
          </script>
        </material>
      </visual>

      <visual name="pp2">
        <pose>-1 -2.205 1.5 0 0 0</pose>
        <geometry>
          <sphere><radius>0.1</radius></sphere>
        </geometry>
        <material>
          <script>
            <uri>file://media/materials/scripts/gazebo.material</uri>
            <name>Gazebo/Black</name>
          </script>
        </material>
      </visual>

      <visual name="pp3">
        <pose>-5.45 0 0.55 0 0 0</pose>
        <geometry>
          <sphere><radius>0.1</radius></sphere>
        </geometry>
        <material>
          <script>
            <uri>file://media/materials/scripts/gazebo.material</uri>
            <name>Gazebo/Black</name>
          </script>
        </material>
      </visual>

      <visual name="pp4">
        <pose>-6 0 1.55 0 0 0</pose>
        <geometry>
          <sphere><radius>0.1</radius></sphere>
        </geometry>
        <material>
          <script>
            <uri>file://media/materials/scripts/gazebo.material</uri>
            <name>Gazebo/Black</name>
          </script>
        </material>
      </visual>


    </link>

    <!-- The propeller attached to the body -->
    <link name="propeller">
      <pose>1.54 0 0.84 0 0 0</pose>
      <inertial>
        <mass>18.37</mass>
        <inertia>
          <ixx>7.5067</ixx>
          <ixy>0</ixy>
          <iyy>7.5150</iyy>
          <ixz>0</ixz>
          <iyz>0</iyz>
          <izz>0.068275</izz>
        </inertia>
        <pose>-0.35 0 0 0 0 0</pose>
      </inertial>

      <collision name="collision">
        <geometry>
          <!-- In case a simple shape is preferred -->
          <!--box><size>0.05 0.14 2.21</size></box>-->
          <mesh>
            <uri>model://cessna/meshes/cessna_prop.dae</uri>
          </mesh>
        </geometry>
      </collision>
      <visual name="visual">
        <geometry>
          <mesh>
            <uri>model://cessna/meshes/cessna_prop.dae</uri>
          </mesh>
        </geometry>
        <material>
          <script>
            <name>Gazebo/Grey</name>
          </script>
        </material>
      </visual>
    </link>

    <!-- Joint to make the propeller spin -->
    <joint name='spinning_joint' type='revolute'>
      <parent>body</parent>
      <child>propeller</child>
      <axis>
        <xyz>1 0 0</xyz>
        <use_parent_model_frame>1</use_parent_model_frame>
        <limit>
          <lower>-1e+12</lower>
          <upper>1e+12</upper>
          <effort>1000</effort>
          <velocity>-1</velocity>
        </limit>
      </axis>
    </joint>

    <plugin name="gazebo_left_wing" filename="libLiftDragPlugin.so">
      <a0>0.05984281113</a0>
      <cla>4.752798721</cla>
      <cda>0.6417112299</cda>
      <cma>-1.8</cma>
      <alpha_stall>0.3391428111</alpha_stall>
      <cla_stall>-3.85</cla_stall>
      <cda_stall>-0.9233984055</cda_stall>
      <cma_stall>0</cma_stall>
      <cp>-1 2.205 1.5</cp>
      <area>8.08255</area>
      <air_density>1.2041</air_density>
      <forward>1 0 0</forward>
      <upward>0 0 1</upward>
      <link_name>cessna::body</link_name>
    </plugin>

    <plugin name="gazebo_right_wing" filename="libLiftDragPlugin.so">
      <a0>0.05984281113</a0>
      <cla>4.752798721</cla>
      <cda>0.6417112299</cda>
      <cma>-1.8</cma>
      <alpha_stall></alpha_stall>
      <cla_stall>-3.85</cla_stall>
      <cda_stall>-0.9233984055</cda_stall>
      <cma_stall>0</cma_stall>
      <cp>-1 -2.205 1.5</cp>
      <area>8.08255</area>
      <air_density>1.2041</air_density>
      <forward>1 0 0</forward>
      <upward>0 0 1</upward>
      <link_name>cessna::body</link_name>
    </plugin>

    <!--<plugin name="gazebo_elevator" filename="libLiftDragPlugin.so">
      <a0>0</a0>
      <cla>-0.43</cla>
      <cda></cda>
      <cma></cma>
      <alpha_stall></alpha_stall>
      <cla_stall></cla_stall>
      <cda_stall></cda_stall>
      <cma_stall></cma_stall>
      <cp>-5.45 0 0.55</cp>
      <area>2.03458</area>
      <air_density>1.2041</air_density>
      <forward>1 0 0</forward>
      <upward>0 0 1</upward>
      <link_name>cessna::body</link_name>
    </plugin>-->

    <!--<plugin name="gazebo_rudder" filename="libLiftDragPlugin.so">
      <a0>0</a0>
      <cla></cla>
      <cda></cda>
      <cma></cma>
      <alpha_stall></alpha_stall>
      <cla_stall></cla_stall>
      <cda_stall></cda_stall>
      <cma_stall></cma_stall>
      <cp>-6 0 1.55</cp>
      <area>1.5329</area>
      <air_density>1.2041</air_density>
      <forward>1 0 0</forward>
      <upward>0 0 1</upward>
      <link_name>cessna::body</link_name>
    </plugin>-->

  </model>
</sdf>
