<?xml version="1.0" ?>
<sdf version="1.5">
  <model name="wheel_valve_large">
    <link name="handle">
      <pose>0 0.0310 0 0 0 0</pose>
      <inertial>
        <mass>7.8219</mass>
        <pose>0 0.0615 0 0 0 0</pose>
        <inertia>
          <ixx>0.0695</ixx>
          <ixy>0.0000</ixy>
          <ixz>0.0000</ixz>
          <iyy>0.1349</iyy>
          <iyz>0.0000</iyz>
          <izz>0.0695</izz>
        </inertia>
      </inertial>
      <collision name="collision">
        <geometry>
          <mesh>
            <uri>model://drc_practice_wheel_valve_large/meshes/wheel_valve_large.dae</uri>
          </mesh>
        </geometry>
        <surface>
          <friction>
            <ode>
              <mu>1</mu>
              <mu2>1</mu2>
            </ode>
          </friction>
          <contact>
            <ode>
              <kp>1000000.0</kp>
              <kd>100.0</kd>
              <max_vel>0.01</max_vel>
              <min_depth>0.001</min_depth>
            </ode>
          </contact>
        </surface>
      </collision>
      <visual name="visual">
        <geometry>
          <mesh>
            <uri>model://drc_practice_wheel_valve_large/meshes/wheel_valve_large.dae</uri>
          </mesh>
        </geometry>
      </visual>
    </link>
    <!--
         This is just a visual until SDF collide_bitmask is implemented.
         Without collide_bitmask, the "attachment" will collide with a
         wall that separates the handle from the attachment causing jitter
    -->
    <!--
    <link name="attachment">
      <pose>0 0 0.177428906 0 0 0</pose>
      <collision name="collision">
        <geometry>
          <mesh>
            <uri>model://drc_practice_ball_valve/meshes/attachment.dae</uri>
          </mesh>
        </geometry>
      </collision>

      <visual name="visual">
        <geometry>
          <mesh>
            <scale>1.6 1.6 1.6</scale>
            <uri>model://drc_practice_ball_valve/meshes/attachment.dae</uri>
          </mesh>
        </geometry>
      </visual>
    </link>
-->
    <joint name="joint" type="revolute">
      <parent>world</parent>
      <child>handle</child>
      <axis>
        <xyz>0 1 0</xyz>
        <limit>
          <lower>-12.56</lower>
          <upper>12.56</upper>
        </limit>
        <dynamics>
          <!--velocity dependent viscous damping coefficient of the joint-->
          <damping>0.1</damping>
          <!--default 0, static friction value of the joint-->
          <friction>0.1</friction>
        </dynamics>
        <use_parent_model_frame>false</use_parent_model_frame>
      </axis>
      <physics>
        <ode>
          <implicit_spring_damper>1</implicit_spring_damper>
        </ode>
      </physics>
    </joint>
  </model>
</sdf>
