<robot xmlns:xacro="http://ros.org/wiki/xacro"
        xmlns:sensor="http://playerstage.sourceforge.net/gazebo/xmlschema/#sensor"
       xmlns:controller="http://playerstage.sourceforge.net/gazebo/xmlschema/#controller"
       xmlns:joint="http://playerstage.sourceforge.net/gazebo/xmlschema/#slider"
       xmlns:interface="http://playerstage.sourceforge.net/gazebo/xmlschema/#interface"
       xmlns:body="http://playerstage.sourceforge.net/gazebo/xmlschema/#body"
       xmlns:geom="http://playerstage.sourceforge.net/gazebo/xmlschema/#geom">


<!-- C6 hand thumb with BioTAC sensor
  this is currently completely broken; we need to fix the
  collision geometries, and to calculate/measure the correct
  position for thtip for FK/IK services.

  We also need to check the THJ2 rotation axis and the rpy
  orientation of the thmiddle BioTAC adapter.

  2012.11.08 - use downsampled BioTAC meshes, fix thumb collision model
  2012.09.05 - new file

  (C) 2012 fnh, hendrich@informatik.uni-hamburg.de
-->

  <xacro:macro name="thbiotac" params="parent">

    <link name="thmiddle">
      <inertial>
	      <mass value="0.016" />
	      <origin xyz="0 0 0.016" rpy="0 0 0"/>
	      <inertia  ixx="1e-6" ixy="0.0"  ixz="0.0"
                  iyy="1e-6"  iyz="0.0"
                  izz="1e-6" />
      </inertial>
      <visual>
	      <origin xyz="0 0 0" rpy="0 0 0" />
	      <geometry name="thmiddle_visual">
	        <mesh filename="package://sr_description/hand/model/biotacs/biotac_thumb_adapter.dae" scale="0.001 0.001 0.001" />
        </geometry>
      </visual>
      <collision>
	      <origin xyz="0 0 0.01" rpy="0 0 0" />
	      <geometry name="thmiddle_collision_geom">
	        <box size="0.008 0.008 0.01" />
	      </geometry>
      </collision>
    </link>

    <gazebo reference="thmiddle">
      <sensor type="contact" name="thmiddle_contact" >
        <always_on>1</always_on>
        <update_rate>1000.0</update_rate>
        <contact>
          <collision>thmiddle_collision</collision>
          <topic>thmiddle_collision</topic>
        </contact>
        <plugin name="thmiddle_gazebo_ros_bumper_controller" filename="libgazebo_ros_bumper.so">
          <updateRate>100.0</updateRate>
	  <frameName>thmiddle</frameName>
	  <bumperTopicName>contacts/th/middle</bumperTopicName>
        </plugin>
      </sensor>
      <material>LightGrey</material>
    </gazebo>

    <joint name="THJ2" type="revolute">
      <parent link="${parent}"/>
      <child link="thmiddle"/>
      <origin xyz="0 0 0.01" rpy="0 0 0" /> <!-- FIXME: z offset is too large -->
      <axis xyz="0 -1 0" />
      <limit lower="-0.6981" upper="0.6981" effort="1000.0"
      velocity="10.0" />
      <dynamics damping="10.0"/>
    </joint>
    <gazebo reference="THJ2">
      <provideFeedback>1</provideFeedback>
      <implicitSpringDamper>1</implicitSpringDamper>
    </gazebo>

    <transmission type="sr_mechanism_model/SimpleTransmission" name="thmiddle_transmission">
      <actuator name="THJ2" />
      <joint name="THJ2" />
      <mechanicalReduction>1</mechanicalReduction>
      <motorTorqueConstant>1</motorTorqueConstant>
      <pulsesPerRevolution>90000</pulsesPerRevolution>
    </transmission>

    <link name="thbiotac_J1_dummy">
      <inertial>
        <origin xyz="0 0 0" rpy="0 0 0" />
        <mass value="0.01" />
        <inertia  ixx="0.1" ixy="0.0"  ixz="0.0"  iyy="0.1"  iyz="0.0" izz="0.01" />
      </inertial>
    </link>

    <joint name="THJ1" type="revolute">
      <parent link="thmiddle"/>
      <child link="thbiotac_J1_dummy"/>
      <origin xyz="0 0 0.02" rpy="0 0 0" />
      <axis xyz="1 0 0" />
      <limit lower="${20*M_PI/180}" upper="${20.1*M_PI/180}" effort="1000.0" velocity="10.0" />
      <dynamics damping="10.0"/>
    </joint>
    <gazebo reference="THJ1">
      <provideFeedback>1</provideFeedback>
      <implicitSpringDamper>1</implicitSpringDamper>
    </gazebo>

    <transmission type="sr_mechanism_model/SimpleTransmission" name="thdistal_transmission">
      <actuator name="THJ1" />
      <joint name="THJ1" />
      <mechanicalReduction>1</mechanicalReduction>
      <motorTorqueConstant>1</motorTorqueConstant>
      <pulsesPerRevolution>90000</pulsesPerRevolution>
    </transmission>


    <link name="thbiotac">
      <inertial>
        <origin xyz="0 0 0" rpy="0 0 0" />
        <mass value="0.2" />
        <inertia  ixx="1" ixy="0.0"  ixz="0.0"  iyy="1"  iyz="0.0" izz="1" />
      </inertial>
      <visual>
        <origin xyz="0 0 0" rpy="0 0 0" />
        <geometry name="biotac_visual">
          <!-- <mesh filename="package://sr_description/hand/model/biotacs/biotac.stl" scale="0.0254 0.0254 0.0254" /> -->
          <mesh filename="package://sr_description/hand/model/biotacs/biotac_decimated.dae" scale="0.0254 0.0254 0.0254" />
        </geometry>
        <material name="BiotacGreen" />
      </visual>
      <collision>
        <geometry name="th_biotac_collision_geom">
          <!-- <box size="0.001 0.001 0.001" /> -->
          <!-- <mesh filename="package://sr_description/hand/model/biotacs/biotac-v5.stl" scale="0.0254 0.0254 0.0254" /> -->
          <mesh filename="package://sr_description/hand/model/biotacs/biotac_decimated.dae" scale="0.0254 0.0254 0.0254" />
        </geometry>
      </collision>
    </link>

    <gazebo reference="thdistal">
      <sensor type="contact" name="thdistal_contact" >
        <always_on>1</always_on>
        <update_rate>1000.0</update_rate>
        <contact>
          <collision>thbiotac_collision_geom</collision>
          <topic>thdistal_collision</topic>
        </contact>
        <plugin name="thdistal_gazebo_ros_bumper_controller" filename="libgazebo_ros_bumper.so">
          <updateRate>100.0</updateRate>
	  <frameName>thbiotac</frameName>
	  <bumperTopicName>contacts/th/distal</bumperTopicName>
        </plugin>
      </sensor>
      <selfCollide>true</selfCollide>
      <material>BiotacGreen</material>
    </gazebo>

    <joint name="th_biotac_joint" type="fixed">
      <parent link="thmiddle"/>
      <child link="thbiotac"/>
      <origin xyz="0 0.0 0.01" rpy="0 0 -1.571" />
    </joint>


    <!-- extra link to imaginary sphere in fingertip for FK/IK calculations -->
    <!-- remove visual and collision once the correct position is found -->
    <link name="thtip">
      <inertial>
       <mass value="0.001" />
       <origin xyz="0 0 0" rpy="0 0 0" />
       <inertia  ixx="1" ixy="0"  ixz="0"  iyy="1"  iyz="0" izz="1" />
      </inertial>
      <visual>
        <geometry>
          <sphere radius="0.002" />
        </geometry>
      </visual>
      <collision>
        <geometry>
          <box size="0.001 0.001 0.001" />
        </geometry>
      </collision>
    </link>

    <gazebo reference="thtip">
      <material name="LightGrey"/>
    </gazebo>

    <joint name="thtip" type="fixed">
      <parent link="thmiddle"/>
      <child link="thtip"/>
      <origin xyz="-0.009 0.0 ${0.01+0.044}" rpy="0 0 -1.571" /> <!-- approximated only FIXME -->
    </joint>

  </xacro:macro>

</robot>
