<robot xmlns:xacro="http://ros.org/wiki/xacro"
       xmlns:sensor="http://playerstage.sourceforge.net/gazebo/xmlschema/#sensor"
       xmlns:controller="http://playerstage.sourceforge.net/gazebo/xmlschema/#controller"
       xmlns:joint="http://playerstage.sourceforge.net/gazebo/xmlschema/#slider"
       xmlns:interface="http://playerstage.sourceforge.net/gazebo/xmlschema/#interface"
       xmlns:body="http://playerstage.sourceforge.net/gazebo/xmlschema/#body"
       xmlns:geom="http://playerstage.sourceforge.net/gazebo/xmlschema/#geom">

  <xacro:include filename="$(find sr_description)/hand/xacro/thumb/thhub.transmission.xacro" />

  <xacro:macro name="thhub" params="parent">

    <link name="thhub">
      <inertial>
	<mass value="0.002" />
	<origin xyz="0 0 0" rpy="0 0 0"/>
	<inertia  ixx="1e-7" ixy="0.0"  ixz="0.0"
            iyy="1e-7"  iyz="0.0"
	          izz="1e-7" />
      </inertial>
      <visual>
	<origin xyz="0 0 0" rpy="0 0 0" />
	<geometry name="thhub_visual">
	<box size="0.001 0.001 0.001" />
      </geometry>
      <material name="shadow_thhub_material">
	  <color rgba="0.7 0.7 0.7 1.0"/>
	</material>
      </visual>
      <collision>
	<origin xyz="0 0 0" rpy="0 0 0 " />
	<geometry name="thhub_collision_geom">
	  <box size="0.001 0.001 0.001" />
	</geometry>
      </collision>
    </link>

    <gazebo reference="thhub">
      <sensor type="contact" name="thhub_contact" >
        <always_on>1</always_on>
        <update_rate>1000.0</update_rate>
        <contact>
          <collision>thhub_collision</collision>
          <topic>thhub_collision</topic>
        </contact>
        <plugin name="thhub_gazebo_ros_bumper_controller" filename="libgazebo_ros_bumper.so">
          <updateRate>100.0</updateRate>
	  <frameName>thhub</frameName>
	  <bumperTopicName>contacts/th/hub</bumperTopicName>
        </plugin>
      </sensor>
      <material>LightGrey</material>
    </gazebo>

    <joint name="THJ3" type="revolute">
      <parent link="${parent}"/>
      <child link="thhub"/>
      <origin xyz="0 0 0.038" rpy="0 0 0" />
      <axis xyz="1 0 0" />
      <limit lower="-0.2618" upper="0.2618" effort="1000.0"
      velocity="10.0" />
      <dynamics damping="10.0"/>
    </joint>
    <gazebo reference="THJ3">
      <provideFeedback>1</provideFeedback>
      <implicitSpringDamper>1</implicitSpringDamper>
    </gazebo>

    <xacro:thhub_transmission />

  </xacro:macro>

</robot>
