<?xml version="1.0" ?>
<!-- =================================================================================== -->
<!-- |    This document was autogenerated by xacro from robots/handle.urdf.xacro       | -->
<!-- |    EDITING THIS FILE BY HAND IS NOT RECOMMENDED                                 | -->
<!-- =================================================================================== -->
<robot name="armh_handle" xmlns:xacro="http://www.ros.org/wiki/xacro">
  <!-- roslaunch urdf_tutorial display.launch model:=handle.urdf gui:=True -->
  <!-- rosrun xacro xacro.py handle_urdf.xacro > handle.urdf -->
  <!-- tip: use measurements from solid to find the origins and length -->
  <link name="finger[0]/flexible_link_1">
    <inertial>
      <mass value="0.1"/>
      <origin xyz="0 0 0"/>
      <inertia ixx="0.001" ixy="0.0" ixz="0.0" iyy="0.001" iyz="0.0" izz="0.001"/>
    </inertial>
    <collision>
      <geometry>
        <box size=".014 0.00176 .006"/>
      </geometry>
      <origin rpy="1.57 0 0" xyz="0 0 0"/>
    </collision>
    <visual>
      <geometry>
        <box size=".014 0.00176 .006"/>
      </geometry>
      <origin rpy="1.57 0 0" xyz="0 0 0"/>
      <material name="darkgray">
        <color rgba="0.2 0.2 0.2 1"/>
      </material>
    </visual>
  </link>
  <link name="finger[0]/flexible_link_2">
    <inertial>
      <mass value="0.1"/>
      <origin xyz="0 0 0"/>
      <inertia ixx="0.001" ixy="0.0" ixz="0.0" iyy="0.001" iyz="0.0" izz="0.001"/>
    </inertial>
    <collision>
      <geometry>
        <box size=".014 0.00176 .006"/>
      </geometry>
      <origin rpy="1.57 0 0" xyz="0 0 0"/>
    </collision>
    <visual>
      <geometry>
        <box size=".014 0.00176 .006"/>
      </geometry>
      <origin rpy="1.57 0 0" xyz="0 0 0"/>
      <material name="darkgray">
        <color rgba="0.2 0.2 0.2 1"/>
      </material>
    </visual>
  </link>
  <link name="finger[0]/flexible_link_3">
    <inertial>
      <mass value="0.1"/>
      <origin xyz="0 0 0"/>
      <inertia ixx="0.001" ixy="0.0" ixz="0.0" iyy="0.001" iyz="0.0" izz="0.001"/>
    </inertial>
    <collision>
      <geometry>
        <box size=".014 0.00176 .006"/>
      </geometry>
      <origin rpy="1.57 0 0" xyz="0 0 0"/>
    </collision>
    <visual>
      <geometry>
        <box size=".014 0.00176 .006"/>
      </geometry>
      <origin rpy="1.57 0 0" xyz="0 0 0"/>
      <material name="darkgray">
        <color rgba="0.2 0.2 0.2 1"/>
      </material>
    </visual>
  </link>
  <link name="finger[0]/flexible_link_4">
    <inertial>
      <mass value="0.1"/>
      <origin xyz="0 0 0"/>
      <inertia ixx="0.001" ixy="0.0" ixz="0.0" iyy="0.001" iyz="0.0" izz="0.001"/>
    </inertial>
    <collision>
      <geometry>
        <box size=".014 0.00176 .006"/>
      </geometry>
      <origin rpy="1.57 0 0" xyz="0 0 0"/>
    </collision>
    <visual>
      <geometry>
        <box size=".014 0.00176 .006"/>
      </geometry>
      <origin rpy="1.57 0 0" xyz="0 0 0"/>
      <material name="darkgray">
        <color rgba="0.2 0.2 0.2 1"/>
      </material>
    </visual>
  </link>
  <link name="finger[0]/flexible_link_5">
    <inertial>
      <mass value="0.1"/>
      <origin xyz="0 0 0"/>
      <inertia ixx="0.001" ixy="0.0" ixz="0.0" iyy="0.001" iyz="0.0" izz="0.001"/>
    </inertial>
    <collision>
      <geometry>
        <box size=".014 0.00176 .006"/>
      </geometry>
      <origin rpy="1.57 0 0" xyz="0 0 0"/>
    </collision>
    <visual>
      <geometry>
        <box size=".014 0.00176 .006"/>
      </geometry>
      <origin rpy="1.57 0 0" xyz="0 0 0"/>
      <material name="darkgray">
        <color rgba="0.2 0.2 0.2 1"/>
      </material>
    </visual>
  </link>
  <link name="finger[0]/flexible_link_6">
    <inertial>
      <mass value="0.1"/>
      <origin xyz="0 0 0"/>
      <inertia ixx="0.001" ixy="0.0" ixz="0.0" iyy="0.001" iyz="0.0" izz="0.001"/>
    </inertial>
    <collision>
      <geometry>
        <box size=".014 0.00176 .006"/>
      </geometry>
      <origin rpy="1.57 0 0" xyz="0 0 0"/>
    </collision>
    <visual>
      <geometry>
        <box size=".014 0.00176 .006"/>
      </geometry>
      <origin rpy="1.57 0 0" xyz="0 0 0"/>
      <material name="darkgray">
        <color rgba="0.2 0.2 0.2 1"/>
      </material>
    </visual>
  </link>
  <link name="finger[0]/flexible_link_7">
    <inertial>
      <mass value="0.1"/>
      <origin xyz="0 0 0"/>
      <inertia ixx="0.001" ixy="0.0" ixz="0.0" iyy="0.001" iyz="0.0" izz="0.001"/>
    </inertial>
    <collision>
      <geometry>
        <box size=".014 0.00176 .006"/>
      </geometry>
      <origin rpy="1.57 0 0" xyz="0 0 0"/>
    </collision>
    <visual>
      <geometry>
        <box size=".014 0.00176 .006"/>
      </geometry>
      <origin rpy="1.57 0 0" xyz="0 0 0"/>
      <material name="darkgray">
        <color rgba="0.2 0.2 0.2 1"/>
      </material>
    </visual>
  </link>
  <link name="finger[0]/flexible_link_8">
    <inertial>
      <mass value="0.1"/>
      <origin xyz="0 0 0"/>
      <inertia ixx="0.001" ixy="0.0" ixz="0.0" iyy="0.001" iyz="0.0" izz="0.001"/>
    </inertial>
    <collision>
      <geometry>
        <box size=".014 0.00176 .006"/>
      </geometry>
      <origin rpy="1.57 0 0" xyz="0 0 0"/>
    </collision>
    <visual>
      <geometry>
        <box size=".014 0.00176 .006"/>
      </geometry>
      <origin rpy="1.57 0 0" xyz="0 0 0"/>
      <material name="darkgray">
        <color rgba="0.2 0.2 0.2 1"/>
      </material>
    </visual>
  </link>
  <link name="finger[0]/flexible_link_9">
    <inertial>
      <mass value="0.1"/>
      <origin xyz="0 0 0"/>
      <inertia ixx="0.001" ixy="0.0" ixz="0.0" iyy="0.001" iyz="0.0" izz="0.001"/>
    </inertial>
    <collision>
      <geometry>
        <box size=".014 0.00176 .006"/>
      </geometry>
      <origin rpy="1.57 0 0" xyz="0 0 0"/>
    </collision>
    <visual>
      <geometry>
        <box size=".014 0.00176 .006"/>
      </geometry>
      <origin rpy="1.57 0 0" xyz="0 0 0"/>
      <material name="darkgray">
        <color rgba="0.2 0.2 0.2 1"/>
      </material>
    </visual>
  </link>
  <joint name="finger[0]/flexible_joint_flex_from_1_to_2" type="revolute">
    <parent link="finger[0]/flexible_link_1"/>
    <child link="finger[0]/flexible_link_hidden_between_1_and_2"/>
    <origin xyz="0 0 0.00177777777778"/>
    <axis xyz="-1 0 0"/>
    <limit effort="1000.0" lower="0.0" upper="1.57" velocity="0.5"/>
  </joint>
  <link name="finger[0]/flexible_link_hidden_between_1_and_2">
    <inertial>
      <mass value="0.1"/>
      <origin xyz="0 0 0"/>
      <inertia ixx="0.001" ixy="0.0" ixz="0.0" iyy="0.001" iyz="0.0" izz="0.001"/>
    </inertial>
    <collision>
      <geometry>
        <box size="0 0 0"/>
      </geometry>
      <origin rpy="0 0 0" xyz="0 0 0"/>
    </collision>
    <visual>
      <geometry>
        <box size="0 0 0"/>
      </geometry>
      <origin rpy="0 0 0" xyz="0 0 0"/>
    </visual>
  </link>
  <joint name="finger[0]/flexible_joint_twist_from_1_to_2" type="revolute">
    <parent link="finger[0]/flexible_link_hidden_between_1_and_2"/>
    <child link="finger[0]/flexible_link_2"/>
    <origin xyz="0 0 0"/>
    <axis xyz="0 0 1"/>
    <limit effort="1000.0" lower="0.0" upper="1.57" velocity="0.5"/>
  </joint>
  <joint name="finger[0]/flexible_joint_flex_from_2_to_3" type="revolute">
    <parent link="finger[0]/flexible_link_2"/>
    <child link="finger[0]/flexible_link_hidden_between_2_and_3"/>
    <origin xyz="0 0 0.00177777777778"/>
    <axis xyz="-1 0 0"/>
    <limit effort="1000.0" lower="0.0" upper="1.57" velocity="0.5"/>
  </joint>
  <link name="finger[0]/flexible_link_hidden_between_2_and_3">
    <inertial>
      <mass value="0.1"/>
      <origin xyz="0 0 0"/>
      <inertia ixx="0.001" ixy="0.0" ixz="0.0" iyy="0.001" iyz="0.0" izz="0.001"/>
    </inertial>
    <collision>
      <geometry>
        <box size="0 0 0"/>
      </geometry>
      <origin rpy="0 0 0" xyz="0 0 0"/>
    </collision>
    <visual>
      <geometry>
        <box size="0 0 0"/>
      </geometry>
      <origin rpy="0 0 0" xyz="0 0 0"/>
    </visual>
  </link>
  <joint name="finger[0]/flexible_joint_twist_from_2_to_3" type="revolute">
    <parent link="finger[0]/flexible_link_hidden_between_2_and_3"/>
    <child link="finger[0]/flexible_link_3"/>
    <origin xyz="0 0 0"/>
    <axis xyz="0 0 1"/>
    <limit effort="1000.0" lower="0.0" upper="1.57" velocity="0.5"/>
  </joint>
  <joint name="finger[0]/flexible_joint_flex_from_3_to_4" type="revolute">
    <parent link="finger[0]/flexible_link_3"/>
    <child link="finger[0]/flexible_link_hidden_between_3_and_4"/>
    <origin xyz="0 0 0.00177777777778"/>
    <axis xyz="-1 0 0"/>
    <limit effort="1000.0" lower="0.0" upper="1.57" velocity="0.5"/>
  </joint>
  <link name="finger[0]/flexible_link_hidden_between_3_and_4">
    <inertial>
      <mass value="0.1"/>
      <origin xyz="0 0 0"/>
      <inertia ixx="0.001" ixy="0.0" ixz="0.0" iyy="0.001" iyz="0.0" izz="0.001"/>
    </inertial>
    <collision>
      <geometry>
        <box size="0 0 0"/>
      </geometry>
      <origin rpy="0 0 0" xyz="0 0 0"/>
    </collision>
    <visual>
      <geometry>
        <box size="0 0 0"/>
      </geometry>
      <origin rpy="0 0 0" xyz="0 0 0"/>
    </visual>
  </link>
  <joint name="finger[0]/flexible_joint_twist_from_3_to_4" type="revolute">
    <parent link="finger[0]/flexible_link_hidden_between_3_and_4"/>
    <child link="finger[0]/flexible_link_4"/>
    <origin xyz="0 0 0"/>
    <axis xyz="0 0 1"/>
    <limit effort="1000.0" lower="0.0" upper="1.57" velocity="0.5"/>
  </joint>
  <joint name="finger[0]/flexible_joint_flex_from_4_to_5" type="revolute">
    <parent link="finger[0]/flexible_link_4"/>
    <child link="finger[0]/flexible_link_hidden_between_4_and_5"/>
    <origin xyz="0 0 0.00177777777778"/>
    <axis xyz="-1 0 0"/>
    <limit effort="1000.0" lower="0.0" upper="1.57" velocity="0.5"/>
  </joint>
  <link name="finger[0]/flexible_link_hidden_between_4_and_5">
    <inertial>
      <mass value="0.1"/>
      <origin xyz="0 0 0"/>
      <inertia ixx="0.001" ixy="0.0" ixz="0.0" iyy="0.001" iyz="0.0" izz="0.001"/>
    </inertial>
    <collision>
      <geometry>
        <box size="0 0 0"/>
      </geometry>
      <origin rpy="0 0 0" xyz="0 0 0"/>
    </collision>
    <visual>
      <geometry>
        <box size="0 0 0"/>
      </geometry>
      <origin rpy="0 0 0" xyz="0 0 0"/>
    </visual>
  </link>
  <joint name="finger[0]/flexible_joint_twist_from_4_to_5" type="revolute">
    <parent link="finger[0]/flexible_link_hidden_between_4_and_5"/>
    <child link="finger[0]/flexible_link_5"/>
    <origin xyz="0 0 0"/>
    <axis xyz="0 0 1"/>
    <limit effort="1000.0" lower="0.0" upper="1.57" velocity="0.5"/>
  </joint>
  <joint name="finger[0]/flexible_joint_flex_from_5_to_6" type="revolute">
    <parent link="finger[0]/flexible_link_5"/>
    <child link="finger[0]/flexible_link_hidden_between_5_and_6"/>
    <origin xyz="0 0 0.00177777777778"/>
    <axis xyz="-1 0 0"/>
    <limit effort="1000.0" lower="0.0" upper="1.57" velocity="0.5"/>
  </joint>
  <link name="finger[0]/flexible_link_hidden_between_5_and_6">
    <inertial>
      <mass value="0.1"/>
      <origin xyz="0 0 0"/>
      <inertia ixx="0.001" ixy="0.0" ixz="0.0" iyy="0.001" iyz="0.0" izz="0.001"/>
    </inertial>
    <collision>
      <geometry>
        <box size="0 0 0"/>
      </geometry>
      <origin rpy="0 0 0" xyz="0 0 0"/>
    </collision>
    <visual>
      <geometry>
        <box size="0 0 0"/>
      </geometry>
      <origin rpy="0 0 0" xyz="0 0 0"/>
    </visual>
  </link>
  <joint name="finger[0]/flexible_joint_twist_from_5_to_6" type="revolute">
    <parent link="finger[0]/flexible_link_hidden_between_5_and_6"/>
    <child link="finger[0]/flexible_link_6"/>
    <origin xyz="0 0 0"/>
    <axis xyz="0 0 1"/>
    <limit effort="1000.0" lower="0.0" upper="1.57" velocity="0.5"/>
  </joint>
  <joint name="finger[0]/flexible_joint_flex_from_6_to_7" type="revolute">
    <parent link="finger[0]/flexible_link_6"/>
    <child link="finger[0]/flexible_link_hidden_between_6_and_7"/>
    <origin xyz="0 0 0.00177777777778"/>
    <axis xyz="-1 0 0"/>
    <limit effort="1000.0" lower="0.0" upper="1.57" velocity="0.5"/>
  </joint>
  <link name="finger[0]/flexible_link_hidden_between_6_and_7">
    <inertial>
      <mass value="0.1"/>
      <origin xyz="0 0 0"/>
      <inertia ixx="0.001" ixy="0.0" ixz="0.0" iyy="0.001" iyz="0.0" izz="0.001"/>
    </inertial>
    <collision>
      <geometry>
        <box size="0 0 0"/>
      </geometry>
      <origin rpy="0 0 0" xyz="0 0 0"/>
    </collision>
    <visual>
      <geometry>
        <box size="0 0 0"/>
      </geometry>
      <origin rpy="0 0 0" xyz="0 0 0"/>
    </visual>
  </link>
  <joint name="finger[0]/flexible_joint_twist_from_6_to_7" type="revolute">
    <parent link="finger[0]/flexible_link_hidden_between_6_and_7"/>
    <child link="finger[0]/flexible_link_7"/>
    <origin xyz="0 0 0"/>
    <axis xyz="0 0 1"/>
    <limit effort="1000.0" lower="0.0" upper="1.57" velocity="0.5"/>
  </joint>
  <joint name="finger[0]/flexible_joint_flex_from_7_to_8" type="revolute">
    <parent link="finger[0]/flexible_link_7"/>
    <child link="finger[0]/flexible_link_hidden_between_7_and_8"/>
    <origin xyz="0 0 0.00177777777778"/>
    <axis xyz="-1 0 0"/>
    <limit effort="1000.0" lower="0.0" upper="1.57" velocity="0.5"/>
  </joint>
  <link name="finger[0]/flexible_link_hidden_between_7_and_8">
    <inertial>
      <mass value="0.1"/>
      <origin xyz="0 0 0"/>
      <inertia ixx="0.001" ixy="0.0" ixz="0.0" iyy="0.001" iyz="0.0" izz="0.001"/>
    </inertial>
    <collision>
      <geometry>
        <box size="0 0 0"/>
      </geometry>
      <origin rpy="0 0 0" xyz="0 0 0"/>
    </collision>
    <visual>
      <geometry>
        <box size="0 0 0"/>
      </geometry>
      <origin rpy="0 0 0" xyz="0 0 0"/>
    </visual>
  </link>
  <joint name="finger[0]/flexible_joint_twist_from_7_to_8" type="revolute">
    <parent link="finger[0]/flexible_link_hidden_between_7_and_8"/>
    <child link="finger[0]/flexible_link_8"/>
    <origin xyz="0 0 0"/>
    <axis xyz="0 0 1"/>
    <limit effort="1000.0" lower="0.0" upper="1.57" velocity="0.5"/>
  </joint>
  <joint name="finger[0]/flexible_joint_flex_from_8_to_9" type="revolute">
    <parent link="finger[0]/flexible_link_8"/>
    <child link="finger[0]/flexible_link_hidden_between_8_and_9"/>
    <origin xyz="0 0 0.00177777777778"/>
    <axis xyz="-1 0 0"/>
    <limit effort="1000.0" lower="0.0" upper="1.57" velocity="0.5"/>
  </joint>
  <link name="finger[0]/flexible_link_hidden_between_8_and_9">
    <inertial>
      <mass value="0.1"/>
      <origin xyz="0 0 0"/>
      <inertia ixx="0.001" ixy="0.0" ixz="0.0" iyy="0.001" iyz="0.0" izz="0.001"/>
    </inertial>
    <collision>
      <geometry>
        <box size="0 0 0"/>
      </geometry>
      <origin rpy="0 0 0" xyz="0 0 0"/>
    </collision>
    <visual>
      <geometry>
        <box size="0 0 0"/>
      </geometry>
      <origin rpy="0 0 0" xyz="0 0 0"/>
    </visual>
  </link>
  <joint name="finger[0]/flexible_joint_twist_from_8_to_9" type="revolute">
    <parent link="finger[0]/flexible_link_hidden_between_8_and_9"/>
    <child link="finger[0]/flexible_link_9"/>
    <origin xyz="0 0 0"/>
    <axis xyz="0 0 1"/>
    <limit effort="1000.0" lower="0.0" upper="1.57" velocity="0.5"/>
  </joint>
  <joint name="finger[0]/flexible_joint_flex_from_proximal_to_1" type="revolute">
    <parent link="finger[0]/proximal_link"/>
    <child link="finger[0]/flexible_link_hidden_between_proximal_link_and_1"/>
    <origin xyz="0 0 0.062"/>
    <axis xyz="-1 0 0"/>
    <limit effort="1000.0" lower="0.0" upper="1.57" velocity="0.5"/>
  </joint>
  <link name="finger[0]/flexible_link_hidden_between_proximal_link_and_1">
    <inertial>
      <mass value="0.1"/>
      <origin xyz="0 0 0"/>
      <inertia ixx="0.001" ixy="0.0" ixz="0.0" iyy="0.001" iyz="0.0" izz="0.001"/>
    </inertial>
    <collision>
      <geometry>
        <box size="0 0 0"/>
      </geometry>
      <origin rpy="0 0 0" xyz="0 0 0"/>
    </collision>
    <visual>
      <geometry>
        <box size="0 0 0"/>
      </geometry>
      <origin rpy="0 0 0" xyz="0 0 0"/>
    </visual>
  </link>
  <joint name="finger[0]/flexible_joint_twist_from_proximal_to_1" type="revolute">
    <parent link="finger[0]/flexible_link_hidden_between_proximal_link_and_1"/>
    <child link="finger[0]/flexible_link_1"/>
    <origin xyz="0 0 0"/>
    <axis xyz="0 0 1"/>
    <limit effort="1000.0" lower="0.0" upper="1.57" velocity="0.5"/>
  </joint>
  <joint name="finger[0]/flexible_joint_flex_from_9_to_distal" type="revolute">
    <parent link="finger[0]/flexible_link_9"/>
    <child link="finger[0]/flexible_link_hidden_between_9_and_distal_link"/>
    <origin xyz="0 0 0.00177777777778"/>
    <axis xyz="-1 0 0"/>
    <limit effort="1000.0" lower="0.0" upper="1.57" velocity="0.5"/>
  </joint>
  <link name="finger[0]/flexible_link_hidden_between_9_and_distal_link">
    <inertial>
      <mass value="0.1"/>
      <origin xyz="0 0 0"/>
      <inertia ixx="0.001" ixy="0.0" ixz="0.0" iyy="0.001" iyz="0.0" izz="0.001"/>
    </inertial>
    <collision>
      <geometry>
        <box size="0 0 0"/>
      </geometry>
      <origin rpy="0 0 0" xyz="0 0 0"/>
    </collision>
    <visual>
      <geometry>
        <box size="0 0 0"/>
      </geometry>
      <origin rpy="0 0 0" xyz="0 0 0"/>
    </visual>
  </link>
  <joint name="finger[0]/flexible_joint_twist_from_9_to_distal" type="revolute">
    <parent link="finger[0]/flexible_link_hidden_between_9_and_distal_link"/>
    <child link="finger[0]/distal_link"/>
    <origin xyz="0 0 0"/>
    <axis xyz="0 0 1"/>
    <limit effort="1000.0" lower="0.0" upper="1.57" velocity="0.5"/>
  </joint>
  <link name="finger[1]/flexible_link_1">
    <inertial>
      <mass value="0.1"/>
      <origin xyz="0 0 0"/>
      <inertia ixx="0.001" ixy="0.0" ixz="0.0" iyy="0.001" iyz="0.0" izz="0.001"/>
    </inertial>
    <collision>
      <geometry>
        <box size=".014 0.00176 .006"/>
      </geometry>
      <origin rpy="1.57 0 0" xyz="0 0 0"/>
    </collision>
    <visual>
      <geometry>
        <box size=".014 0.00176 .006"/>
      </geometry>
      <origin rpy="1.57 0 0" xyz="0 0 0"/>
      <material name="darkgray">
        <color rgba="0.2 0.2 0.2 1"/>
      </material>
    </visual>
  </link>
  <link name="finger[1]/flexible_link_2">
    <inertial>
      <mass value="0.1"/>
      <origin xyz="0 0 0"/>
      <inertia ixx="0.001" ixy="0.0" ixz="0.0" iyy="0.001" iyz="0.0" izz="0.001"/>
    </inertial>
    <collision>
      <geometry>
        <box size=".014 0.00176 .006"/>
      </geometry>
      <origin rpy="1.57 0 0" xyz="0 0 0"/>
    </collision>
    <visual>
      <geometry>
        <box size=".014 0.00176 .006"/>
      </geometry>
      <origin rpy="1.57 0 0" xyz="0 0 0"/>
      <material name="darkgray">
        <color rgba="0.2 0.2 0.2 1"/>
      </material>
    </visual>
  </link>
  <link name="finger[1]/flexible_link_3">
    <inertial>
      <mass value="0.1"/>
      <origin xyz="0 0 0"/>
      <inertia ixx="0.001" ixy="0.0" ixz="0.0" iyy="0.001" iyz="0.0" izz="0.001"/>
    </inertial>
    <collision>
      <geometry>
        <box size=".014 0.00176 .006"/>
      </geometry>
      <origin rpy="1.57 0 0" xyz="0 0 0"/>
    </collision>
    <visual>
      <geometry>
        <box size=".014 0.00176 .006"/>
      </geometry>
      <origin rpy="1.57 0 0" xyz="0 0 0"/>
      <material name="darkgray">
        <color rgba="0.2 0.2 0.2 1"/>
      </material>
    </visual>
  </link>
  <link name="finger[1]/flexible_link_4">
    <inertial>
      <mass value="0.1"/>
      <origin xyz="0 0 0"/>
      <inertia ixx="0.001" ixy="0.0" ixz="0.0" iyy="0.001" iyz="0.0" izz="0.001"/>
    </inertial>
    <collision>
      <geometry>
        <box size=".014 0.00176 .006"/>
      </geometry>
      <origin rpy="1.57 0 0" xyz="0 0 0"/>
    </collision>
    <visual>
      <geometry>
        <box size=".014 0.00176 .006"/>
      </geometry>
      <origin rpy="1.57 0 0" xyz="0 0 0"/>
      <material name="darkgray">
        <color rgba="0.2 0.2 0.2 1"/>
      </material>
    </visual>
  </link>
  <link name="finger[1]/flexible_link_5">
    <inertial>
      <mass value="0.1"/>
      <origin xyz="0 0 0"/>
      <inertia ixx="0.001" ixy="0.0" ixz="0.0" iyy="0.001" iyz="0.0" izz="0.001"/>
    </inertial>
    <collision>
      <geometry>
        <box size=".014 0.00176 .006"/>
      </geometry>
      <origin rpy="1.57 0 0" xyz="0 0 0"/>
    </collision>
    <visual>
      <geometry>
        <box size=".014 0.00176 .006"/>
      </geometry>
      <origin rpy="1.57 0 0" xyz="0 0 0"/>
      <material name="darkgray">
        <color rgba="0.2 0.2 0.2 1"/>
      </material>
    </visual>
  </link>
  <link name="finger[1]/flexible_link_6">
    <inertial>
      <mass value="0.1"/>
      <origin xyz="0 0 0"/>
      <inertia ixx="0.001" ixy="0.0" ixz="0.0" iyy="0.001" iyz="0.0" izz="0.001"/>
    </inertial>
    <collision>
      <geometry>
        <box size=".014 0.00176 .006"/>
      </geometry>
      <origin rpy="1.57 0 0" xyz="0 0 0"/>
    </collision>
    <visual>
      <geometry>
        <box size=".014 0.00176 .006"/>
      </geometry>
      <origin rpy="1.57 0 0" xyz="0 0 0"/>
      <material name="darkgray">
        <color rgba="0.2 0.2 0.2 1"/>
      </material>
    </visual>
  </link>
  <link name="finger[1]/flexible_link_7">
    <inertial>
      <mass value="0.1"/>
      <origin xyz="0 0 0"/>
      <inertia ixx="0.001" ixy="0.0" ixz="0.0" iyy="0.001" iyz="0.0" izz="0.001"/>
    </inertial>
    <collision>
      <geometry>
        <box size=".014 0.00176 .006"/>
      </geometry>
      <origin rpy="1.57 0 0" xyz="0 0 0"/>
    </collision>
    <visual>
      <geometry>
        <box size=".014 0.00176 .006"/>
      </geometry>
      <origin rpy="1.57 0 0" xyz="0 0 0"/>
      <material name="darkgray">
        <color rgba="0.2 0.2 0.2 1"/>
      </material>
    </visual>
  </link>
  <link name="finger[1]/flexible_link_8">
    <inertial>
      <mass value="0.1"/>
      <origin xyz="0 0 0"/>
      <inertia ixx="0.001" ixy="0.0" ixz="0.0" iyy="0.001" iyz="0.0" izz="0.001"/>
    </inertial>
    <collision>
      <geometry>
        <box size=".014 0.00176 .006"/>
      </geometry>
      <origin rpy="1.57 0 0" xyz="0 0 0"/>
    </collision>
    <visual>
      <geometry>
        <box size=".014 0.00176 .006"/>
      </geometry>
      <origin rpy="1.57 0 0" xyz="0 0 0"/>
      <material name="darkgray">
        <color rgba="0.2 0.2 0.2 1"/>
      </material>
    </visual>
  </link>
  <link name="finger[1]/flexible_link_9">
    <inertial>
      <mass value="0.1"/>
      <origin xyz="0 0 0"/>
      <inertia ixx="0.001" ixy="0.0" ixz="0.0" iyy="0.001" iyz="0.0" izz="0.001"/>
    </inertial>
    <collision>
      <geometry>
        <box size=".014 0.00176 .006"/>
      </geometry>
      <origin rpy="1.57 0 0" xyz="0 0 0"/>
    </collision>
    <visual>
      <geometry>
        <box size=".014 0.00176 .006"/>
      </geometry>
      <origin rpy="1.57 0 0" xyz="0 0 0"/>
      <material name="darkgray">
        <color rgba="0.2 0.2 0.2 1"/>
      </material>
    </visual>
  </link>
  <joint name="finger[1]/flexible_joint_flex_from_1_to_2" type="revolute">
    <parent link="finger[1]/flexible_link_1"/>
    <child link="finger[1]/flexible_link_hidden_between_1_and_2"/>
    <origin xyz="0 0 0.00177777777778"/>
    <axis xyz="-1 0 0"/>
    <limit effort="1000.0" lower="0.0" upper="1.57" velocity="0.5"/>
  </joint>
  <link name="finger[1]/flexible_link_hidden_between_1_and_2">
    <inertial>
      <mass value="0.1"/>
      <origin xyz="0 0 0"/>
      <inertia ixx="0.001" ixy="0.0" ixz="0.0" iyy="0.001" iyz="0.0" izz="0.001"/>
    </inertial>
    <collision>
      <geometry>
        <box size="0 0 0"/>
      </geometry>
      <origin rpy="0 0 0" xyz="0 0 0"/>
    </collision>
    <visual>
      <geometry>
        <box size="0 0 0"/>
      </geometry>
      <origin rpy="0 0 0" xyz="0 0 0"/>
    </visual>
  </link>
  <joint name="finger[1]/flexible_joint_twist_from_1_to_2" type="revolute">
    <parent link="finger[1]/flexible_link_hidden_between_1_and_2"/>
    <child link="finger[1]/flexible_link_2"/>
    <origin xyz="0 0 0"/>
    <axis xyz="0 0 1"/>
    <limit effort="1000.0" lower="0.0" upper="1.57" velocity="0.5"/>
  </joint>
  <joint name="finger[1]/flexible_joint_flex_from_2_to_3" type="revolute">
    <parent link="finger[1]/flexible_link_2"/>
    <child link="finger[1]/flexible_link_hidden_between_2_and_3"/>
    <origin xyz="0 0 0.00177777777778"/>
    <axis xyz="-1 0 0"/>
    <limit effort="1000.0" lower="0.0" upper="1.57" velocity="0.5"/>
  </joint>
  <link name="finger[1]/flexible_link_hidden_between_2_and_3">
    <inertial>
      <mass value="0.1"/>
      <origin xyz="0 0 0"/>
      <inertia ixx="0.001" ixy="0.0" ixz="0.0" iyy="0.001" iyz="0.0" izz="0.001"/>
    </inertial>
    <collision>
      <geometry>
        <box size="0 0 0"/>
      </geometry>
      <origin rpy="0 0 0" xyz="0 0 0"/>
    </collision>
    <visual>
      <geometry>
        <box size="0 0 0"/>
      </geometry>
      <origin rpy="0 0 0" xyz="0 0 0"/>
    </visual>
  </link>
  <joint name="finger[1]/flexible_joint_twist_from_2_to_3" type="revolute">
    <parent link="finger[1]/flexible_link_hidden_between_2_and_3"/>
    <child link="finger[1]/flexible_link_3"/>
    <origin xyz="0 0 0"/>
    <axis xyz="0 0 1"/>
    <limit effort="1000.0" lower="0.0" upper="1.57" velocity="0.5"/>
  </joint>
  <joint name="finger[1]/flexible_joint_flex_from_3_to_4" type="revolute">
    <parent link="finger[1]/flexible_link_3"/>
    <child link="finger[1]/flexible_link_hidden_between_3_and_4"/>
    <origin xyz="0 0 0.00177777777778"/>
    <axis xyz="-1 0 0"/>
    <limit effort="1000.0" lower="0.0" upper="1.57" velocity="0.5"/>
  </joint>
  <link name="finger[1]/flexible_link_hidden_between_3_and_4">
    <inertial>
      <mass value="0.1"/>
      <origin xyz="0 0 0"/>
      <inertia ixx="0.001" ixy="0.0" ixz="0.0" iyy="0.001" iyz="0.0" izz="0.001"/>
    </inertial>
    <collision>
      <geometry>
        <box size="0 0 0"/>
      </geometry>
      <origin rpy="0 0 0" xyz="0 0 0"/>
    </collision>
    <visual>
      <geometry>
        <box size="0 0 0"/>
      </geometry>
      <origin rpy="0 0 0" xyz="0 0 0"/>
    </visual>
  </link>
  <joint name="finger[1]/flexible_joint_twist_from_3_to_4" type="revolute">
    <parent link="finger[1]/flexible_link_hidden_between_3_and_4"/>
    <child link="finger[1]/flexible_link_4"/>
    <origin xyz="0 0 0"/>
    <axis xyz="0 0 1"/>
    <limit effort="1000.0" lower="0.0" upper="1.57" velocity="0.5"/>
  </joint>
  <joint name="finger[1]/flexible_joint_flex_from_4_to_5" type="revolute">
    <parent link="finger[1]/flexible_link_4"/>
    <child link="finger[1]/flexible_link_hidden_between_4_and_5"/>
    <origin xyz="0 0 0.00177777777778"/>
    <axis xyz="-1 0 0"/>
    <limit effort="1000.0" lower="0.0" upper="1.57" velocity="0.5"/>
  </joint>
  <link name="finger[1]/flexible_link_hidden_between_4_and_5">
    <inertial>
      <mass value="0.1"/>
      <origin xyz="0 0 0"/>
      <inertia ixx="0.001" ixy="0.0" ixz="0.0" iyy="0.001" iyz="0.0" izz="0.001"/>
    </inertial>
    <collision>
      <geometry>
        <box size="0 0 0"/>
      </geometry>
      <origin rpy="0 0 0" xyz="0 0 0"/>
    </collision>
    <visual>
      <geometry>
        <box size="0 0 0"/>
      </geometry>
      <origin rpy="0 0 0" xyz="0 0 0"/>
    </visual>
  </link>
  <joint name="finger[1]/flexible_joint_twist_from_4_to_5" type="revolute">
    <parent link="finger[1]/flexible_link_hidden_between_4_and_5"/>
    <child link="finger[1]/flexible_link_5"/>
    <origin xyz="0 0 0"/>
    <axis xyz="0 0 1"/>
    <limit effort="1000.0" lower="0.0" upper="1.57" velocity="0.5"/>
  </joint>
  <joint name="finger[1]/flexible_joint_flex_from_5_to_6" type="revolute">
    <parent link="finger[1]/flexible_link_5"/>
    <child link="finger[1]/flexible_link_hidden_between_5_and_6"/>
    <origin xyz="0 0 0.00177777777778"/>
    <axis xyz="-1 0 0"/>
    <limit effort="1000.0" lower="0.0" upper="1.57" velocity="0.5"/>
  </joint>
  <link name="finger[1]/flexible_link_hidden_between_5_and_6">
    <inertial>
      <mass value="0.1"/>
      <origin xyz="0 0 0"/>
      <inertia ixx="0.001" ixy="0.0" ixz="0.0" iyy="0.001" iyz="0.0" izz="0.001"/>
    </inertial>
    <collision>
      <geometry>
        <box size="0 0 0"/>
      </geometry>
      <origin rpy="0 0 0" xyz="0 0 0"/>
    </collision>
    <visual>
      <geometry>
        <box size="0 0 0"/>
      </geometry>
      <origin rpy="0 0 0" xyz="0 0 0"/>
    </visual>
  </link>
  <joint name="finger[1]/flexible_joint_twist_from_5_to_6" type="revolute">
    <parent link="finger[1]/flexible_link_hidden_between_5_and_6"/>
    <child link="finger[1]/flexible_link_6"/>
    <origin xyz="0 0 0"/>
    <axis xyz="0 0 1"/>
    <limit effort="1000.0" lower="0.0" upper="1.57" velocity="0.5"/>
  </joint>
  <joint name="finger[1]/flexible_joint_flex_from_6_to_7" type="revolute">
    <parent link="finger[1]/flexible_link_6"/>
    <child link="finger[1]/flexible_link_hidden_between_6_and_7"/>
    <origin xyz="0 0 0.00177777777778"/>
    <axis xyz="-1 0 0"/>
    <limit effort="1000.0" lower="0.0" upper="1.57" velocity="0.5"/>
  </joint>
  <link name="finger[1]/flexible_link_hidden_between_6_and_7">
    <inertial>
      <mass value="0.1"/>
      <origin xyz="0 0 0"/>
      <inertia ixx="0.001" ixy="0.0" ixz="0.0" iyy="0.001" iyz="0.0" izz="0.001"/>
    </inertial>
    <collision>
      <geometry>
        <box size="0 0 0"/>
      </geometry>
      <origin rpy="0 0 0" xyz="0 0 0"/>
    </collision>
    <visual>
      <geometry>
        <box size="0 0 0"/>
      </geometry>
      <origin rpy="0 0 0" xyz="0 0 0"/>
    </visual>
  </link>
  <joint name="finger[1]/flexible_joint_twist_from_6_to_7" type="revolute">
    <parent link="finger[1]/flexible_link_hidden_between_6_and_7"/>
    <child link="finger[1]/flexible_link_7"/>
    <origin xyz="0 0 0"/>
    <axis xyz="0 0 1"/>
    <limit effort="1000.0" lower="0.0" upper="1.57" velocity="0.5"/>
  </joint>
  <joint name="finger[1]/flexible_joint_flex_from_7_to_8" type="revolute">
    <parent link="finger[1]/flexible_link_7"/>
    <child link="finger[1]/flexible_link_hidden_between_7_and_8"/>
    <origin xyz="0 0 0.00177777777778"/>
    <axis xyz="-1 0 0"/>
    <limit effort="1000.0" lower="0.0" upper="1.57" velocity="0.5"/>
  </joint>
  <link name="finger[1]/flexible_link_hidden_between_7_and_8">
    <inertial>
      <mass value="0.1"/>
      <origin xyz="0 0 0"/>
      <inertia ixx="0.001" ixy="0.0" ixz="0.0" iyy="0.001" iyz="0.0" izz="0.001"/>
    </inertial>
    <collision>
      <geometry>
        <box size="0 0 0"/>
      </geometry>
      <origin rpy="0 0 0" xyz="0 0 0"/>
    </collision>
    <visual>
      <geometry>
        <box size="0 0 0"/>
      </geometry>
      <origin rpy="0 0 0" xyz="0 0 0"/>
    </visual>
  </link>
  <joint name="finger[1]/flexible_joint_twist_from_7_to_8" type="revolute">
    <parent link="finger[1]/flexible_link_hidden_between_7_and_8"/>
    <child link="finger[1]/flexible_link_8"/>
    <origin xyz="0 0 0"/>
    <axis xyz="0 0 1"/>
    <limit effort="1000.0" lower="0.0" upper="1.57" velocity="0.5"/>
  </joint>
  <joint name="finger[1]/flexible_joint_flex_from_8_to_9" type="revolute">
    <parent link="finger[1]/flexible_link_8"/>
    <child link="finger[1]/flexible_link_hidden_between_8_and_9"/>
    <origin xyz="0 0 0.00177777777778"/>
    <axis xyz="-1 0 0"/>
    <limit effort="1000.0" lower="0.0" upper="1.57" velocity="0.5"/>
  </joint>
  <link name="finger[1]/flexible_link_hidden_between_8_and_9">
    <inertial>
      <mass value="0.1"/>
      <origin xyz="0 0 0"/>
      <inertia ixx="0.001" ixy="0.0" ixz="0.0" iyy="0.001" iyz="0.0" izz="0.001"/>
    </inertial>
    <collision>
      <geometry>
        <box size="0 0 0"/>
      </geometry>
      <origin rpy="0 0 0" xyz="0 0 0"/>
    </collision>
    <visual>
      <geometry>
        <box size="0 0 0"/>
      </geometry>
      <origin rpy="0 0 0" xyz="0 0 0"/>
    </visual>
  </link>
  <joint name="finger[1]/flexible_joint_twist_from_8_to_9" type="revolute">
    <parent link="finger[1]/flexible_link_hidden_between_8_and_9"/>
    <child link="finger[1]/flexible_link_9"/>
    <origin xyz="0 0 0"/>
    <axis xyz="0 0 1"/>
    <limit effort="1000.0" lower="0.0" upper="1.57" velocity="0.5"/>
  </joint>
  <joint name="finger[1]/flexible_joint_flex_from_proximal_to_1" type="revolute">
    <parent link="finger[1]/proximal_link"/>
    <child link="finger[1]/flexible_link_hidden_between_proximal_link_and_1"/>
    <origin xyz="0 0 0.062"/>
    <axis xyz="-1 0 0"/>
    <limit effort="1000.0" lower="0.0" upper="1.57" velocity="0.5"/>
  </joint>
  <link name="finger[1]/flexible_link_hidden_between_proximal_link_and_1">
    <inertial>
      <mass value="0.1"/>
      <origin xyz="0 0 0"/>
      <inertia ixx="0.001" ixy="0.0" ixz="0.0" iyy="0.001" iyz="0.0" izz="0.001"/>
    </inertial>
    <collision>
      <geometry>
        <box size="0 0 0"/>
      </geometry>
      <origin rpy="0 0 0" xyz="0 0 0"/>
    </collision>
    <visual>
      <geometry>
        <box size="0 0 0"/>
      </geometry>
      <origin rpy="0 0 0" xyz="0 0 0"/>
    </visual>
  </link>
  <joint name="finger[1]/flexible_joint_twist_from_proximal_to_1" type="revolute">
    <parent link="finger[1]/flexible_link_hidden_between_proximal_link_and_1"/>
    <child link="finger[1]/flexible_link_1"/>
    <origin xyz="0 0 0"/>
    <axis xyz="0 0 1"/>
    <limit effort="1000.0" lower="0.0" upper="1.57" velocity="0.5"/>
  </joint>
  <joint name="finger[1]/flexible_joint_flex_from_9_to_distal" type="revolute">
    <parent link="finger[1]/flexible_link_9"/>
    <child link="finger[1]/flexible_link_hidden_between_9_and_distal_link"/>
    <origin xyz="0 0 0.00177777777778"/>
    <axis xyz="-1 0 0"/>
    <limit effort="1000.0" lower="0.0" upper="1.57" velocity="0.5"/>
  </joint>
  <link name="finger[1]/flexible_link_hidden_between_9_and_distal_link">
    <inertial>
      <mass value="0.1"/>
      <origin xyz="0 0 0"/>
      <inertia ixx="0.001" ixy="0.0" ixz="0.0" iyy="0.001" iyz="0.0" izz="0.001"/>
    </inertial>
    <collision>
      <geometry>
        <box size="0 0 0"/>
      </geometry>
      <origin rpy="0 0 0" xyz="0 0 0"/>
    </collision>
    <visual>
      <geometry>
        <box size="0 0 0"/>
      </geometry>
      <origin rpy="0 0 0" xyz="0 0 0"/>
    </visual>
  </link>
  <joint name="finger[1]/flexible_joint_twist_from_9_to_distal" type="revolute">
    <parent link="finger[1]/flexible_link_hidden_between_9_and_distal_link"/>
    <child link="finger[1]/distal_link"/>
    <origin xyz="0 0 0"/>
    <axis xyz="0 0 1"/>
    <limit effort="1000.0" lower="0.0" upper="1.57" velocity="0.5"/>
  </joint>
  <link name="finger[2]/flexible_link_1">
    <inertial>
      <mass value="0.1"/>
      <origin xyz="0 0 0"/>
      <inertia ixx="0.001" ixy="0.0" ixz="0.0" iyy="0.001" iyz="0.0" izz="0.001"/>
    </inertial>
    <collision>
      <geometry>
        <box size=".014 0.00176 .006"/>
      </geometry>
      <origin rpy="1.57 0 0" xyz="0 0 0"/>
    </collision>
    <visual>
      <geometry>
        <box size=".014 0.00176 .006"/>
      </geometry>
      <origin rpy="1.57 0 0" xyz="0 0 0"/>
      <material name="darkgray">
        <color rgba="0.2 0.2 0.2 1"/>
      </material>
    </visual>
  </link>
  <link name="finger[2]/flexible_link_2">
    <inertial>
      <mass value="0.1"/>
      <origin xyz="0 0 0"/>
      <inertia ixx="0.001" ixy="0.0" ixz="0.0" iyy="0.001" iyz="0.0" izz="0.001"/>
    </inertial>
    <collision>
      <geometry>
        <box size=".014 0.00176 .006"/>
      </geometry>
      <origin rpy="1.57 0 0" xyz="0 0 0"/>
    </collision>
    <visual>
      <geometry>
        <box size=".014 0.00176 .006"/>
      </geometry>
      <origin rpy="1.57 0 0" xyz="0 0 0"/>
      <material name="darkgray">
        <color rgba="0.2 0.2 0.2 1"/>
      </material>
    </visual>
  </link>
  <link name="finger[2]/flexible_link_3">
    <inertial>
      <mass value="0.1"/>
      <origin xyz="0 0 0"/>
      <inertia ixx="0.001" ixy="0.0" ixz="0.0" iyy="0.001" iyz="0.0" izz="0.001"/>
    </inertial>
    <collision>
      <geometry>
        <box size=".014 0.00176 .006"/>
      </geometry>
      <origin rpy="1.57 0 0" xyz="0 0 0"/>
    </collision>
    <visual>
      <geometry>
        <box size=".014 0.00176 .006"/>
      </geometry>
      <origin rpy="1.57 0 0" xyz="0 0 0"/>
      <material name="darkgray">
        <color rgba="0.2 0.2 0.2 1"/>
      </material>
    </visual>
  </link>
  <link name="finger[2]/flexible_link_4">
    <inertial>
      <mass value="0.1"/>
      <origin xyz="0 0 0"/>
      <inertia ixx="0.001" ixy="0.0" ixz="0.0" iyy="0.001" iyz="0.0" izz="0.001"/>
    </inertial>
    <collision>
      <geometry>
        <box size=".014 0.00176 .006"/>
      </geometry>
      <origin rpy="1.57 0 0" xyz="0 0 0"/>
    </collision>
    <visual>
      <geometry>
        <box size=".014 0.00176 .006"/>
      </geometry>
      <origin rpy="1.57 0 0" xyz="0 0 0"/>
      <material name="darkgray">
        <color rgba="0.2 0.2 0.2 1"/>
      </material>
    </visual>
  </link>
  <link name="finger[2]/flexible_link_5">
    <inertial>
      <mass value="0.1"/>
      <origin xyz="0 0 0"/>
      <inertia ixx="0.001" ixy="0.0" ixz="0.0" iyy="0.001" iyz="0.0" izz="0.001"/>
    </inertial>
    <collision>
      <geometry>
        <box size=".014 0.00176 .006"/>
      </geometry>
      <origin rpy="1.57 0 0" xyz="0 0 0"/>
    </collision>
    <visual>
      <geometry>
        <box size=".014 0.00176 .006"/>
      </geometry>
      <origin rpy="1.57 0 0" xyz="0 0 0"/>
      <material name="darkgray">
        <color rgba="0.2 0.2 0.2 1"/>
      </material>
    </visual>
  </link>
  <link name="finger[2]/flexible_link_6">
    <inertial>
      <mass value="0.1"/>
      <origin xyz="0 0 0"/>
      <inertia ixx="0.001" ixy="0.0" ixz="0.0" iyy="0.001" iyz="0.0" izz="0.001"/>
    </inertial>
    <collision>
      <geometry>
        <box size=".014 0.00176 .006"/>
      </geometry>
      <origin rpy="1.57 0 0" xyz="0 0 0"/>
    </collision>
    <visual>
      <geometry>
        <box size=".014 0.00176 .006"/>
      </geometry>
      <origin rpy="1.57 0 0" xyz="0 0 0"/>
      <material name="darkgray">
        <color rgba="0.2 0.2 0.2 1"/>
      </material>
    </visual>
  </link>
  <link name="finger[2]/flexible_link_7">
    <inertial>
      <mass value="0.1"/>
      <origin xyz="0 0 0"/>
      <inertia ixx="0.001" ixy="0.0" ixz="0.0" iyy="0.001" iyz="0.0" izz="0.001"/>
    </inertial>
    <collision>
      <geometry>
        <box size=".014 0.00176 .006"/>
      </geometry>
      <origin rpy="1.57 0 0" xyz="0 0 0"/>
    </collision>
    <visual>
      <geometry>
        <box size=".014 0.00176 .006"/>
      </geometry>
      <origin rpy="1.57 0 0" xyz="0 0 0"/>
      <material name="darkgray">
        <color rgba="0.2 0.2 0.2 1"/>
      </material>
    </visual>
  </link>
  <link name="finger[2]/flexible_link_8">
    <inertial>
      <mass value="0.1"/>
      <origin xyz="0 0 0"/>
      <inertia ixx="0.001" ixy="0.0" ixz="0.0" iyy="0.001" iyz="0.0" izz="0.001"/>
    </inertial>
    <collision>
      <geometry>
        <box size=".014 0.00176 .006"/>
      </geometry>
      <origin rpy="1.57 0 0" xyz="0 0 0"/>
    </collision>
    <visual>
      <geometry>
        <box size=".014 0.00176 .006"/>
      </geometry>
      <origin rpy="1.57 0 0" xyz="0 0 0"/>
      <material name="darkgray">
        <color rgba="0.2 0.2 0.2 1"/>
      </material>
    </visual>
  </link>
  <link name="finger[2]/flexible_link_9">
    <inertial>
      <mass value="0.1"/>
      <origin xyz="0 0 0"/>
      <inertia ixx="0.001" ixy="0.0" ixz="0.0" iyy="0.001" iyz="0.0" izz="0.001"/>
    </inertial>
    <collision>
      <geometry>
        <box size=".014 0.00176 .006"/>
      </geometry>
      <origin rpy="1.57 0 0" xyz="0 0 0"/>
    </collision>
    <visual>
      <geometry>
        <box size=".014 0.00176 .006"/>
      </geometry>
      <origin rpy="1.57 0 0" xyz="0 0 0"/>
      <material name="darkgray">
        <color rgba="0.2 0.2 0.2 1"/>
      </material>
    </visual>
  </link>
  <joint name="finger[2]/flexible_joint_flex_from_1_to_2" type="revolute">
    <parent link="finger[2]/flexible_link_1"/>
    <child link="finger[2]/flexible_link_hidden_between_1_and_2"/>
    <origin xyz="0 0 0.00177777777778"/>
    <axis xyz="-1 0 0"/>
    <limit effort="1000.0" lower="0.0" upper="1.57" velocity="0.5"/>
  </joint>
  <link name="finger[2]/flexible_link_hidden_between_1_and_2">
    <inertial>
      <mass value="0.1"/>
      <origin xyz="0 0 0"/>
      <inertia ixx="0.001" ixy="0.0" ixz="0.0" iyy="0.001" iyz="0.0" izz="0.001"/>
    </inertial>
    <collision>
      <geometry>
        <box size="0 0 0"/>
      </geometry>
      <origin rpy="0 0 0" xyz="0 0 0"/>
    </collision>
    <visual>
      <geometry>
        <box size="0 0 0"/>
      </geometry>
      <origin rpy="0 0 0" xyz="0 0 0"/>
    </visual>
  </link>
  <joint name="finger[2]/flexible_joint_twist_from_1_to_2" type="revolute">
    <parent link="finger[2]/flexible_link_hidden_between_1_and_2"/>
    <child link="finger[2]/flexible_link_2"/>
    <origin xyz="0 0 0"/>
    <axis xyz="0 0 1"/>
    <limit effort="1000.0" lower="0.0" upper="1.57" velocity="0.5"/>
  </joint>
  <joint name="finger[2]/flexible_joint_flex_from_2_to_3" type="revolute">
    <parent link="finger[2]/flexible_link_2"/>
    <child link="finger[2]/flexible_link_hidden_between_2_and_3"/>
    <origin xyz="0 0 0.00177777777778"/>
    <axis xyz="-1 0 0"/>
    <limit effort="1000.0" lower="0.0" upper="1.57" velocity="0.5"/>
  </joint>
  <link name="finger[2]/flexible_link_hidden_between_2_and_3">
    <inertial>
      <mass value="0.1"/>
      <origin xyz="0 0 0"/>
      <inertia ixx="0.001" ixy="0.0" ixz="0.0" iyy="0.001" iyz="0.0" izz="0.001"/>
    </inertial>
    <collision>
      <geometry>
        <box size="0 0 0"/>
      </geometry>
      <origin rpy="0 0 0" xyz="0 0 0"/>
    </collision>
    <visual>
      <geometry>
        <box size="0 0 0"/>
      </geometry>
      <origin rpy="0 0 0" xyz="0 0 0"/>
    </visual>
  </link>
  <joint name="finger[2]/flexible_joint_twist_from_2_to_3" type="revolute">
    <parent link="finger[2]/flexible_link_hidden_between_2_and_3"/>
    <child link="finger[2]/flexible_link_3"/>
    <origin xyz="0 0 0"/>
    <axis xyz="0 0 1"/>
    <limit effort="1000.0" lower="0.0" upper="1.57" velocity="0.5"/>
  </joint>
  <joint name="finger[2]/flexible_joint_flex_from_3_to_4" type="revolute">
    <parent link="finger[2]/flexible_link_3"/>
    <child link="finger[2]/flexible_link_hidden_between_3_and_4"/>
    <origin xyz="0 0 0.00177777777778"/>
    <axis xyz="-1 0 0"/>
    <limit effort="1000.0" lower="0.0" upper="1.57" velocity="0.5"/>
  </joint>
  <link name="finger[2]/flexible_link_hidden_between_3_and_4">
    <inertial>
      <mass value="0.1"/>
      <origin xyz="0 0 0"/>
      <inertia ixx="0.001" ixy="0.0" ixz="0.0" iyy="0.001" iyz="0.0" izz="0.001"/>
    </inertial>
    <collision>
      <geometry>
        <box size="0 0 0"/>
      </geometry>
      <origin rpy="0 0 0" xyz="0 0 0"/>
    </collision>
    <visual>
      <geometry>
        <box size="0 0 0"/>
      </geometry>
      <origin rpy="0 0 0" xyz="0 0 0"/>
    </visual>
  </link>
  <joint name="finger[2]/flexible_joint_twist_from_3_to_4" type="revolute">
    <parent link="finger[2]/flexible_link_hidden_between_3_and_4"/>
    <child link="finger[2]/flexible_link_4"/>
    <origin xyz="0 0 0"/>
    <axis xyz="0 0 1"/>
    <limit effort="1000.0" lower="0.0" upper="1.57" velocity="0.5"/>
  </joint>
  <joint name="finger[2]/flexible_joint_flex_from_4_to_5" type="revolute">
    <parent link="finger[2]/flexible_link_4"/>
    <child link="finger[2]/flexible_link_hidden_between_4_and_5"/>
    <origin xyz="0 0 0.00177777777778"/>
    <axis xyz="-1 0 0"/>
    <limit effort="1000.0" lower="0.0" upper="1.57" velocity="0.5"/>
  </joint>
  <link name="finger[2]/flexible_link_hidden_between_4_and_5">
    <inertial>
      <mass value="0.1"/>
      <origin xyz="0 0 0"/>
      <inertia ixx="0.001" ixy="0.0" ixz="0.0" iyy="0.001" iyz="0.0" izz="0.001"/>
    </inertial>
    <collision>
      <geometry>
        <box size="0 0 0"/>
      </geometry>
      <origin rpy="0 0 0" xyz="0 0 0"/>
    </collision>
    <visual>
      <geometry>
        <box size="0 0 0"/>
      </geometry>
      <origin rpy="0 0 0" xyz="0 0 0"/>
    </visual>
  </link>
  <joint name="finger[2]/flexible_joint_twist_from_4_to_5" type="revolute">
    <parent link="finger[2]/flexible_link_hidden_between_4_and_5"/>
    <child link="finger[2]/flexible_link_5"/>
    <origin xyz="0 0 0"/>
    <axis xyz="0 0 1"/>
    <limit effort="1000.0" lower="0.0" upper="1.57" velocity="0.5"/>
  </joint>
  <joint name="finger[2]/flexible_joint_flex_from_5_to_6" type="revolute">
    <parent link="finger[2]/flexible_link_5"/>
    <child link="finger[2]/flexible_link_hidden_between_5_and_6"/>
    <origin xyz="0 0 0.00177777777778"/>
    <axis xyz="-1 0 0"/>
    <limit effort="1000.0" lower="0.0" upper="1.57" velocity="0.5"/>
  </joint>
  <link name="finger[2]/flexible_link_hidden_between_5_and_6">
    <inertial>
      <mass value="0.1"/>
      <origin xyz="0 0 0"/>
      <inertia ixx="0.001" ixy="0.0" ixz="0.0" iyy="0.001" iyz="0.0" izz="0.001"/>
    </inertial>
    <collision>
      <geometry>
        <box size="0 0 0"/>
      </geometry>
      <origin rpy="0 0 0" xyz="0 0 0"/>
    </collision>
    <visual>
      <geometry>
        <box size="0 0 0"/>
      </geometry>
      <origin rpy="0 0 0" xyz="0 0 0"/>
    </visual>
  </link>
  <joint name="finger[2]/flexible_joint_twist_from_5_to_6" type="revolute">
    <parent link="finger[2]/flexible_link_hidden_between_5_and_6"/>
    <child link="finger[2]/flexible_link_6"/>
    <origin xyz="0 0 0"/>
    <axis xyz="0 0 1"/>
    <limit effort="1000.0" lower="0.0" upper="1.57" velocity="0.5"/>
  </joint>
  <joint name="finger[2]/flexible_joint_flex_from_6_to_7" type="revolute">
    <parent link="finger[2]/flexible_link_6"/>
    <child link="finger[2]/flexible_link_hidden_between_6_and_7"/>
    <origin xyz="0 0 0.00177777777778"/>
    <axis xyz="-1 0 0"/>
    <limit effort="1000.0" lower="0.0" upper="1.57" velocity="0.5"/>
  </joint>
  <link name="finger[2]/flexible_link_hidden_between_6_and_7">
    <inertial>
      <mass value="0.1"/>
      <origin xyz="0 0 0"/>
      <inertia ixx="0.001" ixy="0.0" ixz="0.0" iyy="0.001" iyz="0.0" izz="0.001"/>
    </inertial>
    <collision>
      <geometry>
        <box size="0 0 0"/>
      </geometry>
      <origin rpy="0 0 0" xyz="0 0 0"/>
    </collision>
    <visual>
      <geometry>
        <box size="0 0 0"/>
      </geometry>
      <origin rpy="0 0 0" xyz="0 0 0"/>
    </visual>
  </link>
  <joint name="finger[2]/flexible_joint_twist_from_6_to_7" type="revolute">
    <parent link="finger[2]/flexible_link_hidden_between_6_and_7"/>
    <child link="finger[2]/flexible_link_7"/>
    <origin xyz="0 0 0"/>
    <axis xyz="0 0 1"/>
    <limit effort="1000.0" lower="0.0" upper="1.57" velocity="0.5"/>
  </joint>
  <joint name="finger[2]/flexible_joint_flex_from_7_to_8" type="revolute">
    <parent link="finger[2]/flexible_link_7"/>
    <child link="finger[2]/flexible_link_hidden_between_7_and_8"/>
    <origin xyz="0 0 0.00177777777778"/>
    <axis xyz="-1 0 0"/>
    <limit effort="1000.0" lower="0.0" upper="1.57" velocity="0.5"/>
  </joint>
  <link name="finger[2]/flexible_link_hidden_between_7_and_8">
    <inertial>
      <mass value="0.1"/>
      <origin xyz="0 0 0"/>
      <inertia ixx="0.001" ixy="0.0" ixz="0.0" iyy="0.001" iyz="0.0" izz="0.001"/>
    </inertial>
    <collision>
      <geometry>
        <box size="0 0 0"/>
      </geometry>
      <origin rpy="0 0 0" xyz="0 0 0"/>
    </collision>
    <visual>
      <geometry>
        <box size="0 0 0"/>
      </geometry>
      <origin rpy="0 0 0" xyz="0 0 0"/>
    </visual>
  </link>
  <joint name="finger[2]/flexible_joint_twist_from_7_to_8" type="revolute">
    <parent link="finger[2]/flexible_link_hidden_between_7_and_8"/>
    <child link="finger[2]/flexible_link_8"/>
    <origin xyz="0 0 0"/>
    <axis xyz="0 0 1"/>
    <limit effort="1000.0" lower="0.0" upper="1.57" velocity="0.5"/>
  </joint>
  <joint name="finger[2]/flexible_joint_flex_from_8_to_9" type="revolute">
    <parent link="finger[2]/flexible_link_8"/>
    <child link="finger[2]/flexible_link_hidden_between_8_and_9"/>
    <origin xyz="0 0 0.00177777777778"/>
    <axis xyz="-1 0 0"/>
    <limit effort="1000.0" lower="0.0" upper="1.57" velocity="0.5"/>
  </joint>
  <link name="finger[2]/flexible_link_hidden_between_8_and_9">
    <inertial>
      <mass value="0.1"/>
      <origin xyz="0 0 0"/>
      <inertia ixx="0.001" ixy="0.0" ixz="0.0" iyy="0.001" iyz="0.0" izz="0.001"/>
    </inertial>
    <collision>
      <geometry>
        <box size="0 0 0"/>
      </geometry>
      <origin rpy="0 0 0" xyz="0 0 0"/>
    </collision>
    <visual>
      <geometry>
        <box size="0 0 0"/>
      </geometry>
      <origin rpy="0 0 0" xyz="0 0 0"/>
    </visual>
  </link>
  <joint name="finger[2]/flexible_joint_twist_from_8_to_9" type="revolute">
    <parent link="finger[2]/flexible_link_hidden_between_8_and_9"/>
    <child link="finger[2]/flexible_link_9"/>
    <origin xyz="0 0 0"/>
    <axis xyz="0 0 1"/>
    <limit effort="1000.0" lower="0.0" upper="1.57" velocity="0.5"/>
  </joint>
  <joint name="finger[2]/flexible_joint_flex_from_proximal_to_1" type="revolute">
    <parent link="finger[2]/proximal_link"/>
    <child link="finger[2]/flexible_link_hidden_between_proximal_link_and_1"/>
    <origin xyz="0 0 0.062"/>
    <axis xyz="-1 0 0"/>
    <limit effort="1000.0" lower="0.0" upper="1.57" velocity="0.5"/>
  </joint>
  <link name="finger[2]/flexible_link_hidden_between_proximal_link_and_1">
    <inertial>
      <mass value="0.1"/>
      <origin xyz="0 0 0"/>
      <inertia ixx="0.001" ixy="0.0" ixz="0.0" iyy="0.001" iyz="0.0" izz="0.001"/>
    </inertial>
    <collision>
      <geometry>
        <box size="0 0 0"/>
      </geometry>
      <origin rpy="0 0 0" xyz="0 0 0"/>
    </collision>
    <visual>
      <geometry>
        <box size="0 0 0"/>
      </geometry>
      <origin rpy="0 0 0" xyz="0 0 0"/>
    </visual>
  </link>
  <joint name="finger[2]/flexible_joint_twist_from_proximal_to_1" type="revolute">
    <parent link="finger[2]/flexible_link_hidden_between_proximal_link_and_1"/>
    <child link="finger[2]/flexible_link_1"/>
    <origin xyz="0 0 0"/>
    <axis xyz="0 0 1"/>
    <limit effort="1000.0" lower="0.0" upper="1.57" velocity="0.5"/>
  </joint>
  <joint name="finger[2]/flexible_joint_flex_from_9_to_distal" type="revolute">
    <parent link="finger[2]/flexible_link_9"/>
    <child link="finger[2]/flexible_link_hidden_between_9_and_distal_link"/>
    <origin xyz="0 0 0.00177777777778"/>
    <axis xyz="-1 0 0"/>
    <limit effort="1000.0" lower="0.0" upper="1.57" velocity="0.5"/>
  </joint>
  <link name="finger[2]/flexible_link_hidden_between_9_and_distal_link">
    <inertial>
      <mass value="0.1"/>
      <origin xyz="0 0 0"/>
      <inertia ixx="0.001" ixy="0.0" ixz="0.0" iyy="0.001" iyz="0.0" izz="0.001"/>
    </inertial>
    <collision>
      <geometry>
        <box size="0 0 0"/>
      </geometry>
      <origin rpy="0 0 0" xyz="0 0 0"/>
    </collision>
    <visual>
      <geometry>
        <box size="0 0 0"/>
      </geometry>
      <origin rpy="0 0 0" xyz="0 0 0"/>
    </visual>
  </link>
  <joint name="finger[2]/flexible_joint_twist_from_9_to_distal" type="revolute">
    <parent link="finger[2]/flexible_link_hidden_between_9_and_distal_link"/>
    <child link="finger[2]/distal_link"/>
    <origin xyz="0 0 0"/>
    <axis xyz="0 0 1"/>
    <limit effort="1000.0" lower="0.0" upper="1.57" velocity="0.5"/>
  </joint>
  <link name="base_link">
    <inertial>
      <mass value="0.1"/>
      <origin xyz="0 0 0"/>
      <inertia ixx="0.001" ixy="0.0" ixz="0.0" iyy="0.001" iyz="0.0" izz="0.001"/>
    </inertial>
    <visual>
      <geometry>
        <mesh filename="package://irobot_hand/meshes/palm.stl"/>
      </geometry>
      <material name="darkgray">
        <color rgba="0.2 0.2 0.2 1"/>
      </material>
      <origin rpy="0 0 0" xyz="0 -0.038 -0.023"/>
    </visual>
    <collision>
      <geometry>
        <mesh filename="package://irobot_hand/meshes/palm.stl"/>
      </geometry>
      <origin rpy="0 0 0" xyz="0 -0.038 -0.023"/>
    </collision>
  </link>
  <link name="finger[0]/base_rotation_link">
    <inertial>
      <mass value="0.1"/>
      <origin xyz="0 0 0"/>
      <inertia ixx="0.001" ixy="0.0" ixz="0.0" iyy="0.001" iyz="0.0" izz="0.001"/>
    </inertial>
    <collision>
      <geometry>
        <mesh filename="package://irobot_hand/meshes/finger_base.stl"/>
      </geometry>
      <origin rpy="1.57 0 0" xyz="0 0 0"/>
    </collision>
    <visual>
      <geometry>
        <mesh filename="package://irobot_hand/meshes/finger_base.stl"/>
      </geometry>
      <material name="darkgray">
        <color rgba="0.2 0.2 0.2 1"/>
      </material>
      <origin rpy="1.57 0 0" xyz="0 0 0"/>
    </visual>
  </link>
  <link name="finger[0]/proximal_link">
    <inertial>
      <mass value="0.1"/>
      <origin xyz="0 0 0"/>
      <inertia ixx="0.001" ixy="0.0" ixz="0.0" iyy="0.001" iyz="0.0" izz="0.001"/>
    </inertial>
    <collision>
      <geometry>
        <mesh filename="package://irobot_hand/meshes/finger_proximal.stl"/>
      </geometry>
      <origin rpy="1.57 -1.57 0" xyz="0 0 0"/>
    </collision>
    <visual>
      <geometry>
        <mesh filename="package://irobot_hand/meshes/finger_proximal.stl"/>
      </geometry>
      <material name="green">
        <color rgba="0.1 0.6 0.1 1"/>
      </material>
      <origin rpy="1.57 -1.57 0" xyz="0 0 0"/>
    </visual>
  </link>
  <link name="finger[0]/distal_link">
    <inertial>
      <mass value="0.1"/>
      <origin xyz="0 0 0"/>
      <inertia ixx="0.001" ixy="0.0" ixz="0.0" iyy="0.001" iyz="0.0" izz="0.001"/>
    </inertial>
    <collision>
      <geometry>
        <mesh filename="package://irobot_hand/meshes/finger_distal.stl"/>
      </geometry>
      <origin rpy="0 3.14 0" xyz="0 0 0"/>
    </collision>
    <visual>
      <geometry>
        <mesh filename="package://irobot_hand/meshes/finger_distal.stl"/>
      </geometry>
      <material name="green">
        <color rgba="0.1 0.6 0.1 1"/>
      </material>
      <origin rpy="0 3.14 0" xyz="0 0 0"/>
    </visual>
  </link>
  <link name="finger[1]/base_rotation_link">
    <inertial>
      <mass value="0.1"/>
      <origin xyz="0 0 0"/>
      <inertia ixx="0.001" ixy="0.0" ixz="0.0" iyy="0.001" iyz="0.0" izz="0.001"/>
    </inertial>
    <collision>
      <geometry>
        <mesh filename="package://irobot_hand/meshes/finger_base.stl"/>
      </geometry>
      <origin rpy="1.57 0 0" xyz="0 0 0"/>
    </collision>
    <visual>
      <geometry>
        <mesh filename="package://irobot_hand/meshes/finger_base.stl"/>
      </geometry>
      <material name="darkgray">
        <color rgba="0.2 0.2 0.2 1"/>
      </material>
      <origin rpy="1.57 0 0" xyz="0 0 0"/>
    </visual>
  </link>
  <link name="finger[1]/proximal_link">
    <inertial>
      <mass value="0.1"/>
      <origin xyz="0 0 0"/>
      <inertia ixx="0.001" ixy="0.0" ixz="0.0" iyy="0.001" iyz="0.0" izz="0.001"/>
    </inertial>
    <collision>
      <geometry>
        <mesh filename="package://irobot_hand/meshes/finger_proximal.stl"/>
      </geometry>
      <origin rpy="1.57 -1.57 0" xyz="0 0 0"/>
    </collision>
    <visual>
      <geometry>
        <mesh filename="package://irobot_hand/meshes/finger_proximal.stl"/>
      </geometry>
      <material name="green">
        <color rgba="0.1 0.6 0.1 1"/>
      </material>
      <origin rpy="1.57 -1.57 0" xyz="0 0 0"/>
    </visual>
  </link>
  <link name="finger[1]/distal_link">
    <inertial>
      <mass value="0.1"/>
      <origin xyz="0 0 0"/>
      <inertia ixx="0.001" ixy="0.0" ixz="0.0" iyy="0.001" iyz="0.0" izz="0.001"/>
    </inertial>
    <collision>
      <geometry>
        <mesh filename="package://irobot_hand/meshes/finger_distal.stl"/>
      </geometry>
      <origin rpy="0 3.14 0" xyz="0 0 0"/>
    </collision>
    <visual>
      <geometry>
        <mesh filename="package://irobot_hand/meshes/finger_distal.stl"/>
      </geometry>
      <material name="green">
        <color rgba="0.1 0.6 0.1 1"/>
      </material>
      <origin rpy="0 3.14 0" xyz="0 0 0"/>
    </visual>
  </link>
  <link name="finger[2]/proximal_link">
    <inertial>
      <mass value="0.1"/>
      <origin xyz="0 0 0"/>
      <inertia ixx="0.001" ixy="0.0" ixz="0.0" iyy="0.001" iyz="0.0" izz="0.001"/>
    </inertial>
    <collision>
      <geometry>
        <mesh filename="package://irobot_hand/meshes/finger_proximal.stl"/>
      </geometry>
      <origin rpy="1.57 -1.57 0" xyz="0 0 0"/>
    </collision>
    <visual>
      <geometry>
        <mesh filename="package://irobot_hand/meshes/finger_proximal.stl"/>
      </geometry>
      <material name="green">
        <color rgba="0.1 0.6 0.1 1"/>
      </material>
      <origin rpy="1.57 -1.57 0" xyz="0 0 0"/>
    </visual>
  </link>
  <link name="finger[2]/distal_link">
    <inertial>
      <mass value="0.1"/>
      <origin xyz="0 0 0"/>
      <inertia ixx="0.001" ixy="0.0" ixz="0.0" iyy="0.001" iyz="0.0" izz="0.001"/>
    </inertial>
    <collision>
      <geometry>
        <mesh filename="package://irobot_hand/meshes/finger_distal.stl"/>
      </geometry>
      <origin rpy="0 3.14 0" xyz="0 0 0"/>
    </collision>
    <visual>
      <geometry>
        <mesh filename="package://irobot_hand/meshes/finger_distal.stl"/>
      </geometry>
      <material name="green">
        <color rgba="0.1 0.6 0.1 1"/>
      </material>
      <origin rpy="0 3.14 0" xyz="0 0 0"/>
    </visual>
  </link>
  <joint name="finger[0]/joint_base_rotation" type="revolute">
    <parent link="base_link"/>
    <child link="finger[0]/base_rotation_link"/>
    <origin rpy="0 0 0" xyz="0.03075 0.038 0.069477"/>
    <axis xyz="0 0 -1"/>
    <limit effort="1000.0" lower="0.0" upper="1.57" velocity="0.5"/>
  </joint>
  <joint name="finger[0]/joint_base" type="revolute">
    <parent link="finger[0]/base_rotation_link"/>
    <child link="finger[0]/proximal_link"/>
    <origin rpy="1.57 0 -3.14" xyz="0 0 0.0135"/>
    <axis xyz="-1 0 0"/>
    <limit effort="1000.0" lower="0.0" upper="1.57" velocity="0.5"/>
  </joint>
  <joint name="finger[1]/joint_base_rotation" type="revolute">
    <parent link="base_link"/>
    <child link="finger[1]/base_rotation_link"/>
    <origin rpy="0 0 0" xyz="-0.03075 0.038 0.069477"/>
    <axis xyz="0 0 1"/>
    <limit effort="1000.0" lower="0.0" upper="1.57" velocity="0.5"/>
  </joint>
  <joint name="finger[1]/joint_base" type="revolute">
    <parent link="finger[1]/base_rotation_link"/>
    <child link="finger[1]/proximal_link"/>
    <origin rpy="1.57 0 -3.14" xyz="0 0 0.0135"/>
    <axis xyz="-1 0 0"/>
    <limit effort="1000.0" lower="0.0" upper="1.57" velocity="0.5"/>
  </joint>
  <joint name="finger[2]/joint_base" type="revolute">
    <parent link="base_link"/>
    <child link="finger[2]/proximal_link"/>
    <origin rpy="1.57 0 0" xyz="0 -0.038 0.082755"/>
    <axis xyz="-1 0 0"/>
    <limit effort="1000.0" lower="0.0" upper="1.57" velocity="0.5"/>
  </joint>
</robot>

